Workbook

Sheet estabelecimentos
A1: place_id | B1: nome | C1: capital_endereco | D1: origem | E1: endereco | F1: avaliacao_media | G1: volume_avaliacoes | H1: link_google_maps | I1: dias_abertos | J1: horas_semana | K1: abre_cedo | L1: fecha_tarde | M1: segunda | N1: terca | O1: quarta | P1: quinta | Q1: sexta | R1: sabado | S1: domingo | T1: metro_500m | U1: metro_1000m | V1: dist_metro_m | W1: shopping_porte_500m | X1: shopping_porte_1000m | Y1: dist_shopping_m | Z1: perfil_instagram | AA1: seguidores | AB1: n_posts_total | AC1: primeiro_post | AD1: n_posts_periodo | AE1: curtidas_periodo | AF1: comentarios_periodo | AG1: obs_instagram | AH1: itens_com_preco | AI1: couvert_no_cardapio | AJ1: cesta_baixa | AK1: cesta_mediana | AL1: cesta_alta | AM1: titulos_acervo | AN1: fonte_acervo | AO1: avaliacoes_b2 | AP1: avaliacoes_b2_com_texto
A2: ChIJRcWOaPabpgARDvX2Bad0qb0 | B2: Bardo Mago | C2: Belo Horizonte | D2: acervodejogos | E2: Av. Petrolina, 883 - Horto Florestal, Belo Horizonte - MG, 31030-370 | F2: 4.8 | G2: 823 | H2: https://maps.google.com/?cid=13666582804940911886 | I2: 5 | J2: 37 | K2: 13:00 | L2: 24:00 | O2: 18:00-00:00 | P2: 18:00-00:00 | Q2: 18:00-00:00 | R2: 14:00-00:00 | S2: 13:00-22:00 | T2: 1 | U2: 1 | V2: 307 | Y2: 723 | Z2: bardo.mago | AB2: 616 | AC2: 2024-05-15 | AD2: 31 | AE2: 8610 | AF2: 288 | AG2: 1 de 616 posts não carregou; o primeiro post pode ser anterior | AH2: 110 | AI2: não encontrado | AJ2: =IFERROR(INDEX(cesta!$O$2:$O$43,MATCH($A2,cesta!$A$2:$A$43,0)),"") | AK2: =IFERROR(INDEX(cesta!$P$2:$P$43,MATCH($A2,cesta!$A$2:$A$43,0)),"") | AL2: =IFERROR(INDEX(cesta!$Q$2:$Q$43,MATCH($A2,cesta!$A$2:$A$43,0)),"") | AM2: 588 | AN2: acervodejogos
A3: ChIJpzB8zc2XpgARoJTUu90J6Pw | B3: Comdado Bar e Jogos | C3: Belo Horizonte | D3: triagem manual | E3: Av. Amazonas, 2310 - Santo Agostinho, Belo Horizonte - MG, 30180-012, Brazil | F3: 4.4 | G3: 158 | H3: https://maps.google.com/?cid=18223826740098405536&g_mp=CiVnb29nbGUubWFwcy5wbGFjZXMudjEuUGxhY2VzLkdldFBsYWNlEAIYBCAA | I3: 5 | J3: 45 | K3: 12:00 | L3: 25:00 | O3: 17:00-00:00 | P3: 17:00-00:00 | Q3: 17:00-01:00 | R3: 12:00-01:00 | S3: 12:00-22:00 | T3: 0 | U3: 0 | Y3: 105 | Z3: comdadobar | AA3: 10671 | AB3: 190 | AC3: 2022-10-22 | AD3: 2 | AE3: 100 | AF3: 4 | AH3: 55 | AI3: sim | AJ3: =IFERROR(INDEX(cesta!$O$2:$O$43,MATCH($A3,cesta!$A$2:$A$43,0)),"") | AK3: =IFERROR(INDEX(cesta!$P$2:$P$43,MATCH($A3,cesta!$A$2:$A$43,0)),"") | AL3: =IFERROR(INDEX(cesta!$Q$2:$Q$43,MATCH($A3,cesta!$A$2:$A$43,0)),"") | AM3: 190 | AN3: acervodejogos | AO3: 12 | AP3: 6
A4: ChIJsUAT-dObpgARCT2C5QpnVKU | B4: Garagem do Nerd | C4: Belo Horizonte | D4: triagem manual | E4: R. Padre Júlio Maria, 93 - Vera Cruz, Belo Horizonte - MG, 30285-360, Brazil | F4: 4.9 | G4: 244 | H4: https://maps.google.com/?cid=11913260210799656201&g_mp=CiVnb29nbGUubWFwcy5wbGFjZXMudjEuUGxhY2VzLkdldFBsYWNlEAIYBCAA | I4: 5 | J4: 34 | K4: 13:00 | L4: 25:00 | N4: 18:00-01:00 | O4: 18:00-01:00 | P4: 18:00-01:00 | Q4: 18:00-01:00 | R4: 13:00-19:00 | T4: 0 | U4: 0 | Y4: 754 | Z4: garagemdonerd | AA4: 13420 | AB4: 3023 | AC4: 2018-01-22 | AD4: 30 | AE4: 529 | AF4: 10 | AH4: 1 | AI4: sim | AJ4: =IFERROR(INDEX(cesta!$O$2:$O$43,MATCH($A4,cesta!$A$2:$A$43,0)),"") | AK4: =IFERROR(INDEX(cesta!$P$2:$P$43,MATCH($A4,cesta!$A$2:$A$43,0)),"") | AL4: =IFERROR(INDEX(cesta!$Q$2:$Q$43,MATCH($A4,cesta!$A$2:$A$43,0)),"") | AO4: 4 | AP4: 1
A5: ChIJ-17ZQDG9pgARc-AxpXmaNRU | B5: La Tabuleria | C5: Belo Horizonte | D5: acervodejogos | E5: Av. Aggeo Pio Sobrinho, 414 - Buritis, Belo Horizonte - MG, 30575-834 | F5: 4.7 | G5: 138 | H5: https://maps.google.com/?cid=1528297495815381107 | I5: 5 | J5: 42 | K5: 15:00 | L5: 25:00 | O5: 16:00-00:00 | P5: 16:00-00:00 | Q5: 16:00-01:00 | R5: 16:00-01:00 | S5: 15:00-23:00 | T5: 0 | U5: 0 | Y5: 137 | Z5: latabuleria | AC5: 2024-02-23 | AD5: 8 | AE5: 140 | AF5: 1 | AH5: 90 | AI5: sim | AJ5: =IFERROR(INDEX(cesta!$O$2:$O$43,MATCH($A5,cesta!$A$2:$A$43,0)),"") | AK5: =IFERROR(INDEX(cesta!$P$2:$P$43,MATCH($A5,cesta!$A$2:$A$43,0)),"") | AL5: =IFERROR(INDEX(cesta!$Q$2:$Q$43,MATCH($A5,cesta!$A$2:$A$43,0)),"") | AM5: 192 | AN5: acervodejogos
A6: ChIJx5jr3zGXpgARQGx9eX7TDmY | B6: LudoCafé | C6: Belo Horizonte | D6: triagem manual | E6: R. Antônio Dias, 201 - Santo Antônio, Belo Horizonte - MG, 30350-150, Brazil | F6: 4.6 | G6: 585 | H6: https://maps.google.com/?cid=7354047781700201536&g_mp=CiVnb29nbGUubWFwcy5wbGFjZXMudjEuUGxhY2VzLkdldFBsYWNlEAIYBCAA | I6: 6 | J6: 41 | K6: 13:00 | L6: 24:00 | N6: 17:00-23:00 | O6: 17:00-23:00 | P6: 17:00-23:00 | Q6: 17:00-00:00 | R6: 16:00-00:00 | S6: 13:00-21:00 | T6: 0 | U6: 0 | Y6: 391 | Z6: ludocafe_editora | AA6: 1208 | AB6: 60 | AC6: 2022-09-01 | AD6: 1 | AE6: 12 | AF6: 0 | AG6: perfil da editora; a triagem aponta @ludocafebh | AH6: 11 | AI6: sim | AJ6: =IFERROR(INDEX(cesta!$O$2:$O$43,MATCH($A6,cesta!$A$2:$A$43,0)),"") | AK6: =IFERROR(INDEX(cesta!$P$2:$P$43,MATCH($A6,cesta!$A$2:$A$43,0)),"") | AL6: =IFERROR(INDEX(cesta!$Q$2:$Q$43,MATCH($A6,cesta!$A$2:$A$43,0)),"") | AM6: 362 | AN6: acervodejogos | AO6: 10 | AP6: 6
A7: ChIJ6ZLMZw-XpgAR_OR6SwY5xKo | B7: Shelf Bar e Jogos | C7: Belo Horizonte | D7: triagem manual | E7: Av. do Contorno, 7287 - Lourdes, Belo Horizonte - MG, 30110-047, Brazil | F7: 4.6 | G7: 1505 | H7: https://maps.google.com/?cid=12305022781081969916&g_mp=CiVnb29nbGUubWFwcy5wbGFjZXMudjEuUGxhY2VzLkdldFBsYWNlEAIYBCAA | I7: 6 | J7: 56 | K7: 15:00 | L7: 25:00 | N7: 15:00-00:00 | O7: 15:00-00:00 | P7: 15:00-00:00 | Q7: 15:00-01:00 | R7: 15:00-01:00 | S7: 15:00-00:00 | T7: 0 | U7: 0 | Y7: 221 | Z7: shelfbar | AA7: 31800 | AB7: 630 | AC7: 2024-08-22 | AD7: 32 | AE7: 1557 | AF7: 121 | AH7: 138 | AI7: sim | AJ7: =IFERROR(INDEX(cesta!$O$2:$O$43,MATCH($A7,cesta!$A$2:$A$43,0)),"") | AK7: =IFERROR(INDEX(cesta!$P$2:$P$43,MATCH($A7,cesta!$A$2:$A$43,0)),"") | AL7: =IFERROR(INDEX(cesta!$Q$2:$Q$43,MATCH($A7,cesta!$A$2:$A$43,0)),"") | AM7: 836 | AN7: acervodejogos | AO7: 272 | AP7: 243
A8: ChIJ-97tiEeNpJIRb_eV7a-sxBs | B8: Ludoteca Sidequest | C8: Belém | D8: triagem manual | E8: Av. Visc. de Souza Franco, 1313 - Umarizal, Belém - PA, 66053-000, Brazil | F8: 4.8 | G8: 327 | H8: https://maps.google.com/?cid=2000914006064625519&g_mp=CiVnb29nbGUubWFwcy5wbGFjZXMudjEuUGxhY2VzLkdldFBsYWNlEAIYBCAA | I8: 5 | J8: 42 | K8: 14:00 | L8: 24:00 | O8: 16:00-00:00 | P8: 16:00-00:00 | Q8: 16:00-00:00 | R8: 14:00-00:00 | S8: 14:00-22:00 | T8: 0 | U8: 0 | Y8: 52 | Z8: ludotecasidequest | AA8: 21601 | AB8: 235 | AC8: 2023-10-24 | AD8: 10 | AE8: 3394 | AF8: 92 | AH8: 58 | AI8: sim | AJ8: =IFERROR(INDEX(cesta!$O$2:$O$43,MATCH($A8,cesta!$A$2:$A$43,0)),"") | AK8: =IFERROR(INDEX(cesta!$P$2:$P$43,MATCH($A8,cesta!$A$2:$A$43,0)),"") | AL8: =IFERROR(INDEX(cesta!$Q$2:$Q$43,MATCH($A8,cesta!$A$2:$A$43,0)),"") | AM8: 468 | AN8: rejoy | AO8: 40 | AP8: 26
A9: ChIJyXjE650xWpMRJL-J6QbGkt4 | B9: FORTALÚDICA - BURGERS & JOGOS | C9: Brasília | D9: triagem manual | E9: Guará II QE 26 BLOCO B Lj 31 - Guará, Brasília - DF, 71060-621, Brazil | F9: 4.8 | G9: 105 | H9: https://maps.google.com/?cid=16038098956009979684&g_mp=CiVnb29nbGUubWFwcy5wbGFjZXMudjEuUGxhY2VzLkdldFBsYWNlEAIYBCAA | I9: 7 | J9: 46 | K9: 14:00 | L9: 24:00 | M9: 18:00-00:00 | N9: 18:00-00:00 | O9: 18:00-00:00 | P9: 18:00-00:00 | Q9: 18:00-00:00 | R9: 14:00-22:00 | S9: 14:00-22:00 | T9: 0 | U9: 1 | V9: 768 | Y9: 305 | Z9: fortaludica | AA9: 2711 | AB9: 185 | AC9: 2025-07-10 | AD9: 9 | AE9: 86 | AF9: 11 | AH9: 51 | AI9: não encontrado | AJ9: =IFERROR(INDEX(cesta!$O$2:$O$43,MATCH($A9,cesta!$A$2:$A$43,0)),"") | AK9: =IFERROR(INDEX(cesta!$P$2:$P$43,MATCH($A9,cesta!$A$2:$A$43,0)),"") | AL9: =IFERROR(INDEX(cesta!$Q$2:$Q$43,MATCH($A9,cesta!$A$2:$A$43,0)),"") | AO9: 23 | AP9: 15
A10: ChIJ172cu2U7WpMR-GxnGmUHCkc | B10: Gruta BSB | C10: Brasília | D10: triagem manual | E10: SHCN CLN 406 Bloco E Lj 16/22 subsolo - Asa Norte, Brasília - DF, 70847-550, Brazil | F10: 4.9 | G10: 112 | H10: https://maps.google.com/?cid=5118912057276067064&g_mp=CiVnb29nbGUubWFwcy5wbGFjZXMudjEuUGxhY2VzLkdldFBsYWNlEAIYBCAA | I10: 5 | J10: 30 | K10: 14:00 | L10: 23:00 | N10: 17:00-23:00 | O10: 17:00-23:00 | P10: 17:00-23:00 | Q10: 17:00-23:00 | R10: 14:00-20:00 | T10: 0 | U10: 0 | Y10: 76 | Z10: grutabsb | AA10: 7631 | AB10: 897 | AC10: 2021-02-26 | AD10: 17 | AE10: 450 | AF10: 9 | AJ10: =IFERROR(INDEX(cesta!$O$2:$O$43,MATCH($A10,cesta!$A$2:$A$43,0)),"") | AK10: =IFERROR(INDEX(cesta!$P$2:$P$43,MATCH($A10,cesta!$A$2:$A$43,0)),"") | AL10: =IFERROR(INDEX(cesta!$Q$2:$Q$43,MATCH($A10,cesta!$A$2:$A$43,0)),"") | AO10: 12 | AP10: 8
A11: ChIJdUv4La46WpMRnBvNknmOqWo | B11: Inside Games | C11: Brasília | D11: triagem manual | E11: SHCS CRS 513 BL B Loja 07 - Asa Sul, Brasília - DF, 70380-520, Brazil | F11: 4.6 | G11: 640 | H11: https://maps.google.com/?cid=7685830891889564572&g_mp=CiVnb29nbGUubWFwcy5wbGFjZXMudjEuUGxhY2VzLkdldFBsYWNlEAIYBCAA | I11: 6 | J11: 64 | K11: 12:00 | L11: 24:00 | N11: 12:00-00:00 | O11: 12:00-00:00 | P11: 12:00-00:00 | Q11: 12:00-00:00 | R11: 12:00-20:00 | S11: 12:00-20:00 | T11: 0 | U11: 2 | V11: 702 | Z11: insidegamestore | AA11: 6058 | AB11: 2542 | AC11: 2017-06-15 | AD11: 39 | AE11: 193 | AF11: 2 | AH11: 24 | AI11: não encontrado | AJ11: =IFERROR(INDEX(cesta!$O$2:$O$43,MATCH($A11,cesta!$A$2:$A$43,0)),"") | AK11: =IFERROR(INDEX(cesta!$P$2:$P$43,MATCH($A11,cesta!$A$2:$A$43,0)),"") | AL11: =IFERROR(INDEX(cesta!$Q$2:$Q$43,MATCH($A11,cesta!$A$2:$A$43,0)),"") | AO11: 12 | AP11: 6
A12: ChIJzdFNP3AyWpMRH2P6HEuhE-I | B12: Loja de Jogos - Asgard | C12: Brasília | D12: triagem manual | E12: Rua 25 Sul, Lote 30 Bloco A loja 1 - Águas Claras, Brasília - DF, 71928-720, Brazil | F12: 4.7 | G12: 754 | H12: https://maps.google.com/?cid=16290541621110006559&g_mp=CiVnb29nbGUubWFwcy5wbGFjZXMudjEuUGxhY2VzLkdldFBsYWNlEAIYBCAA | I12: 7 | J12: 63 | K12: 14:00 | L12: 23:00 | M12: 14:00-23:00 | N12: 14:00-23:00 | O12: 14:00-23:00 | P12: 14:00-23:00 | Q12: 14:00-23:00 | R12: 14:00-23:00 | S12: 14:00-23:00 | T12: 1 | U12: 1 | V12: 430 | Y12: 169 | Z12: asgardbrasilia | AA12: 7305 | AB12: 608 | AC12: 2017-10-06 | AD12: 1 | AE12: 15 | AF12: 0 | AH12: 39 | AI12: sim | AJ12: =IFERROR(INDEX(cesta!$O$2:$O$43,MATCH($A12,cesta!$A$2:$A$43,0)),"") | AK12: =IFERROR(INDEX(cesta!$P$2:$P$43,MATCH($A12,cesta!$A$2:$A$43,0)),"") | AL12: =IFERROR(INDEX(cesta!$Q$2:$Q$43,MATCH($A12,cesta!$A$2:$A$43,0)),"") | AM12: 150 | AN12: asgard | AO12: 11 | AP12: 4
A13: ChIJ15nLgwAwWpMRY1whwD29ZSo | B13: Ludoteca BGC | C13: Brasília | D13: triagem manual | E13: BLOCO C - LOJA 02 - Asa Sul, Brasília - DF, 70254-530, Brazil | F13: 4.7 | G13: 1379 | H13: https://maps.google.com/?cid=3055055995154816099&g_mp=CiVnb29nbGUubWFwcy5wbGFjZXMudjEuUGxhY2VzLkdldFBsYWNlEAIYBCAA | I13: 6 | J13: 63 | K13: 12:00 | L13: 23:30 | N13: 12:00-22:00 | O13: 12:00-22:00 | P13: 12:00-22:00 | Q13: 12:00-23:30 | R13: 12:00-23:30 | S13: 12:00-22:00 | T13: 2 | U13: 2 | V13: 465 | Y13: 747 | Z13: ludotecabgc | AA13: 15000 | AB13: 820 | AC13: 2016-06-01 | AD13: 13 | AE13: 144 | AF13: 10 | AH13: 60 | AI13: sim | AJ13: =IFERROR(INDEX(cesta!$O$2:$O$43,MATCH($A13,cesta!$A$2:$A$43,0)),"") | AK13: =IFERROR(INDEX(cesta!$P$2:$P$43,MATCH($A13,cesta!$A$2:$A$43,0)),"") | AL13: =IFERROR(INDEX(cesta!$Q$2:$Q$43,MATCH($A13,cesta!$A$2:$A$43,0)),"") | AM13: 952 | AN13: acervodejogos | AO13: 24 | AP13: 13
A14: ChIJN8BZeb85WpMRgVKT05caxB4 | B14: Utopia Games & Food | C14: Brasília | D14: triagem manual | E14: SHCN CL QD 116 CLN 116 BLOCO I Lojas 31 e 35 subsolo - Asa Norte, Brasília - DF, 70773-590, Brazil | F14: 4.8 | G14: 159 | H14: https://maps.google.com/?cid=2216926155965158017&g_mp=CiVnb29nbGUubWFwcy5wbGFjZXMudjEuUGxhY2VzLkdldFBsYWNlEAIYBCAA | I14: 6 | J14: 44 | K14: 14:00 | L14: 24:00 | N14: 17:00-00:00 | O14: 17:00-00:00 | P14: 17:00-00:00 | Q14: 17:00-00:00 | R14: 14:00-22:00 | S14: 14:00-22:00 | T14: 0 | U14: 0 | Y14: 162 | Z14: utopiagamesbr | AA14: 2824 | AB14: 208 | AC14: 2024-02-12 | AD14: 27 | AE14: 997 | AF14: 64 | AH14: 32 | AI14: não encontrado | AJ14: =IFERROR(INDEX(cesta!$O$2:$O$43,MATCH($A14,cesta!$A$2:$A$43,0)),"") | AK14: =IFERROR(INDEX(cesta!$P$2:$P$43,MATCH($A14,cesta!$A$2:$A$43,0)),"") | AL14: =IFERROR(INDEX(cesta!$Q$2:$Q$43,MATCH($A14,cesta!$A$2:$A$43,0)),"") | AO14: 31 | AP14: 22
A15: ChIJ3ekLtDjl3JQRHwtNgmINgLo | B15: Alçapão Jogos | C15: Curitiba | D15: triagem manual | E15: R. Mal. Hermes, 104 - Centro Cívico, Curitiba - PR, 80530-230, Brazil | F15: 5 | G15: 219 | H15: https://maps.google.com/?cid=13438756004817603359&g_mp=CiVnb29nbGUubWFwcy5wbGFjZXMudjEuUGxhY2VzLkdldFBsYWNlEAIYBCAA | I15: 5 | J15: 36 | K15: 15:00 | L15: 24:00 | O15: 16:00-23:00 | P15: 16:00-23:00 | Q15: 16:00-00:00 | R15: 15:00-23:00 | S15: 15:00-21:00 | T15: 0 | U15: 0 | Y15: 770 | Z15: alcapaojogos | AA15: 13883 | AB15: 303 | AC15: 2018-12-17 | AD15: 3 | AE15: 67 | AF15: 5 | AH15: 26 | AI15: não encontrado | AJ15: =IFERROR(INDEX(cesta!$O$2:$O$43,MATCH($A15,cesta!$A$2:$A$43,0)),"") | AK15: =IFERROR(INDEX(cesta!$P$2:$P$43,MATCH($A15,cesta!$A$2:$A$43,0)),"") | AL15: =IFERROR(INDEX(cesta!$Q$2:$Q$43,MATCH($A15,cesta!$A$2:$A$43,0)),"") | AM15: 270 | AN15: acervodejogos | AO15: 20 | AP15: 8
A16: ChIJY_lqHVLl3JQRvDHacOMDKuc | B16: BoardZ Game Pub | C16: Curitiba | D16: triagem manual | E16: R. Chile, 2077 - Rebouças, Curitiba - PR, 80220-181, Brazil | F16: 4.8 | G16: 776 | H16: https://maps.google.com/?cid=16657130447169008060&g_mp=CiVnb29nbGUubWFwcy5wbGFjZXMudjEuUGxhY2VzLkdldFBsYWNlEAIYBCAA | I16: 6 | J16: 35 | K16: 16:00 | L16: 24:30 | N16: 18:00-23:00 | O16: 18:00-23:00 | P16: 18:00-23:00 | Q16: 18:00-00:30 | R16: 16:00-00:30 | S16: 17:00-22:00 | T16: 0 | U16: 0 | Z16: boardzgamepub | AA16: 18698 | AB16: 491 | AC16: 2020-02-17 | AD16: 2 | AE16: 237 | AF16: 22 | AH16: 91 | AI16: não encontrado | AJ16: =IFERROR(INDEX(cesta!$O$2:$O$43,MATCH($A16,cesta!$A$2:$A$43,0)),"") | AK16: =IFERROR(INDEX(cesta!$P$2:$P$43,MATCH($A16,cesta!$A$2:$A$43,0)),"") | AL16: =IFERROR(INDEX(cesta!$Q$2:$Q$43,MATCH($A16,cesta!$A$2:$A$43,0)),"") | AO16: 37 | AP16: 24
A17: ChIJOczn8z7l3JQRNBEL_ZJ3iQo | B17: Joyjoy Café | C17: Curitiba | D17: triagem manual | E17: Av. Presidente Affonso Camargo, 1939 - Lj 02 - Cristo Rei, Curitiba - PR, 80050-370, Brazil | F17: 4.8 | G17: 690 | H17: https://maps.google.com/?cid=759269485382930740&g_mp=CiVnb29nbGUubWFwcy5wbGFjZXMudjEuUGxhY2VzLkdldFBsYWNlEAIYBCAA | I17: 6 | J17: 37 | K17: 14:00 | L17: 23:00 | N17: 18:00-23:00 | O17: 18:00-23:00 | P17: 18:00-23:00 | Q17: 18:00-23:00 | R17: 14:00-23:00 | S17: 14:00-22:00 | T17: 0 | U17: 0 | Z17: joyjoycafe | AA17: 25555 | AB17: 627 | AC17: 2020-02-16 | AD17: 6 | AE17: 1721 | AF17: 114 | AH17: 2 | AI17: sim | AJ17: =IFERROR(INDEX(cesta!$O$2:$O$43,MATCH($A17,cesta!$A$2:$A$43,0)),"") | AK17: =IFERROR(INDEX(cesta!$P$2:$P$43,MATCH($A17,cesta!$A$2:$A$43,0)),"") | AL17: =IFERROR(INDEX(cesta!$Q$2:$Q$43,MATCH($A17,cesta!$A$2:$A$43,0)),"") | AM17: 1010 | AN17: acervodejogos | AO17: 50 | AP17: 17
A18: ChIJK5Dhtunj3JQRniPWHB3haDU | B18: Paladino Hobbies | C18: Curitiba | D18: triagem manual | E18: R. Padre Anchieta, 2454 - Lj 24 - Bigorrilho, Curitiba - PR, 80730-000, Brazil | F18: 4.8 | G18: 188 | H18: https://maps.google.com/?cid=3848573396742185886&g_mp=CiVnb29nbGUubWFwcy5wbGFjZXMudjEuUGxhY2VzLkdldFBsYWNlEAIYBCAA | I18: 4 | J18: 22 | K18: 12:00 | L18: 19:00 | O18: 13:00-19:00 | P18: 13:00-19:00 | Q18: 13:00-19:00 | R18: 12:00-16:00 | T18: 0 | U18: 0 | Y18: 293 | Z18: paladinohobbies | AA18: 1432 | AB18: 140 | AC18: 2020-03-26 | AD18: 1 | AE18: 1 | AF18: 0 | AJ18: =IFERROR(INDEX(cesta!$O$2:$O$43,MATCH($A18,cesta!$A$2:$A$43,0)),"") | AK18: =IFERROR(INDEX(cesta!$P$2:$P$43,MATCH($A18,cesta!$A$2:$A$43,0)),"") | AL18: =IFERROR(INDEX(cesta!$Q$2:$Q$43,MATCH($A18,cesta!$A$2:$A$43,0)),"") | AO18: 2 | AP18: 0
A19: ChIJc66HomXk3JQRNl28jz_VsPc | B19: Taverna Game House | C19: Curitiba | D19: triagem manual | E19: R. Alferes Poli, 589 - Centro, Curitiba - PR, 80220-050, Brazil | F19: 4.8 | G19: 625 | H19: https://maps.google.com/?cid=17847999792240418102&g_mp=CiVnb29nbGUubWFwcy5wbGFjZXMudjEuUGxhY2VzLkdldFBsYWNlEAIYBCAA | I19: 6 | J19: 48 | K19: 14:00 | L19: 22:00 | M19: 14:00-22:00 | N19: 14:00-22:00 | O19: 14:00-22:00 | P19: 14:00-22:00 | Q19: 14:00-22:00 | R19: 14:00-22:00 | T19: 0 | U19: 0 | Y19: 358 | Z19: tavernagamehouse | AA19: 3168 | AB19: 1832 | AC19: 2017-09-26 | AD19: 26 | AE19: 611 | AF19: 9 | AJ19: =IFERROR(INDEX(cesta!$O$2:$O$43,MATCH($A19,cesta!$A$2:$A$43,0)),"") | AK19: =IFERROR(INDEX(cesta!$P$2:$P$43,MATCH($A19,cesta!$A$2:$A$43,0)),"") | AL19: =IFERROR(INDEX(cesta!$Q$2:$Q$43,MATCH($A19,cesta!$A$2:$A$43,0)),"") | AO19: 13 | AP19: 5
A20: ChIJ1wjBJD7k3JQRQi7trfp_0aQ | B20: Vila Celta Hobby Store - Jogos e Café | C20: Curitiba | D20: triagem manual | E20: Av. Pres. Getúlio Vargas, 659 - Rebouças, Curitiba - PR, 80240-040, Brazil | F20: 4.8 | G20: 751 | H20: https://maps.google.com/?cid=11876414406989262402&g_mp=CiVnb29nbGUubWFwcy5wbGFjZXMudjEuUGxhY2VzLkdldFBsYWNlEAIYBCAA | I20: 7 | J20: 73.5 | K20: 10:00 | L20: 24:00 | M20: 10:30-19:00 | N20: 10:30-21:00 | O20: 10:30-21:00 | P20: 10:30-21:00 | Q20: 10:30-00:00 | R20: 10:00-00:00 | S20: 13:00-19:00 | T20: 0 | U20: 0 | Y20: 590 | Z20: vilacelta | AA20: 11711 | AB20: 566 | AC20: 2016-11-22 | AD20: 2 | AE20: 69 | AF20: 7 | AJ20: =IFERROR(INDEX(cesta!$O$2:$O$43,MATCH($A20,cesta!$A$2:$A$43,0)),"") | AK20: =IFERROR(INDEX(cesta!$P$2:$P$43,MATCH($A20,cesta!$A$2:$A$43,0)),"") | AL20: =IFERROR(INDEX(cesta!$Q$2:$Q$43,MATCH($A20,cesta!$A$2:$A$43,0)),"") | AO20: 13 | AP20: 8
A21: ChIJawIVeV0JM0oR5BtnD_poQeA | B21: CCG Floripa | C21: Florianópolis | D21: triagem manual | E21: R. Lauro Linhares, 245 - Trindade, Florianópolis - SC, 88036-000, Brazil | F21: 4.8 | G21: 194 | H21: https://maps.google.com/?cid=16159312361191578596&g_mp=CiVnb29nbGUubWFwcy5wbGFjZXMudjEuUGxhY2VzLkdldFBsYWNlEAIYBCAA | I21: 5 | J21: 42 | K21: 13:00 | L21: 23:00 | N21: 14:00-23:00 | O21: 14:00-23:00 | P21: 14:00-23:00 | Q21: 14:00-23:00 | R21: 13:00-19:00 | T21: 0 | U21: 0 | Y21: 294 | Z21: ccg_floripa | AA21: 11321 | AB21: 446 | AC21: 2021-08-27 | AD21: 2 | AE21: 668 | AF21: 21 | AH21: 7 | AI21: não encontrado | AJ21: =IFERROR(INDEX(cesta!$O$2:$O$43,MATCH($A21,cesta!$A$2:$A$43,0)),"") | AK21: =IFERROR(INDEX(cesta!$P$2:$P$43,MATCH($A21,cesta!$A$2:$A$43,0)),"") | AL21: =IFERROR(INDEX(cesta!$Q$2:$Q$43,MATCH($A21,cesta!$A$2:$A$43,0)),"") | AO21: 11 | AP21: 5
A22: ChIJc3F7ka83J5URQZ1XTl-_iak | B22: Chef on Play | C22: Florianópolis | D22: triagem manual | E22: Rua kk - atrás do bem bolado bar - Praça Atílio ferreira, 07 - Trindade, Florianópolis - SC, 88080-701, Brazil | F22: 4.6 | G22: 1204 | H22: https://maps.google.com/?cid=12216505880276344129&g_mp=CiVnb29nbGUubWFwcy5wbGFjZXMudjEuUGxhY2VzLkdldFBsYWNlEAIYBCAA | I22: 7 | J22: 35.5 | K22: 18:30 | L22: 24:00 | M22: 18:30-23:30 | N22: 18:30-23:30 | O22: 18:30-23:30 | P22: 18:30-23:30 | Q22: 18:30-00:00 | R22: 18:30-00:00 | S22: 18:30-23:00 | T22: 0 | U22: 0 | Y22: 834 | Z22: chefonplay | AA22: 10739 | AB22: 517 | AC22: 2015-11-22 | AD22: 0 | AE22: 0 | AF22: 0 | AH22: 72 | AI22: não encontrado | AJ22: =IFERROR(INDEX(cesta!$O$2:$O$43,MATCH($A22,cesta!$A$2:$A$43,0)),"") | AK22: =IFERROR(INDEX(cesta!$P$2:$P$43,MATCH($A22,cesta!$A$2:$A$43,0)),"") | AL22: =IFERROR(INDEX(cesta!$Q$2:$Q$43,MATCH($A22,cesta!$A$2:$A$43,0)),"") | AM22: 245 | AN22: ludopedia | AO22: 15 | AP22: 12
A23: ChIJJz8-gcY3J5URYdZrEXdHaAk | B23: Cineplay- Restaurante e Jogos | C23: Florianópolis | D23: triagem manual | E23: R. Getúlio Vargas, 362 - Centro, São José - SC, 88103-400, Brazil | F23: 4.5 | G23: 1154 | H23: https://maps.google.com/?cid=677870320638219873&g_mp=CiVnb29nbGUubWFwcy5wbGFjZXMudjEuUGxhY2VzLkdldFBsYWNlEAIYBCAA | I23: 7 | J23: 43 | K23: 11:00 | L23: 24:00 | M23: 11:00-14:00 | N23: 11:00-13:30 | 19:00-00:00 | O23: 11:00-13:30 | 19:00-00:00 | P23: 11:00-13:30 | 19:00-00:00 | Q23: 11:00-13:30 | 19:00-00:00 | R23: 19:00-00:00 | S23: 19:00-00:00 | T23: 0 | U23: 0 | Z23: cineplay_sc | AA23: 87929 | AB23: 1689 | AC23: 2018-06-04 | AD23: 25 | AE23: 4695 | AF23: 362 | AH23: 112 | AI23: não encontrado | AJ23: =IFERROR(INDEX(cesta!$O$2:$O$43,MATCH($A23,cesta!$A$2:$A$43,0)),"") | AK23: =IFERROR(INDEX(cesta!$P$2:$P$43,MATCH($A23,cesta!$A$2:$A$43,0)),"") | AL23: =IFERROR(INDEX(cesta!$Q$2:$Q$43,MATCH($A23,cesta!$A$2:$A$43,0)),"") | AO23: 48 | AP23: 23
A24: ChIJ0yXbI35IxwcR0_jLi-uINUU | B24: Balboa's Hobby Games | C24: Fortaleza | D24: triagem manual | E24: R. Maria Tomásia, 208 - Aldeota, Fortaleza - CE, 60150-170, Brazil | F24: 4.8 | G24: 881 | H24: https://maps.google.com/?cid=4987042707626784979&g_mp=CiVnb29nbGUubWFwcy5wbGFjZXMudjEuUGxhY2VzLkdldFBsYWNlEAIYBCAA | I24: 5 | J24: 27 | K24: 15:00 | L24: 22:00 | O24: 17:00-22:00 | P24: 17:00-22:00 | Q24: 17:00-22:00 | R24: 15:00-22:00 | S24: 15:00-20:00 | T24: 0 | U24: 0 | Y24: 228 | Z24: balboashobbygames | AA24: 21318 | AB24: 1724 | AC24: 2014-06-02 | AD24: 22 | AE24: 2323 | AF24: 108 | AH24: 36 | AI24: não encontrado | AJ24: =IFERROR(INDEX(cesta!$O$2:$O$43,MATCH($A24,cesta!$A$2:$A$43,0)),"") | AK24: =IFERROR(INDEX(cesta!$P$2:$P$43,MATCH($A24,cesta!$A$2:$A$43,0)),"") | AL24: =IFERROR(INDEX(cesta!$Q$2:$Q$43,MATCH($A24,cesta!$A$2:$A$43,0)),"") | AM24: 1833 | AN24: acervodejogos | AO24: 15 | AP24: 9
A25: ChIJQURqeMZJxwcR95O-XLbS2mk | B25: Dominaria Cards & Games | C25: Fortaleza | D25: triagem manual | E25: R. Juvenal Galeno, 512 - Benfica, Fortaleza - CE, 60015-340, Brazil | F25: 4.7 | G25: 305 | H25: https://maps.google.com/?cid=7627640599587230711&g_mp=CiVnb29nbGUubWFwcy5wbGFjZXMudjEuUGxhY2VzLkdldFBsYWNlEAIYBCAA | I25: 7 | J25: 77 | K25: 08:00 | L25: 21:00 | M25: 10:00-21:00 | N25: 10:00-21:00 | O25: 10:00-21:00 | P25: 10:00-21:00 | Q25: 10:00-21:00 | R25: 08:00-19:00 | S25: 08:00-19:00 | T25: 1 | U25: 2 | V25: 95 | Y25: 96 | Z25: dominariacg.sp | AA25: 1971 | AB25: 33 | AC25: 2024-09-27 | AD25: 0 | AE25: 0 | AF25: 0 | AG25: perfil da unidade de São Paulo; a casa aprovada fica em Fortaleza (@dominariacg) | AJ25: =IFERROR(INDEX(cesta!$O$2:$O$43,MATCH($A25,cesta!$A$2:$A$43,0)),"") | AK25: =IFERROR(INDEX(cesta!$P$2:$P$43,MATCH($A25,cesta!$A$2:$A$43,0)),"") | AL25: =IFERROR(INDEX(cesta!$Q$2:$Q$43,MATCH($A25,cesta!$A$2:$A$43,0)),"") | AO25: 19 | AP25: 14
A26: ChIJ89uEICDxXpMRdaEvN0XiWK0 | B26: Paladins Game Store | C26: Goiânia | D26: triagem manual | E26: Galeria Free Shop - R. S-1, 54 - St. Bueno, Goiânia - GO, 74230-020, Brazil | F26: 4.7 | G26: 906 | H26: https://maps.google.com/?cid=12490982353418559861&g_mp=CiVnb29nbGUubWFwcy5wbGFjZXMudjEuUGxhY2VzLkdldFBsYWNlEAIYBCAA | I26: 7 | J26: 70 | K26: 10:00 | L26: 22:00 | M26: 10:00-20:00 | N26: 10:00-20:00 | O26: 10:00-20:00 | P26: 10:00-22:00 | Q26: 10:00-22:00 | R26: 10:00-18:00 | S26: 10:00-18:00 | T26: 0 | U26: 0 | Y26: 5 | Z26: paladinsgames | AA26: 9690 | AB26: 1376 | AC26: 2015-01-29 | AD26: 1 | AE26: 154 | AF26: 3 | AJ26: =IFERROR(INDEX(cesta!$O$2:$O$43,MATCH($A26,cesta!$A$2:$A$43,0)),"") | AK26: =IFERROR(INDEX(cesta!$P$2:$P$43,MATCH($A26,cesta!$A$2:$A$43,0)),"") | AL26: =IFERROR(INDEX(cesta!$Q$2:$Q$43,MATCH($A26,cesta!$A$2:$A$43,0)),"") | AM26: 214 | AN26: acervodejogos | AO26: 14 | AP26: 7
A27: ChIJHSDPTgF5GZURKmSqKITyoGM | B27: Arcadea Gaming Pub | C27: Porto Alegre | D27: triagem manual | E27: R. Gen. Neto, 440 - Moinhos de Vento, Porto Alegre - RS, 90560-020, Brazil | F27: 4.2 | G27: 1087 | H27: https://maps.google.com/?cid=7179004455460430890&g_mp=CiVnb29nbGUubWFwcy5wbGFjZXMudjEuUGxhY2VzLkdldFBsYWNlEAIYBCAA | I27: 7 | J27: 42 | K27: 17:00 | L27: 24:00 | M27: 18:00-00:00 | N27: 18:00-00:00 | O27: 18:00-00:00 | P27: 18:00-00:00 | Q27: 18:00-00:00 | R27: 18:00-00:00 | S27: 17:00-23:00 | T27: 0 | U27: 0 | Y27: 591 | Z27: arcadeapub | AA27: 45836 | AB27: 2009 | AC27: 2019-09-09 | AD27: 29 | AE27: 1106 | AF27: 12 | AH27: 94 | AI27: não encontrado | AJ27: =IFERROR(INDEX(cesta!$O$2:$O$43,MATCH($A27,cesta!$A$2:$A$43,0)),"") | AK27: =IFERROR(INDEX(cesta!$P$2:$P$43,MATCH($A27,cesta!$A$2:$A$43,0)),"") | AL27: =IFERROR(INDEX(cesta!$Q$2:$Q$43,MATCH($A27,cesta!$A$2:$A$43,0)),"") | AO27: 19 | AP27: 11
A28: ChIJ41pgHNFDGZURC7yTegyn7nU | B28: Toca do Rato - Pizzaria e Jogos de Tabuleiro | C28: Porto Alegre | D28: acervodejogos | E28: Av. Capivara, 241 - Bom Jardim, Ivoti - RS, 93900-000 | F28: 4.8 | G28: 138 | H28: https://maps.google.com/?cid=8497913218932653067 | I28: 6 | J28: 26.5 | K28: 18:00 | L28: 23:00 | M28: 18:30-22:00 | N28: 18:30-23:00 | O28: 18:30-23:00 | P28: 18:30-23:00 | Q28: 18:30-23:00 | R28: 18:00-23:00 | T28: 0 | U28: 0 | Y28: 583 | Z28: tocadorato_oficial | AC28: 2023-07-15 | AD28: 9 | AE28: 309 | AF28: 17 | AH28: 25 | AI28: não encontrado | AJ28: =IFERROR(INDEX(cesta!$O$2:$O$43,MATCH($A28,cesta!$A$2:$A$43,0)),"") | AK28: =IFERROR(INDEX(cesta!$P$2:$P$43,MATCH($A28,cesta!$A$2:$A$43,0)),"") | AL28: =IFERROR(INDEX(cesta!$Q$2:$Q$43,MATCH($A28,cesta!$A$2:$A$43,0)),"") | AM28: 287 | AN28: acervodejogos
A29: ChIJRUjwU66WoGgRzc9yJU7jkwM | B29: Nala Land - Bar de Jogos de Tabuleiro em Recife | C29: Recife | D29: triagem manual | E29: R. Raul Pompéia, 271 - Arruda, Recife - PE, 52120-150, Brazil | F29: 4.9 | G29: 206 | H29: https://maps.google.com/?cid=257799528465485773&g_mp=CiVnb29nbGUubWFwcy5wbGFjZXMudjEuUGxhY2VzLkdldFBsYWNlEAIYBCAA | I29: 4 | J29: 28 | K29: 14:00 | L29: 24:00 | P29: 18:00-00:00 | Q29: 18:00-00:00 | R29: 16:00-00:00 | S29: 14:00-22:00 | T29: 0 | U29: 0 | Z29: nalaland.jogos | AA29: 27673 | AB29: 655 | AC29: 2021-05-22 | AD29: 17 | AE29: 1058 | AF29: 114 | AH29: 25 | AI29: não encontrado | AJ29: =IFERROR(INDEX(cesta!$O$2:$O$43,MATCH($A29,cesta!$A$2:$A$43,0)),"") | AK29: =IFERROR(INDEX(cesta!$P$2:$P$43,MATCH($A29,cesta!$A$2:$A$43,0)),"") | AL29: =IFERROR(INDEX(cesta!$Q$2:$Q$43,MATCH($A29,cesta!$A$2:$A$43,0)),"") | AM29: 312 | AN29: rejoy | AO29: 10 | AP29: 7
A30: ChIJu1yUroF_mQAR7qxqAfxKSw4 | B30: Game Of Boards | C30: Rio de Janeiro | D30: triagem manual | E30: Rua da Passagem, 142 - Botafogo, Rio de Janeiro - RJ, 22290-031, Brazil | F30: 4.7 | G30: 1077 | H30: https://maps.google.com/?cid=1029999386000272622&g_mp=CiVnb29nbGUubWFwcy5wbGFjZXMudjEuUGxhY2VzLkdldFBsYWNlEAIYBCAA | I30: 5 | J30: 41 | K30: 14:00 | L30: 24:00 | O30: 15:00-23:00 | P30: 15:00-23:00 | Q30: 15:00-23:00 | R30: 15:00-00:00 | S30: 14:00-22:00 | T30: 0 | U30: 1 | V30: 555 | Y30: 291 | Z30: gob.ludobar | AA30: 18453 | AB30: 3266 | AC30: 2016-03-28 | AD30: 21 | AE30: 789 | AF30: 76 | AH30: 2 | AI30: sim | AJ30: =IFERROR(INDEX(cesta!$O$2:$O$43,MATCH($A30,cesta!$A$2:$A$43,0)),"") | AK30: =IFERROR(INDEX(cesta!$P$2:$P$43,MATCH($A30,cesta!$A$2:$A$43,0)),"") | AL30: =IFERROR(INDEX(cesta!$Q$2:$Q$43,MATCH($A30,cesta!$A$2:$A$43,0)),"") | AO30: 8 | AP30: 6
A31: ChIJ90Gs_9rVmwAReA7MnIyPLTE | B31: Luderia Carioca | C31: Rio de Janeiro | D31: triagem manual | E31: R. do Catete, 62 - Catete, Rio de Janeiro - RJ, 22220-000, Brazil | F31: 4.7 | G31: 212 | H31: https://maps.google.com/?cid=3543646315899260536&g_mp=CiVnb29nbGUubWFwcy5wbGFjZXMudjEuUGxhY2VzLkdldFBsYWNlEAIYBCAA | I31: 5 | J31: 38 | K31: 14:00 | L31: 24:00 | O31: 17:00-23:00 | P31: 17:00-23:00 | Q31: 16:00-00:00 | R31: 14:00-00:00 | S31: 14:00-22:00 | T31: 2 | U31: 3 | V31: 302 | Y31: 576 | Z31: luderiacariocajogos | AA31: 16137 | AB31: 84 | AC31: 2025-03-12 | AD31: 5 | AE31: 809 | AF31: 20 | AH31: 36 | AI31: não encontrado | AJ31: =IFERROR(INDEX(cesta!$O$2:$O$43,MATCH($A31,cesta!$A$2:$A$43,0)),"") | AK31: =IFERROR(INDEX(cesta!$P$2:$P$43,MATCH($A31,cesta!$A$2:$A$43,0)),"") | AL31: =IFERROR(INDEX(cesta!$Q$2:$Q$43,MATCH($A31,cesta!$A$2:$A$43,0)),"") | AM31: 780 | AN31: acervodejogos | AO31: 99 | AP31: 69
A32: ChIJYzHxUhR-mQARpqVtYD9th0c | B32: Magic Store Brazil | C32: Rio de Janeiro | D32: triagem manual | E32: R. Teodoro da Silva, 240 - Vila Isabel, Rio de Janeiro - RJ, 20520-051, Brazil | F32: 4.7 | G32: 465 | H32: https://maps.google.com/?cid=5154208417516987814&g_mp=CiVnb29nbGUubWFwcy5wbGFjZXMudjEuUGxhY2VzLkdldFBsYWNlEAIYBCAA | I32: 6 | J32: 32 | K32: 13:00 | L32: 21:00 | N32: 15:30-17:00 | O32: 15:30-21:00 | P32: 15:30-21:00 | Q32: 15:30-21:00 | R32: 13:00-20:00 | S32: 13:00-20:00 | T32: 0 | U32: 0 | Y32: 312 | Z32: magicstorebrasil | AA32: 23364 | AB32: 308 | AC32: 2018-11-23 | AD32: 4 | AE32: 132 | AF32: 3 | AJ32: =IFERROR(INDEX(cesta!$O$2:$O$43,MATCH($A32,cesta!$A$2:$A$43,0)),"") | AK32: =IFERROR(INDEX(cesta!$P$2:$P$43,MATCH($A32,cesta!$A$2:$A$43,0)),"") | AL32: =IFERROR(INDEX(cesta!$Q$2:$Q$43,MATCH($A32,cesta!$A$2:$A$43,0)),"") | AO32: 15 | AP32: 7
A33: ChIJ1SAzAGF_mQARQgP-yrPBxbQ | B33: RED jogos | C33: Rio de Janeiro | D33: triagem manual | E33: Av. Treze de Maio, 23 - sala 533 - Centro, Rio de Janeiro - RJ, 20031-902, Brazil | F33: 4.7 | G33: 800 | H33: https://maps.google.com/?cid=13026030475187979074&g_mp=CiVnb29nbGUubWFwcy5wbGFjZXMudjEuUGxhY2VzLkdldFBsYWNlEAIYBCAA | I33: 6 | J33: 47 | K33: 11:00 | L33: 20:00 | M33: 12:00-20:00 | N33: 12:00-20:00 | O33: 12:00-20:00 | P33: 12:00-20:00 | Q33: 12:00-20:00 | R33: 11:00-18:00 | T33: 2 | U33: 3 | V33: 161 | Y33: 496 | Z33: lojaredjogos | AA33: 21522 | AB33: 1164 | AC33: 2015-10-09 | AD33: 12 | AE33: 968 | AF33: 103 | AJ33: =IFERROR(INDEX(cesta!$O$2:$O$43,MATCH($A33,cesta!$A$2:$A$43,0)),"") | AK33: =IFERROR(INDEX(cesta!$P$2:$P$43,MATCH($A33,cesta!$A$2:$A$43,0)),"") | AL33: =IFERROR(INDEX(cesta!$Q$2:$Q$43,MATCH($A33,cesta!$A$2:$A$43,0)),"") | AO33: 10 | AP33: 6
A34: ChIJOcVssmeDmQARZZrnWu2mnwA | B34: TabuClub | C34: Rio de Janeiro | D34: acervodejogos | E34: R. Newton Prado, 29 - Santa Rosa, Niterói - RJ, 24240-004 | F34: 4.7 | G34: 105 | H34: https://maps.google.com/?cid=44938059659582053 | I34: 6 | J34: 43 | K34: 14:00 | L34: 24:00 | N34: 17:00-23:00 | O34: 17:00-23:00 | P34: 17:00-23:00 | Q34: 17:00-00:00 | R34: 14:00-00:00 | S34: 14:00-22:00 | T34: 0 | U34: 0 | Y34: 153 | Z34: tabuclubnit | AC34: 2023-07-22 | AD34: 8 | AE34: 1576 | AF34: 85 | AH34: 75 | AI34: não encontrado | AJ34: =IFERROR(INDEX(cesta!$O$2:$O$43,MATCH($A34,cesta!$A$2:$A$43,0)),"") | AK34: =IFERROR(INDEX(cesta!$P$2:$P$43,MATCH($A34,cesta!$A$2:$A$43,0)),"") | AL34: =IFERROR(INDEX(cesta!$Q$2:$Q$43,MATCH($A34,cesta!$A$2:$A$43,0)),"") | AM34: 1357 | AN34: acervodejogos
A35: ChIJoTlvBfMbFgcRHvuCKHBQrXQ | B35: São Jogue - Bela Vista | C35: Salvador | D35: triagem manual | E35: Alameda Euvaldo Luz, 92 - Pernambués, Salvador - BA, 41098-020, Brazil | F35: 4.8 | G35: 787 | H35: https://maps.google.com/?cid=8407464522016815902&g_mp=CiVnb29nbGUubWFwcy5wbGFjZXMudjEuUGxhY2VzLkdldFBsYWNlEAIYBCAA | I35: 7 | J35: 68 | K35: 12:00 | L35: 22:00 | M35: 12:00-22:00 | N35: 12:00-22:00 | O35: 12:00-22:00 | P35: 12:00-22:00 | Q35: 12:00-22:00 | R35: 12:00-22:00 | S35: 13:00-21:00 | T35: 1 | U35: 2 | V35: 387 | Y35: 118 | Z35: saojogue | AA35: 38492 | AB35: 2036 | AC35: 2017-11-15 | AD35: 26 | AE35: 8448 | AF35: 251 | AH35: 56 | AI35: não encontrado | AJ35: =IFERROR(INDEX(cesta!$O$2:$O$43,MATCH($A35,cesta!$A$2:$A$43,0)),"") | AK35: =IFERROR(INDEX(cesta!$P$2:$P$43,MATCH($A35,cesta!$A$2:$A$43,0)),"") | AL35: =IFERROR(INDEX(cesta!$Q$2:$Q$43,MATCH($A35,cesta!$A$2:$A$43,0)),"") | AM35: 370 | AN35: acervodejogos | AO35: 5 | AP35: 4
A36: ChIJYTHwWgBbzpQRFenbJdM5cxU | B36: Arena BG | Jogos de Tabuleiro | Hamburgueria | C36: São Paulo | D36: triagem manual | E36: R. Lino Coutinho, 1791 - Ipiranga, São Paulo - SP, 04207-002, Brazil | F36: 4.8 | G36: 145 | H36: https://maps.google.com/?cid=1545642676154263829&g_mp=CiVnb29nbGUubWFwcy5wbGFjZXMudjEuUGxhY2VzLkdldFBsYWNlEAIYBCAA | I36: 5 | J36: 33 | K36: 14:00 | L36: 25:00 | O36: 17:00-22:00 | P36: 17:00-22:00 | Q36: 17:00-00:00 | R36: 17:00-01:00 | S36: 14:00-22:00 | T36: 1 | U36: 1 | V36: 351 | Z36: aarenabg | AA36: 6682 | AB36: 520 | AC36: 2024-05-08 | AD36: 32 | AE36: 688 | AF36: 67 | AH36: 65 | AI36: sim | AJ36: =IFERROR(INDEX(cesta!$O$2:$O$43,MATCH($A36,cesta!$A$2:$A$43,0)),"") | AK36: =IFERROR(INDEX(cesta!$P$2:$P$43,MATCH($A36,cesta!$A$2:$A$43,0)),"") | AL36: =IFERROR(INDEX(cesta!$Q$2:$Q$43,MATCH($A36,cesta!$A$2:$A$43,0)),"") | AM36: 540 | AN36: ludopedia | AO36: 17 | AP36: 13
A37: ChIJKeHwNv5ZzpQRlmzx9rCTWdM | B37: Bodogami Restaurante e Cafeteria | C37: São Paulo | D37: triagem manual | E37: Av. da Liberdade, 456 - Liberdade, São Paulo - SP, 01502-001, Brazil | F37: 4.6 | G37: 3386 | H37: https://maps.google.com/?cid=15229366003196587158&g_mp=CiVnb29nbGUubWFwcy5wbGFjZXMudjEuUGxhY2VzLkdldFBsYWNlEAIYBCAA | I37: 7 | J37: 77 | K37: 11:00 | L37: 22:30 | M37: 11:00-22:00 | N37: 11:00-22:00 | O37: 11:00-22:00 | P37: 11:00-22:00 | Q37: 11:00-22:30 | R37: 11:00-22:30 | S37: 11:00-21:00 | T37: 1 | U37: 2 | V37: 204 | Y37: 163 | Z37: bodogami | AA37: 74000 | AB37: 2374 | AC37: 2017-01-12 | AD37: 4 | AE37: 444 | AF37: 8 | AH37: 89 | AI37: não encontrado | AJ37: =IFERROR(INDEX(cesta!$O$2:$O$43,MATCH($A37,cesta!$A$2:$A$43,0)),"") | AK37: =IFERROR(INDEX(cesta!$P$2:$P$43,MATCH($A37,cesta!$A$2:$A$43,0)),"") | AL37: =IFERROR(INDEX(cesta!$Q$2:$Q$43,MATCH($A37,cesta!$A$2:$A$43,0)),"") | AM37: 934 | AN37: acervodejogos | AO37: 712 | AP37: 453
A38: ChIJ__9TTnxCzpQRwVSzrOijkRY | B38: Bravo Jogos | C38: São Paulo | D38: triagem manual | E38: Rua Coronel Alfredo Flaquer, 411 - Centro, Santo André - SP, 09020-030, Brazil | F38: 4.9 | G38: 1719 | H38: https://maps.google.com/?cid=1626261160182633665&g_mp=CiVnb29nbGUubWFwcy5wbGFjZXMudjEuUGxhY2VzLkdldFBsYWNlEAIYBCAA | I38: 5 | J38: 55 | K38: 10:00 | L38: 21:00 | N38: 10:00-21:00 | O38: 10:00-21:00 | P38: 10:00-21:00 | Q38: 10:00-21:00 | R38: 10:00-21:00 | T38: 0 | U38: 0 | Y38: 684 | Z38: bravojogos | AA38: 65145 | AB38: 1782 | AD38: 14 | AE38: 7178 | AF38: 222 | AJ38: =IFERROR(INDEX(cesta!$O$2:$O$43,MATCH($A38,cesta!$A$2:$A$43,0)),"") | AK38: =IFERROR(INDEX(cesta!$P$2:$P$43,MATCH($A38,cesta!$A$2:$A$43,0)),"") | AL38: =IFERROR(INDEX(cesta!$Q$2:$Q$43,MATCH($A38,cesta!$A$2:$A$43,0)),"") | AO38: 32 | AP38: 24
A39: ChIJrT_EWwBZzpQRGAZzptZbtsY | B39: Cartola Luderia Bar | C39: São Paulo | D39: triagem manual | E39: R. Dr. Siqueira Campos, 42 - Liberdade, São Paulo - SP, 01153-000, Brazil | F39: 4.7 | G39: 242 | H39: https://maps.google.com/?cid=14318733042744755736&g_mp=CiVnb29nbGUubWFwcy5wbGFjZXMudjEuUGxhY2VzLkdldFBsYWNlEAIYBCAA | I39: 3 | J39: 19.5 | K39: 17:00 | L39: 23:30 | P39: 17:00-23:30 | Q39: 17:00-23:30 | R39: 17:00-23:30 | T39: 0 | U39: 2 | V39: 607 | Y39: 907 | Z39: cartolaluderia | AA39: 11500 | AB39: 670 | AC39: 2024-03-23 | AD39: 21 | AE39: 1061 | AF39: 24 | AH39: 50 | AI39: não encontrado | AJ39: =IFERROR(INDEX(cesta!$O$2:$O$43,MATCH($A39,cesta!$A$2:$A$43,0)),"") | AK39: =IFERROR(INDEX(cesta!$P$2:$P$43,MATCH($A39,cesta!$A$2:$A$43,0)),"") | AL39: =IFERROR(INDEX(cesta!$Q$2:$Q$43,MATCH($A39,cesta!$A$2:$A$43,0)),"") | AO39: 51 | AP39: 38
A40: ChIJbZRHQPRfzpQRz97-ZOg0yXA | B40: Castelos Bar & Boardgames | C40: São Paulo | D40: triagem manual | E40: R. Serra de Botucatu, 995 - Vila Gomes Cardim, São Paulo - SP, 03317-000, Brazil | F40: 4.6 | G40: 617 | H40: https://maps.google.com/?cid=8127085175298252495&g_mp=CiVnb29nbGUubWFwcy5wbGFjZXMudjEuUGxhY2VzLkdldFBsYWNlEAIYBCAA | I40: 5 | J40: 29 | K40: 14:00 | L40: 23:00 | O40: 18:00-23:00 | P40: 18:00-23:00 | Q40: 18:00-23:00 | R40: 16:00-23:00 | S40: 14:00-21:00 | T40: 0 | U40: 1 | V40: 577 | Z40: castelosbareboardgames | AA40: 41545 | AB40: 1358 | AC40: 2019-11-17 | AD40: 1 | AE40: 20 | AF40: 0 | AH40: 66 | AI40: não encontrado | AJ40: =IFERROR(INDEX(cesta!$O$2:$O$43,MATCH($A40,cesta!$A$2:$A$43,0)),"") | AK40: =IFERROR(INDEX(cesta!$P$2:$P$43,MATCH($A40,cesta!$A$2:$A$43,0)),"") | AL40: =IFERROR(INDEX(cesta!$Q$2:$Q$43,MATCH($A40,cesta!$A$2:$A$43,0)),"") | AM40: 225 | AN40: ludopedia | AO40: 80 | AP40: 48
...

Sheet por_capital
A1: capital | B1: casas | C1: com cardápio | D1: cesta mediana (média, R$) | E1: seguidores (média) | F1: posts no período (média) | G1: horas por semana (média) | H1: nota média (média) | I1: avaliações B2 (soma)
A2: Belo Horizonte | B2: =COUNTIF(estabelecimentos!$C$2:$C$55,A2) | C2: =COUNTIFS(estabelecimentos!$C$2:$C$55,A2,estabelecimentos!$AK$2:$AK$55,">0") | D2: =IFERROR(AVERAGEIFS(estabelecimentos!$AK$2:$AK$55,estabelecimentos!$C$2:$C$55,A2,estabelecimentos!$AK$2:$AK$55,">0"),"") | E2: =IFERROR(AVERAGEIFS(estabelecimentos!$AA$2:$AA$55,estabelecimentos!$C$2:$C$55,A2),"") | F2: =IFERROR(AVERAGEIFS(estabelecimentos!$AD$2:$AD$55,estabelecimentos!$C$2:$C$55,A2),"") | G2: =IFERROR(AVERAGEIFS(estabelecimentos!$J$2:$J$55,estabelecimentos!$C$2:$C$55,A2),"") | H2: =IFERROR(AVERAGEIFS(estabelecimentos!$F$2:$F$55,estabelecimentos!$C$2:$C$55,A2),"") | I2: =SUMIF(estabelecimentos!$C$2:$C$55,A2,estabelecimentos!$AO$2:$AO$55)
A3: Belém | B3: =COUNTIF(estabelecimentos!$C$2:$C$55,A3) | C3: =COUNTIFS(estabelecimentos!$C$2:$C$55,A3,estabelecimentos!$AK$2:$AK$55,">0") | D3: =IFERROR(AVERAGEIFS(estabelecimentos!$AK$2:$AK$55,estabelecimentos!$C$2:$C$55,A3,estabelecimentos!$AK$2:$AK$55,">0"),"") | E3: =IFERROR(AVERAGEIFS(estabelecimentos!$AA$2:$AA$55,estabelecimentos!$C$2:$C$55,A3),"") | F3: =IFERROR(AVERAGEIFS(estabelecimentos!$AD$2:$AD$55,estabelecimentos!$C$2:$C$55,A3),"") | G3: =IFERROR(AVERAGEIFS(estabelecimentos!$J$2:$J$55,estabelecimentos!$C$2:$C$55,A3),"") | H3: =IFERROR(AVERAGEIFS(estabelecimentos!$F$2:$F$55,estabelecimentos!$C$2:$C$55,A3),"") | I3: =SUMIF(estabelecimentos!$C$2:$C$55,A3,estabelecimentos!$AO$2:$AO$55)
A4: Brasília | B4: =COUNTIF(estabelecimentos!$C$2:$C$55,A4) | C4: =COUNTIFS(estabelecimentos!$C$2:$C$55,A4,estabelecimentos!$AK$2:$AK$55,">0") | D4: =IFERROR(AVERAGEIFS(estabelecimentos!$AK$2:$AK$55,estabelecimentos!$C$2:$C$55,A4,estabelecimentos!$AK$2:$AK$55,">0"),"") | E4: =IFERROR(AVERAGEIFS(estabelecimentos!$AA$2:$AA$55,estabelecimentos!$C$2:$C$55,A4),"") | F4: =IFERROR(AVERAGEIFS(estabelecimentos!$AD$2:$AD$55,estabelecimentos!$C$2:$C$55,A4),"") | G4: =IFERROR(AVERAGEIFS(estabelecimentos!$J$2:$J$55,estabelecimentos!$C$2:$C$55,A4),"") | H4: =IFERROR(AVERAGEIFS(estabelecimentos!$F$2:$F$55,estabelecimentos!$C$2:$C$55,A4),"") | I4: =SUMIF(estabelecimentos!$C$2:$C$55,A4,estabelecimentos!$AO$2:$AO$55)
A5: Curitiba | B5: =COUNTIF(estabelecimentos!$C$2:$C$55,A5) | C5: =COUNTIFS(estabelecimentos!$C$2:$C$55,A5,estabelecimentos!$AK$2:$AK$55,">0") | D5: =IFERROR(AVERAGEIFS(estabelecimentos!$AK$2:$AK$55,estabelecimentos!$C$2:$C$55,A5,estabelecimentos!$AK$2:$AK$55,">0"),"") | E5: =IFERROR(AVERAGEIFS(estabelecimentos!$AA$2:$AA$55,estabelecimentos!$C$2:$C$55,A5),"") | F5: =IFERROR(AVERAGEIFS(estabelecimentos!$AD$2:$AD$55,estabelecimentos!$C$2:$C$55,A5),"") | G5: =IFERROR(AVERAGEIFS(estabelecimentos!$J$2:$J$55,estabelecimentos!$C$2:$C$55,A5),"") | H5: =IFERROR(AVERAGEIFS(estabelecimentos!$F$2:$F$55,estabelecimentos!$C$2:$C$55,A5),"") | I5: =SUMIF(estabelecimentos!$C$2:$C$55,A5,estabelecimentos!$AO$2:$AO$55)
A6: Florianópolis | B6: =COUNTIF(estabelecimentos!$C$2:$C$55,A6) | C6: =COUNTIFS(estabelecimentos!$C$2:$C$55,A6,estabelecimentos!$AK$2:$AK$55,">0") | D6: =IFERROR(AVERAGEIFS(estabelecimentos!$AK$2:$AK$55,estabelecimentos!$C$2:$C$55,A6,estabelecimentos!$AK$2:$AK$55,">0"),"") | E6: =IFERROR(AVERAGEIFS(estabelecimentos!$AA$2:$AA$55,estabelecimentos!$C$2:$C$55,A6),"") | F6: =IFERROR(AVERAGEIFS(estabelecimentos!$AD$2:$AD$55,estabelecimentos!$C$2:$C$55,A6),"") | G6: =IFERROR(AVERAGEIFS(estabelecimentos!$J$2:$J$55,estabelecimentos!$C$2:$C$55,A6),"") | H6: =IFERROR(AVERAGEIFS(estabelecimentos!$F$2:$F$55,estabelecimentos!$C$2:$C$55,A6),"") | I6: =SUMIF(estabelecimentos!$C$2:$C$55,A6,estabelecimentos!$AO$2:$AO$55)
A7: Fortaleza | B7: =COUNTIF(estabelecimentos!$C$2:$C$55,A7) | C7: =COUNTIFS(estabelecimentos!$C$2:$C$55,A7,estabelecimentos!$AK$2:$AK$55,">0") | D7: =IFERROR(AVERAGEIFS(estabelecimentos!$AK$2:$AK$55,estabelecimentos!$C$2:$C$55,A7,estabelecimentos!$AK$2:$AK$55,">0"),"") | E7: =IFERROR(AVERAGEIFS(estabelecimentos!$AA$2:$AA$55,estabelecimentos!$C$2:$C$55,A7),"") | F7: =IFERROR(AVERAGEIFS(estabelecimentos!$AD$2:$AD$55,estabelecimentos!$C$2:$C$55,A7),"") | G7: =IFERROR(AVERAGEIFS(estabelecimentos!$J$2:$J$55,estabelecimentos!$C$2:$C$55,A7),"") | H7: =IFERROR(AVERAGEIFS(estabelecimentos!$F$2:$F$55,estabelecimentos!$C$2:$C$55,A7),"") | I7: =SUMIF(estabelecimentos!$C$2:$C$55,A7,estabelecimentos!$AO$2:$AO$55)
A8: Goiânia | B8: =COUNTIF(estabelecimentos!$C$2:$C$55,A8) | C8: =COUNTIFS(estabelecimentos!$C$2:$C$55,A8,estabelecimentos!$AK$2:$AK$55,">0") | D8: =IFERROR(AVERAGEIFS(estabelecimentos!$AK$2:$AK$55,estabelecimentos!$C$2:$C$55,A8,estabelecimentos!$AK$2:$AK$55,">0"),"") | E8: =IFERROR(AVERAGEIFS(estabelecimentos!$AA$2:$AA$55,estabelecimentos!$C$2:$C$55,A8),"") | F8: =IFERROR(AVERAGEIFS(estabelecimentos!$AD$2:$AD$55,estabelecimentos!$C$2:$C$55,A8),"") | G8: =IFERROR(AVERAGEIFS(estabelecimentos!$J$2:$J$55,estabelecimentos!$C$2:$C$55,A8),"") | H8: =IFERROR(AVERAGEIFS(estabelecimentos!$F$2:$F$55,estabelecimentos!$C$2:$C$55,A8),"") | I8: =SUMIF(estabelecimentos!$C$2:$C$55,A8,estabelecimentos!$AO$2:$AO$55)
A9: Porto Alegre | B9: =COUNTIF(estabelecimentos!$C$2:$C$55,A9) | C9: =COUNTIFS(estabelecimentos!$C$2:$C$55,A9,estabelecimentos!$AK$2:$AK$55,">0") | D9: =IFERROR(AVERAGEIFS(estabelecimentos!$AK$2:$AK$55,estabelecimentos!$C$2:$C$55,A9,estabelecimentos!$AK$2:$AK$55,">0"),"") | E9: =IFERROR(AVERAGEIFS(estabelecimentos!$AA$2:$AA$55,estabelecimentos!$C$2:$C$55,A9),"") | F9: =IFERROR(AVERAGEIFS(estabelecimentos!$AD$2:$AD$55,estabelecimentos!$C$2:$C$55,A9),"") | G9: =IFERROR(AVERAGEIFS(estabelecimentos!$J$2:$J$55,estabelecimentos!$C$2:$C$55,A9),"") | H9: =IFERROR(AVERAGEIFS(estabelecimentos!$F$2:$F$55,estabelecimentos!$C$2:$C$55,A9),"") | I9: =SUMIF(estabelecimentos!$C$2:$C$55,A9,estabelecimentos!$AO$2:$AO$55)
A10: Recife | B10: =COUNTIF(estabelecimentos!$C$2:$C$55,A10) | C10: =COUNTIFS(estabelecimentos!$C$2:$C$55,A10,estabelecimentos!$AK$2:$AK$55,">0") | D10: =IFERROR(AVERAGEIFS(estabelecimentos!$AK$2:$AK$55,estabelecimentos!$C$2:$C$55,A10,estabelecimentos!$AK$2:$AK$55,">0"),"") | E10: =IFERROR(AVERAGEIFS(estabelecimentos!$AA$2:$AA$55,estabelecimentos!$C$2:$C$55,A10),"") | F10: =IFERROR(AVERAGEIFS(estabelecimentos!$AD$2:$AD$55,estabelecimentos!$C$2:$C$55,A10),"") | G10: =IFERROR(AVERAGEIFS(estabelecimentos!$J$2:$J$55,estabelecimentos!$C$2:$C$55,A10),"") | H10: =IFERROR(AVERAGEIFS(estabelecimentos!$F$2:$F$55,estabelecimentos!$C$2:$C$55,A10),"") | I10: =SUMIF(estabelecimentos!$C$2:$C$55,A10,estabelecimentos!$AO$2:$AO$55)
A11: Rio de Janeiro | B11: =COUNTIF(estabelecimentos!$C$2:$C$55,A11) | C11: =COUNTIFS(estabelecimentos!$C$2:$C$55,A11,estabelecimentos!$AK$2:$AK$55,">0") | D11: =IFERROR(AVERAGEIFS(estabelecimentos!$AK$2:$AK$55,estabelecimentos!$C$2:$C$55,A11,estabelecimentos!$AK$2:$AK$55,">0"),"") | E11: =IFERROR(AVERAGEIFS(estabelecimentos!$AA$2:$AA$55,estabelecimentos!$C$2:$C$55,A11),"") | F11: =IFERROR(AVERAGEIFS(estabelecimentos!$AD$2:$AD$55,estabelecimentos!$C$2:$C$55,A11),"") | G11: =IFERROR(AVERAGEIFS(estabelecimentos!$J$2:$J$55,estabelecimentos!$C$2:$C$55,A11),"") | H11: =IFERROR(AVERAGEIFS(estabelecimentos!$F$2:$F$55,estabelecimentos!$C$2:$C$55,A11),"") | I11: =SUMIF(estabelecimentos!$C$2:$C$55,A11,estabelecimentos!$AO$2:$AO$55)
A12: Salvador | B12: =COUNTIF(estabelecimentos!$C$2:$C$55,A12) | C12: =COUNTIFS(estabelecimentos!$C$2:$C$55,A12,estabelecimentos!$AK$2:$AK$55,">0") | D12: =IFERROR(AVERAGEIFS(estabelecimentos!$AK$2:$AK$55,estabelecimentos!$C$2:$C$55,A12,estabelecimentos!$AK$2:$AK$55,">0"),"") | E12: =IFERROR(AVERAGEIFS(estabelecimentos!$AA$2:$AA$55,estabelecimentos!$C$2:$C$55,A12),"") | F12: =IFERROR(AVERAGEIFS(estabelecimentos!$AD$2:$AD$55,estabelecimentos!$C$2:$C$55,A12),"") | G12: =IFERROR(AVERAGEIFS(estabelecimentos!$J$2:$J$55,estabelecimentos!$C$2:$C$55,A12),"") | H12: =IFERROR(AVERAGEIFS(estabelecimentos!$F$2:$F$55,estabelecimentos!$C$2:$C$55,A12),"") | I12: =SUMIF(estabelecimentos!$C$2:$C$55,A12,estabelecimentos!$AO$2:$AO$55)
A13: São Paulo | B13: =COUNTIF(estabelecimentos!$C$2:$C$55,A13) | C13: =COUNTIFS(estabelecimentos!$C$2:$C$55,A13,estabelecimentos!$AK$2:$AK$55,">0") | D13: =IFERROR(AVERAGEIFS(estabelecimentos!$AK$2:$AK$55,estabelecimentos!$C$2:$C$55,A13,estabelecimentos!$AK$2:$AK$55,">0"),"") | E13: =IFERROR(AVERAGEIFS(estabelecimentos!$AA$2:$AA$55,estabelecimentos!$C$2:$C$55,A13),"") | F13: =IFERROR(AVERAGEIFS(estabelecimentos!$AD$2:$AD$55,estabelecimentos!$C$2:$C$55,A13),"") | G13: =IFERROR(AVERAGEIFS(estabelecimentos!$J$2:$J$55,estabelecimentos!$C$2:$C$55,A13),"") | H13: =IFERROR(AVERAGEIFS(estabelecimentos!$F$2:$F$55,estabelecimentos!$C$2:$C$55,A13),"") | I13: =SUMIF(estabelecimentos!$C$2:$C$55,A13,estabelecimentos!$AO$2:$AO$55)
A14: Vitória | B14: =COUNTIF(estabelecimentos!$C$2:$C$55,A14) | C14: =COUNTIFS(estabelecimentos!$C$2:$C$55,A14,estabelecimentos!$AK$2:$AK$55,">0") | D14: =IFERROR(AVERAGEIFS(estabelecimentos!$AK$2:$AK$55,estabelecimentos!$C$2:$C$55,A14,estabelecimentos!$AK$2:$AK$55,">0"),"") | E14: =IFERROR(AVERAGEIFS(estabelecimentos!$AA$2:$AA$55,estabelecimentos!$C$2:$C$55,A14),"") | F14: =IFERROR(AVERAGEIFS(estabelecimentos!$AD$2:$AD$55,estabelecimentos!$C$2:$C$55,A14),"") | G14: =IFERROR(AVERAGEIFS(estabelecimentos!$J$2:$J$55,estabelecimentos!$C$2:$C$55,A14),"") | H14: =IFERROR(AVERAGEIFS(estabelecimentos!$F$2:$F$55,estabelecimentos!$C$2:$C$55,A14),"") | I14: =SUMIF(estabelecimentos!$C$2:$C$55,A14,estabelecimentos!$AO$2:$AO$55)
A15: Total | B15: =SUM(B2:B14) | C15: =SUM(C2:C14) | D15: =IFERROR(AVERAGEIF(estabelecimentos!$AK$2:$AK$55,">0"),"") | E15: =AVERAGE(estabelecimentos!$AA$2:$AA$55) | F15: =AVERAGE(estabelecimentos!$AD$2:$AD$55) | G15: =AVERAGE(estabelecimentos!$J$2:$J$55) | H15: =AVERAGE(estabelecimentos!$F$2:$F$55) | I15: =SUM(I2:I14)
A16: Conferência (total − linhas da aba estabelecimentos; deve ser 0) | B16: =B15-COUNTA(estabelecimentos!$A$2:$A$55)

Sheet cesta
A1: place_id | B1: nome | C1: capital_endereco | D1: itens_com_preco | E1: couvert_no_cardapio | F1: couvert_p25 | G1: couvert_mediana | H1: couvert_p75 | I1: bebida_p25 | J1: bebida_mediana | K1: bebida_p75 | L1: entrada_ou_prato_p25 | M1: entrada_ou_prato_mediana | N1: entrada_ou_prato_p75 | O1: cesta_baixa | P1: cesta_mediana | Q1: cesta_alta | R1: hamburguer_mediana | S1: batata_mediana | T1: cerveja_mediana | U1: refrigerante_mediana | V1: drinks_mediana | W1: data_cardapio
A2: ChIJRcWOaPabpgARDvX2Bad0qb0 | B2: Bardo Mago | C2: Belo Horizonte | D2: 110 | E2: não encontrado | I2: 12 | J2: 20 | K2: 28 | L2: 28.5 | M2: 34 | N2: 43.5 | O2: =IF(OR(F2="",I2="",L2=""),"",F2+I2+L2) | P2: =IF(OR(G2="",J2="",M2=""),"",G2+J2+M2) | Q2: =IF(OR(H2="",K2="",N2=""),"",H2+K2+N2) | R2: 42 | T2: 12.5 | U2: 8 | V2: 26 | W2: sem data
A3: ChIJpzB8zc2XpgARoJTUu90J6Pw | B3: Comdado Bar e Jogos | C3: Belo Horizonte | D3: 55 | E3: sim | F3: 16.25 | G3: 17.5 | H3: 18.75 | I3: 11 | J3: 18 | K3: 25 | L3: 43.75 | M3: 50 | N3: 55 | O3: =IF(OR(F3="",I3="",L3=""),"",F3+I3+L3) | P3: =IF(OR(G3="",J3="",M3=""),"",G3+J3+M3) | Q3: =IF(OR(H3="",K3="",N3=""),"",H3+K3+N3) | R3: 50 | T3: 12 | V3: 25 | W3: 2023-06, 2025-12
A4: ChIJsUAT-dObpgARCT2C5QpnVKU | B4: Garagem do Nerd | C4: Belo Horizonte | D4: 1 | E4: sim | F4: 10 | G4: 10 | H4: 10 | O4: =IF(OR(F4="",I4="",L4=""),"",F4+I4+L4) | P4: =IF(OR(G4="",J4="",M4=""),"",G4+J4+M4) | Q4: =IF(OR(H4="",K4="",N4=""),"",H4+K4+N4) | W4: 2024-06-23
A5: ChIJ-17ZQDG9pgARc-AxpXmaNRU | B5: La Tabuleria | C5: Belo Horizonte | D5: 90 | E5: sim | F5: 20 | G5: 20 | H5: 20 | I5: 10 | J5: 20 | K5: 26 | L5: 28.5 | M5: 35 | N5: 41.5 | O5: =IF(OR(F5="",I5="",L5=""),"",F5+I5+L5) | P5: =IF(OR(G5="",J5="",M5=""),"",G5+J5+M5) | Q5: =IF(OR(H5="",K5="",N5=""),"",H5+K5+N5) | R5: 42 | S5: 37.5 | T5: 12 | U5: 8 | V5: 25 | W5: sem data
A6: ChIJx5jr3zGXpgARQGx9eX7TDmY | B6: LudoCafé | C6: Belo Horizonte | D6: 11 | E6: sim | F6: 18.75 | G6: 22.5 | H6: 26.25 | I6: 31.4 | J6: 34.4 | K6: 35.9 | L6: 37.9 | M6: 38.9 | N6: 39.9 | O6: =IF(OR(F6="",I6="",L6=""),"",F6+I6+L6) | P6: =IF(OR(G6="",J6="",M6=""),"",G6+J6+M6) | Q6: =IF(OR(H6="",K6="",N6=""),"",H6+K6+N6) | V6: 38.9 | W6: 2024-06-23, 2024-11-16
A7: ChIJ6ZLMZw-XpgAR_OR6SwY5xKo | B7: Shelf Bar e Jogos | C7: Belo Horizonte | D7: 138 | E7: sim | F7: 17.5 | G7: 20 | H7: 25 | I7: 14.5 | J7: 25 | K7: 30 | L7: 42 | M7: 52 | N7: 66 | O7: =IF(OR(F7="",I7="",L7=""),"",F7+I7+L7) | P7: =IF(OR(G7="",J7="",M7=""),"",G7+J7+M7) | Q7: =IF(OR(H7="",K7="",N7=""),"",H7+K7+N7) | R7: 54 | S7: 40 | T7: 13 | U7: 12 | V7: 28 | W7: sem data
A8: ChIJ-97tiEeNpJIRb_eV7a-sxBs | B8: Ludoteca Sidequest | C8: Belém | D8: 58 | E8: sim | F8: 24.25 | G8: 25.5 | H8: 26.75 | I8: 10 | J8: 13 | K8: 14.5 | L8: 20 | M8: 35 | N8: 40 | O8: =IF(OR(F8="",I8="",L8=""),"",F8+I8+L8) | P8: =IF(OR(G8="",J8="",M8=""),"",G8+J8+M8) | Q8: =IF(OR(H8="",K8="",N8=""),"",H8+K8+N8) | R8: 40 | S8: 30.5 | T8: 13 | U8: 7 | V8: 13 | W8: sem data
A9: ChIJyXjE650xWpMRJL-J6QbGkt4 | B9: FORTALÚDICA - BURGERS & JOGOS | C9: Brasília | D9: 51 | E9: não encontrado | I9: 7 | J9: 8.5 | K9: 12 | L9: 25 | M9: 30 | N9: 33 | O9: =IF(OR(F9="",I9="",L9=""),"",F9+I9+L9) | P9: =IF(OR(G9="",J9="",M9=""),"",G9+J9+M9) | Q9: =IF(OR(H9="",K9="",N9=""),"",H9+K9+N9) | R9: 32 | S9: 15 | T9: 8 | U9: 7 | W9: 2025-12
A10: ChIJdUv4La46WpMRnBvNknmOqWo | B10: Inside Games | C10: Brasília | D10: 24 | E10: não encontrado | I10: 5 | J10: 6 | K10: 9.5 | L10: 6 | M10: 6 | N10: 6 | O10: =IF(OR(F10="",I10="",L10=""),"",F10+I10+L10) | P10: =IF(OR(G10="",J10="",M10=""),"",G10+J10+M10) | Q10: =IF(OR(H10="",K10="",N10=""),"",H10+K10+N10) | T10: 8 | U10: 5 | W10: 2026-09
A11: ChIJzdFNP3AyWpMRH2P6HEuhE-I | B11: Loja de Jogos - Asgard | C11: Brasília | D11: 39 | E11: sim | F11: 13.75 | G11: 17.5 | H11: 21.25 | I11: 11.25 | J11: 17 | K11: 21.25 | L11: 29.5 | M11: 33 | N11: 39 | O11: =IF(OR(F11="",I11="",L11=""),"",F11+I11+L11) | P11: =IF(OR(G11="",J11="",M11=""),"",G11+J11+M11) | Q11: =IF(OR(H11="",K11="",N11=""),"",H11+K11+N11) | R11: 45 | S11: 30.5 | T11: 12 | U11: 6 | V11: 22 | W11: sem data
A12: ChIJ15nLgwAwWpMRY1whwD29ZSo | B12: Ludoteca BGC | C12: Brasília | D12: 60 | E12: sim | F12: 30 | G12: 30 | H12: 30 | I12: 5.25 | J12: 9 | K12: 13.75 | L12: 29.25 | M12: 31 | N12: 33 | O12: =IF(OR(F12="",I12="",L12=""),"",F12+I12+L12) | P12: =IF(OR(G12="",J12="",M12=""),"",G12+J12+M12) | Q12: =IF(OR(H12="",K12="",N12=""),"",H12+K12+N12) | T12: 8.5 | U12: 6 | V12: 14 | W12: 2019-03, 2025-03, 2026-08
A13: ChIJN8BZeb85WpMRgVKT05caxB4 | B13: Utopia Games & Food | C13: Brasília | D13: 32 | E13: não encontrado | I13: 5 | J13: 7 | K13: 9.5 | L13: 50 | M13: 50 | N13: 75 | O13: =IF(OR(F13="",I13="",L13=""),"",F13+I13+L13) | P13: =IF(OR(G13="",J13="",M13=""),"",G13+J13+M13) | Q13: =IF(OR(H13="",K13="",N13=""),"",H13+K13+N13) | S13: 25.5 | T13: 11 | U13: 6 | W13: sem data
A14: ChIJ3ekLtDjl3JQRHwtNgmINgLo | B14: Alçapão Jogos | C14: Curitiba | D14: 26 | E14: não encontrado | I14: 10 | J14: 12 | K14: 14 | L14: 11.75 | M14: 12 | N14: 14.5 | O14: =IF(OR(F14="",I14="",L14=""),"",F14+I14+L14) | P14: =IF(OR(G14="",J14="",M14=""),"",G14+J14+M14) | Q14: =IF(OR(H14="",K14="",N14=""),"",H14+K14+N14) | U14: 9 | W14: sem data
A15: ChIJY_lqHVLl3JQRvDHacOMDKuc | B15: BoardZ Game Pub | C15: Curitiba | D15: 91 | E15: não encontrado | I15: 15 | J15: 16 | K15: 25 | L15: 26.75 | M15: 28 | N15: 32 | O15: =IF(OR(F15="",I15="",L15=""),"",F15+I15+L15) | P15: =IF(OR(G15="",J15="",M15=""),"",G15+J15+M15) | Q15: =IF(OR(H15="",K15="",N15=""),"",H15+K15+N15) | R15: 28 | S15: 35 | T15: 15 | U15: 8 | V15: 24 | W15: sem data
A16: ChIJOczn8z7l3JQRNBEL_ZJ3iQo | B16: Joyjoy Café | C16: Curitiba | D16: 2 | E16: sim | F16: 11.25 | G16: 12.5 | H16: 13.75 | O16: =IF(OR(F16="",I16="",L16=""),"",F16+I16+L16) | P16: =IF(OR(G16="",J16="",M16=""),"",G16+J16+M16) | Q16: =IF(OR(H16="",K16="",N16=""),"",H16+K16+N16) | W16: 2024-08-01
A17: ChIJawIVeV0JM0oR5BtnD_poQeA | B17: CCG Floripa | C17: Florianópolis | D17: 7 | E17: não encontrado | L17: 36 | M17: 36 | N17: 37 | O17: =IF(OR(F17="",I17="",L17=""),"",F17+I17+L17) | P17: =IF(OR(G17="",J17="",M17=""),"",G17+J17+M17) | Q17: =IF(OR(H17="",K17="",N17=""),"",H17+K17+N17) | R17: 36 | S17: 44.5 | W17: 2023-07
A18: ChIJc3F7ka83J5URQZ1XTl-_iak | B18: Chef on Play | C18: Florianópolis | D18: 72 | E18: não encontrado | I18: 6.5 | J18: 6.8 | K18: 8.7 | L18: 23.9 | M18: 25.9 | N18: 34.9 | O18: =IF(OR(F18="",I18="",L18=""),"",F18+I18+L18) | P18: =IF(OR(G18="",J18="",M18=""),"",G18+J18+M18) | Q18: =IF(OR(H18="",K18="",N18=""),"",H18+K18+N18) | R18: 25.9 | U18: 6.5 | W18: 2022-12, 2024-01, 2025-04
A19: ChIJJz8-gcY3J5URYdZrEXdHaAk | B19: Cineplay- Restaurante e Jogos | C19: Florianópolis | D19: 112 | E19: não encontrado | I19: 9 | J19: 17.9 | K19: 20.9 | L19: 26.55 | M19: 31.9 | N19: 50.52 | O19: =IF(OR(F19="",I19="",L19=""),"",F19+I19+L19) | P19: =IF(OR(G19="",J19="",M19=""),"",G19+J19+M19) | Q19: =IF(OR(H19="",K19="",N19=""),"",H19+K19+N19) | R19: 29.9 | S19: 29.2 | T19: 17 | U19: 6.75 | V19: 21.4 | W19: 2022-10, 2023-05, 2023-09, 2024-06
A20: ChIJ0yXbI35IxwcR0_jLi-uINUU | B20: Balboa's Hobby Games | C20: Fortaleza | D20: 36 | E20: não encontrado | I20: 7 | J20: 8 | K20: 15 | L20: 28 | M20: 30 | N20: 30 | O20: =IF(OR(F20="",I20="",L20=""),"",F20+I20+L20) | P20: =IF(OR(G20="",J20="",M20=""),"",G20+J20+M20) | Q20: =IF(OR(H20="",K20="",N20=""),"",H20+K20+N20) | R20: 29.5 | S20: 26.5 | T20: 15 | U20: 7.5 | V20: 15 | W20: 2026-01
A21: ChIJHSDPTgF5GZURKmSqKITyoGM | B21: Arcadea Gaming Pub | C21: Porto Alegre | D21: 94 | E21: não encontrado | I21: 20 | J21: 25 | K21: 40 | L21: 35 | M21: 40 | N21: 45 | O21: =IF(OR(F21="",I21="",L21=""),"",F21+I21+L21) | P21: =IF(OR(G21="",J21="",M21=""),"",G21+J21+M21) | Q21: =IF(OR(H21="",K21="",N21=""),"",H21+K21+N21) | R21: 45 | S21: 28 | T21: 21 | U21: 8 | V21: 29 | W21: 2025-03
A22: ChIJ41pgHNFDGZURC7yTegyn7nU | B22: Toca do Rato - Pizzaria e Jogos de Tabuleiro | C22: Porto Alegre | D22: 25 | E22: não encontrado | I22: 7.5 | J22: 7.5 | K22: 10 | L22: 57.17 | M22: 64.45 | N22: 71.5 | O22: =IF(OR(F22="",I22="",L22=""),"",F22+I22+L22) | P22: =IF(OR(G22="",J22="",M22=""),"",G22+J22+M22) | Q22: =IF(OR(H22="",K22="",N22=""),"",H22+K22+N22) | U22: 7.5 | W22: sem data
A23: ChIJRUjwU66WoGgRzc9yJU7jkwM | B23: Nala Land - Bar de Jogos de Tabuleiro em Recife | C23: Recife | D23: 25 | E23: não encontrado | I23: 11.5 | J23: 12 | K23: 12.5 | L23: 18 | M23: 22 | N23: 25 | O23: =IF(OR(F23="",I23="",L23=""),"",F23+I23+L23) | P23: =IF(OR(G23="",J23="",M23=""),"",G23+J23+M23) | Q23: =IF(OR(H23="",K23="",N23=""),"",H23+K23+N23) | R23: 34 | S23: 19 | T23: 12 | W23: sem data
A24: ChIJu1yUroF_mQAR7qxqAfxKSw4 | B24: Game Of Boards | C24: Rio de Janeiro | D24: 2 | E24: sim | F24: 17.5 | G24: 20 | H24: 22.5 | O24: =IF(OR(F24="",I24="",L24=""),"",F24+I24+L24) | P24: =IF(OR(G24="",J24="",M24=""),"",G24+J24+M24) | Q24: =IF(OR(H24="",K24="",N24=""),"",H24+K24+N24) | W24: 2026-10-16
A25: ChIJ90Gs_9rVmwAReA7MnIyPLTE | B25: Luderia Carioca | C25: Rio de Janeiro | D25: 36 | E25: não encontrado | I25: 9 | J25: 12 | K25: 17 | L25: 26 | M25: 32 | N25: 37.5 | O25: =IF(OR(F25="",I25="",L25=""),"",F25+I25+L25) | P25: =IF(OR(G25="",J25="",M25=""),"",G25+J25+M25) | Q25: =IF(OR(H25="",K25="",N25=""),"",H25+K25+N25) | R25: 38 | S25: 24 | T25: 16.5 | U25: 9 | W25: sem data
A26: ChIJOcVssmeDmQARZZrnWu2mnwA | B26: TabuClub | C26: Rio de Janeiro | D26: 75 | E26: não encontrado | I26: 18 | J26: 25 | K26: 29.75 | L26: 23 | M26: 36 | N26: 46 | O26: =IF(OR(F26="",I26="",L26=""),"",F26+I26+L26) | P26: =IF(OR(G26="",J26="",M26=""),"",G26+J26+M26) | Q26: =IF(OR(H26="",K26="",N26=""),"",H26+K26+N26) | R26: 49 | S26: 22 | T26: 23 | U26: 9 | V26: 32 | W26: sem data
A27: ChIJoTlvBfMbFgcRHvuCKHBQrXQ | B27: São Jogue - Bela Vista | C27: Salvador | D27: 56 | E27: não encontrado | I27: 12 | J27: 16 | K27: 23 | L27: 24.25 | M27: 32.5 | N27: 37.5 | O27: =IF(OR(F27="",I27="",L27=""),"",F27+I27+L27) | P27: =IF(OR(G27="",J27="",M27=""),"",G27+J27+M27) | Q27: =IF(OR(H27="",K27="",N27=""),"",H27+K27+N27) | R27: 45 | S27: 35 | T27: 12 | U27: 8.9 | V27: 28 | W27: 2026-10
A28: ChIJYTHwWgBbzpQRFenbJdM5cxU | B28: Arena BG | Jogos de Tabuleiro | Hamburgueria | C28: São Paulo | D28: 65 | E28: sim | F28: 6.25 | G28: 12.5 | H28: 18.75 | I28: 8 | J28: 11 | K28: 20 | L28: 35.25 | M28: 39.5 | N28: 45 | O28: =IF(OR(F28="",I28="",L28=""),"",F28+I28+L28) | P28: =IF(OR(G28="",J28="",M28=""),"",G28+J28+M28) | Q28: =IF(OR(H28="",K28="",N28=""),"",H28+K28+N28) | R28: 42 | S28: 28.5 | T28: 11 | U28: 8 | V28: 25 | W28: sem data
A29: ChIJKeHwNv5ZzpQRlmzx9rCTWdM | B29: Bodogami Restaurante e Cafeteria | C29: São Paulo | D29: 89 | E29: não encontrado | I29: 15 | J29: 17 | K29: 29 | L29: 25 | M29: 43 | N29: 48.5 | O29: =IF(OR(F29="",I29="",L29=""),"",F29+I29+L29) | P29: =IF(OR(G29="",J29="",M29=""),"",G29+J29+M29) | Q29: =IF(OR(H29="",K29="",N29=""),"",H29+K29+N29) | R29: 49.5 | S29: 39 | T29: 15 | U29: 8 | V29: 36.5 | W29: 2025-03-19
A30: ChIJrT_EWwBZzpQRGAZzptZbtsY | B30: Cartola Luderia Bar | C30: São Paulo | D30: 50 | E30: não encontrado | I30: 29 | J30: 36 | K30: 38 | L30: 29.75 | M30: 39 | N30: 40 | O30: =IF(OR(F30="",I30="",L30=""),"",F30+I30+L30) | P30: =IF(OR(G30="",J30="",M30=""),"",G30+J30+M30) | Q30: =IF(OR(H30="",K30="",N30=""),"",H30+K30+N30) | S30: 68 | V30: 36 | W30: sem data
A31: ChIJbZRHQPRfzpQRz97-ZOg0yXA | B31: Castelos Bar & Boardgames | C31: São Paulo | D31: 66 | E31: não encontrado | I31: 15 | J31: 26.9 | K31: 37.9 | L31: 39.15 | M31: 43.4 | N31: 45.65 | O31: =IF(OR(F31="",I31="",L31=""),"",F31+I31+L31) | P31: =IF(OR(G31="",J31="",M31=""),"",G31+J31+M31) | Q31: =IF(OR(H31="",K31="",N31=""),"",H31+K31+N31) | R31: 43.9 | S31: 39.9 | T31: 15 | U31: 9 | V31: 37.4 | W31: sem data
A32: ChIJF9j3OCRbzpQRkk74_QtOk_0 | B32: Coletivo Geek | C32: São Paulo | D32: 71 | E32: não encontrado | I32: 20.25 | J32: 28 | K32: 30 | L32: 27.25 | M32: 32 | N32: 39 | O32: =IF(OR(F32="",I32="",L32=""),"",F32+I32+L32) | P32: =IF(OR(G32="",J32="",M32=""),"",G32+J32+M32) | Q32: =IF(OR(H32="",K32="",N32=""),"",H32+K32+N32) | R32: 28 | S32: 28 | T32: 22 | U32: 8 | V32: 30 | W32: 2026-05
A33: ChIJ7_DDAlH1zpQRJVJ0UHnItH8 | B33: Covil Game Bar | C33: São Paulo | D33: 71 | E33: não encontrado | I33: 14 | J33: 18 | K33: 22 | L33: 29 | M33: 34 | N33: 38 | O33: =IF(OR(F33="",I33="",L33=""),"",F33+I33+L33) | P33: =IF(OR(G33="",J33="",M33=""),"",G33+J33+M33) | Q33: =IF(OR(H33="",K33="",N33=""),"",H33+K33+N33) | R33: 29 | S33: 50 | T33: 17 | U33: 8 | V33: 21.5 | W33: 2025-07
A34: ChIJiZJ_DnIDz5QRaVafFCXGkUE | B34: Dungeon Games Store | C34: São Paulo | D34: 42 | E34: não encontrado | I34: 10 | J34: 14 | K34: 20 | L34: 25.75 | M34: 30 | N34: 32.5 | O34: =IF(OR(F34="",I34="",L34=""),"",F34+I34+L34) | P34: =IF(OR(G34="",J34="",M34=""),"",G34+J34+M34) | Q34: =IF(OR(H34="",K34="",N34=""),"",H34+K34+N34) | R34: 31 | S34: 30 | T34: 12 | U34: 8 | V34: 28 | W34: sem data
A35: ChIJZz29dnVXzpQRvRh7_YKyUN4 | B35: Encounter | Jogos de Tabuleiro | Board Games | C35: São Paulo | D35: 22 | E35: não encontrado | I35: 27.9 | J35: 27.9 | K35: 27.9 | L35: 34.9 | M35: 39.9 | N35: 48.9 | O35: =IF(OR(F35="",I35="",L35=""),"",F35+I35+L35) | P35: =IF(OR(G35="",J35="",M35=""),"",G35+J35+M35) | Q35: =IF(OR(H35="",K35="",N35=""),"",H35+K35+N35) | R35: 38 | S35: 24.9 | W35: 2025-06
A36: ChIJ_aN4OAxXzpQR0UH63sAeVCA | B36: Fan Hour Games and Burgers | C36: São Paulo | D36: 27 | E36: sim | F36: 20 | G36: 20 | H36: 20 | I36: 26.15 | J36: 32.4 | K36: 36.9 | L36: 32.2 | M36: 37.3 | N36: 50.9 | O36: =IF(OR(F36="",I36="",L36=""),"",F36+I36+L36) | P36: =IF(OR(G36="",J36="",M36=""),"",G36+J36+M36) | Q36: =IF(OR(H36="",K36="",N36=""),"",H36+K36+N36) | R36: 50.3 | S36: 26.7 | W36: 2026-10-05
A37: ChIJa3UsDhRczpQRPPSuDl6acO8 | B37: Flow Games - Burgers, Cards & Comunidade | C37: São Paulo | D37: 16 | E37: não encontrado | I37: 6 | J37: 6 | K37: 7 | L37: 11 | M37: 14 | N37: 34.9 | O37: =IF(OR(F37="",I37="",L37=""),"",F37+I37+L37) | P37: =IF(OR(G37="",J37="",M37=""),"",G37+J37+M37) | Q37: =IF(OR(H37="",K37="",N37=""),"",H37+K37+N37) | R37: 12 | S37: 10 | T37: 6.5 | U37: 6 | W37: 2022-09, 2025-08
A38: ChIJn7uU0RNbzpQRI4GI9KHOo_s | B38: Jogasampa | C38: São Paulo | D38: 7 | E38: não encontrado | I38: 6 | J38: 6 | K38: 6 | O38: =IF(OR(F38="",I38="",L38=""),"",F38+I38+L38) | P38: =IF(OR(G38="",J38="",M38=""),"",G38+J38+M38) | Q38: =IF(OR(H38="",K38="",N38=""),"",H38+K38+N38) | U38: 6 | W38: 2023-10
