Workbook

Sheet geral
A1: grupo | B1: variável | C1: descrição | D1: unidade | E1: n (casas com dado) | F1: sem dado | G1: média | H1: mediana | I1: desvio padrão | J1: mínimo | K1: 1º quartil (P25) | L1: 3º quartil (P75) | M1: máximo | N1: amplitude | O1: coef. de variação
A2: Google Maps | B2: avaliacao_media | C2: Nota média no Google | D2: 1 a 5 | E2: =COUNT(dados!$E$2:$E$55) | F2: =ROWS(dados!$E$2:$E$55)-E2 | G2: =IFERROR(AVERAGE(dados!$E$2:$E$55),"") | H2: =IFERROR(MEDIAN(dados!$E$2:$E$55),"") | I2: =IFERROR(STDEV(dados!$E$2:$E$55),"") | J2: =IFERROR(MIN(dados!$E$2:$E$55),"") | K2: =IFERROR(PERCENTILE(dados!$E$2:$E$55,0.25),"") | L2: =IFERROR(PERCENTILE(dados!$E$2:$E$55,0.75),"") | M2: =IFERROR(MAX(dados!$E$2:$E$55),"") | N2: =IFERROR(M2-J2,"") | O2: =IFERROR(I2/G2,"")
A3: Google Maps | B3: volume_avaliacoes | C3: Nº de avaliações no Google | D3: avaliações | E3: =COUNT(dados!$F$2:$F$55) | F3: =ROWS(dados!$F$2:$F$55)-E3 | G3: =IFERROR(AVERAGE(dados!$F$2:$F$55),"") | H3: =IFERROR(MEDIAN(dados!$F$2:$F$55),"") | I3: =IFERROR(STDEV(dados!$F$2:$F$55),"") | J3: =IFERROR(MIN(dados!$F$2:$F$55),"") | K3: =IFERROR(PERCENTILE(dados!$F$2:$F$55,0.25),"") | L3: =IFERROR(PERCENTILE(dados!$F$2:$F$55,0.75),"") | M3: =IFERROR(MAX(dados!$F$2:$F$55),"") | N3: =IFERROR(M3-J3,"") | O3: =IFERROR(I3/G3,"")
A4: Horários | B4: dias_abertos | C4: Dias abertos por semana | D4: dias | E4: =COUNT(dados!$G$2:$G$55) | F4: =ROWS(dados!$G$2:$G$55)-E4 | G4: =IFERROR(AVERAGE(dados!$G$2:$G$55),"") | H4: =IFERROR(MEDIAN(dados!$G$2:$G$55),"") | I4: =IFERROR(STDEV(dados!$G$2:$G$55),"") | J4: =IFERROR(MIN(dados!$G$2:$G$55),"") | K4: =IFERROR(PERCENTILE(dados!$G$2:$G$55,0.25),"") | L4: =IFERROR(PERCENTILE(dados!$G$2:$G$55,0.75),"") | M4: =IFERROR(MAX(dados!$G$2:$G$55),"") | N4: =IFERROR(M4-J4,"") | O4: =IFERROR(I4/G4,"")
A5: Horários | B5: horas_semana | C5: Horas abertas por semana | D5: horas | E5: =COUNT(dados!$H$2:$H$55) | F5: =ROWS(dados!$H$2:$H$55)-E5 | G5: =IFERROR(AVERAGE(dados!$H$2:$H$55),"") | H5: =IFERROR(MEDIAN(dados!$H$2:$H$55),"") | I5: =IFERROR(STDEV(dados!$H$2:$H$55),"") | J5: =IFERROR(MIN(dados!$H$2:$H$55),"") | K5: =IFERROR(PERCENTILE(dados!$H$2:$H$55,0.25),"") | L5: =IFERROR(PERCENTILE(dados!$H$2:$H$55,0.75),"") | M5: =IFERROR(MAX(dados!$H$2:$H$55),"") | N5: =IFERROR(M5-J5,"") | O5: =IFERROR(I5/G5,"")
A6: Horários | B6: abre_cedo_h | C6: Abertura mais cedo da semana | D6: hora do dia | E6: =COUNT(dados!$I$2:$I$55) | F6: =ROWS(dados!$I$2:$I$55)-E6 | G6: =IFERROR(AVERAGE(dados!$I$2:$I$55),"") | H6: =IFERROR(MEDIAN(dados!$I$2:$I$55),"") | I6: =IFERROR(STDEV(dados!$I$2:$I$55),"") | J6: =IFERROR(MIN(dados!$I$2:$I$55),"") | K6: =IFERROR(PERCENTILE(dados!$I$2:$I$55,0.25),"") | L6: =IFERROR(PERCENTILE(dados!$I$2:$I$55,0.75),"") | M6: =IFERROR(MAX(dados!$I$2:$I$55),"") | N6: =IFERROR(M6-J6,"") | O6: =IFERROR(I6/G6,"")
A7: Horários | B7: fecha_tarde_h | C7: Fechamento mais tarde da semana (25 = 1h da manhã) | D7: hora do dia | E7: =COUNT(dados!$J$2:$J$55) | F7: =ROWS(dados!$J$2:$J$55)-E7 | G7: =IFERROR(AVERAGE(dados!$J$2:$J$55),"") | H7: =IFERROR(MEDIAN(dados!$J$2:$J$55),"") | I7: =IFERROR(STDEV(dados!$J$2:$J$55),"") | J7: =IFERROR(MIN(dados!$J$2:$J$55),"") | K7: =IFERROR(PERCENTILE(dados!$J$2:$J$55,0.25),"") | L7: =IFERROR(PERCENTILE(dados!$J$2:$J$55,0.75),"") | M7: =IFERROR(MAX(dados!$J$2:$J$55),"") | N7: =IFERROR(M7-J7,"") | O7: =IFERROR(I7/G7,"")
A8: Entorno | B8: metro_500m | C8: Estações de metrô até 500 m | D8: estações | E8: =COUNT(dados!$K$2:$K$55) | F8: =ROWS(dados!$K$2:$K$55)-E8 | G8: =IFERROR(AVERAGE(dados!$K$2:$K$55),"") | H8: =IFERROR(MEDIAN(dados!$K$2:$K$55),"") | I8: =IFERROR(STDEV(dados!$K$2:$K$55),"") | J8: =IFERROR(MIN(dados!$K$2:$K$55),"") | K8: =IFERROR(PERCENTILE(dados!$K$2:$K$55,0.25),"") | L8: =IFERROR(PERCENTILE(dados!$K$2:$K$55,0.75),"") | M8: =IFERROR(MAX(dados!$K$2:$K$55),"") | N8: =IFERROR(M8-J8,"") | O8: =IFERROR(I8/G8,"")
A9: Entorno | B9: metro_1000m | C9: Estações de metrô até 1000 m | D9: estações | E9: =COUNT(dados!$L$2:$L$55) | F9: =ROWS(dados!$L$2:$L$55)-E9 | G9: =IFERROR(AVERAGE(dados!$L$2:$L$55),"") | H9: =IFERROR(MEDIAN(dados!$L$2:$L$55),"") | I9: =IFERROR(STDEV(dados!$L$2:$L$55),"") | J9: =IFERROR(MIN(dados!$L$2:$L$55),"") | K9: =IFERROR(PERCENTILE(dados!$L$2:$L$55,0.25),"") | L9: =IFERROR(PERCENTILE(dados!$L$2:$L$55,0.75),"") | M9: =IFERROR(MAX(dados!$L$2:$L$55),"") | N9: =IFERROR(M9-J9,"") | O9: =IFERROR(I9/G9,"")
A10: Entorno | B10: dist_metro_m | C10: Distância à estação de metrô mais próxima | D10: metros (linha reta) | E10: =COUNT(dados!$M$2:$M$55) | F10: =ROWS(dados!$M$2:$M$55)-E10 | G10: =IFERROR(AVERAGE(dados!$M$2:$M$55),"") | H10: =IFERROR(MEDIAN(dados!$M$2:$M$55),"") | I10: =IFERROR(STDEV(dados!$M$2:$M$55),"") | J10: =IFERROR(MIN(dados!$M$2:$M$55),"") | K10: =IFERROR(PERCENTILE(dados!$M$2:$M$55,0.25),"") | L10: =IFERROR(PERCENTILE(dados!$M$2:$M$55,0.75),"") | M10: =IFERROR(MAX(dados!$M$2:$M$55),"") | N10: =IFERROR(M10-J10,"") | O10: =IFERROR(I10/G10,"")
A11: Entorno | B11: shopping_porte_500m | C11: Shoppings de porte até 500 m (onde o porte foi buscado) | D11: shoppings | E11: =COUNT(dados!$N$2:$N$55) | F11: =ROWS(dados!$N$2:$N$55)-E11 | G11: =IFERROR(AVERAGE(dados!$N$2:$N$55),"") | H11: =IFERROR(MEDIAN(dados!$N$2:$N$55),"") | I11: =IFERROR(STDEV(dados!$N$2:$N$55),"") | J11: =IFERROR(MIN(dados!$N$2:$N$55),"") | K11: =IFERROR(PERCENTILE(dados!$N$2:$N$55,0.25),"") | L11: =IFERROR(PERCENTILE(dados!$N$2:$N$55,0.75),"") | M11: =IFERROR(MAX(dados!$N$2:$N$55),"") | N11: =IFERROR(M11-J11,"") | O11: =IFERROR(I11/G11,"")
A12: Entorno | B12: shopping_porte_1000m | C12: Shoppings de porte até 1000 m (onde o porte foi buscado) | D12: shoppings | E12: =COUNT(dados!$O$2:$O$55) | F12: =ROWS(dados!$O$2:$O$55)-E12 | G12: =IFERROR(AVERAGE(dados!$O$2:$O$55),"") | H12: =IFERROR(MEDIAN(dados!$O$2:$O$55),"") | I12: =IFERROR(STDEV(dados!$O$2:$O$55),"") | J12: =IFERROR(MIN(dados!$O$2:$O$55),"") | K12: =IFERROR(PERCENTILE(dados!$O$2:$O$55,0.25),"") | L12: =IFERROR(PERCENTILE(dados!$O$2:$O$55,0.75),"") | M12: =IFERROR(MAX(dados!$O$2:$O$55),"") | N12: =IFERROR(M12-J12,"") | O12: =IFERROR(I12/G12,"")
A13: Entorno | B13: dist_shopping_m | C13: Distância ao shopping mais próximo (qualquer porte) | D13: metros (linha reta) | E13: =COUNT(dados!$P$2:$P$55) | F13: =ROWS(dados!$P$2:$P$55)-E13 | G13: =IFERROR(AVERAGE(dados!$P$2:$P$55),"") | H13: =IFERROR(MEDIAN(dados!$P$2:$P$55),"") | I13: =IFERROR(STDEV(dados!$P$2:$P$55),"") | J13: =IFERROR(MIN(dados!$P$2:$P$55),"") | K13: =IFERROR(PERCENTILE(dados!$P$2:$P$55,0.25),"") | L13: =IFERROR(PERCENTILE(dados!$P$2:$P$55,0.75),"") | M13: =IFERROR(MAX(dados!$P$2:$P$55),"") | N13: =IFERROR(M13-J13,"") | O13: =IFERROR(I13/G13,"")
A14: Instagram | B14: seguidores | C14: Seguidores | D14: seguidores | E14: =COUNT(dados!$Q$2:$Q$55) | F14: =ROWS(dados!$Q$2:$Q$55)-E14 | G14: =IFERROR(AVERAGE(dados!$Q$2:$Q$55),"") | H14: =IFERROR(MEDIAN(dados!$Q$2:$Q$55),"") | I14: =IFERROR(STDEV(dados!$Q$2:$Q$55),"") | J14: =IFERROR(MIN(dados!$Q$2:$Q$55),"") | K14: =IFERROR(PERCENTILE(dados!$Q$2:$Q$55,0.25),"") | L14: =IFERROR(PERCENTILE(dados!$Q$2:$Q$55,0.75),"") | M14: =IFERROR(MAX(dados!$Q$2:$Q$55),"") | N14: =IFERROR(M14-J14,"") | O14: =IFERROR(I14/G14,"")
A15: Instagram | B15: n_posts_total | C15: Posts desde a criação do perfil | D15: posts | E15: =COUNT(dados!$R$2:$R$55) | F15: =ROWS(dados!$R$2:$R$55)-E15 | G15: =IFERROR(AVERAGE(dados!$R$2:$R$55),"") | H15: =IFERROR(MEDIAN(dados!$R$2:$R$55),"") | I15: =IFERROR(STDEV(dados!$R$2:$R$55),"") | J15: =IFERROR(MIN(dados!$R$2:$R$55),"") | K15: =IFERROR(PERCENTILE(dados!$R$2:$R$55,0.25),"") | L15: =IFERROR(PERCENTILE(dados!$R$2:$R$55,0.75),"") | M15: =IFERROR(MAX(dados!$R$2:$R$55),"") | N15: =IFERROR(M15-J15,"") | O15: =IFERROR(I15/G15,"")
A16: Instagram | B16: idade_perfil_anos | C16: Idade do perfil (desde o primeiro post até 15/10/2026) | D16: anos | E16: =COUNT(dados!$S$2:$S$55) | F16: =ROWS(dados!$S$2:$S$55)-E16 | G16: =IFERROR(AVERAGE(dados!$S$2:$S$55),"") | H16: =IFERROR(MEDIAN(dados!$S$2:$S$55),"") | I16: =IFERROR(STDEV(dados!$S$2:$S$55),"") | J16: =IFERROR(MIN(dados!$S$2:$S$55),"") | K16: =IFERROR(PERCENTILE(dados!$S$2:$S$55,0.25),"") | L16: =IFERROR(PERCENTILE(dados!$S$2:$S$55,0.75),"") | M16: =IFERROR(MAX(dados!$S$2:$S$55),"") | N16: =IFERROR(M16-J16,"") | O16: =IFERROR(I16/G16,"")
A17: Instagram | B17: n_posts_periodo | C17: Posts de 01/09 a 01/10/2026 | D17: posts | E17: =COUNT(dados!$T$2:$T$55) | F17: =ROWS(dados!$T$2:$T$55)-E17 | G17: =IFERROR(AVERAGE(dados!$T$2:$T$55),"") | H17: =IFERROR(MEDIAN(dados!$T$2:$T$55),"") | I17: =IFERROR(STDEV(dados!$T$2:$T$55),"") | J17: =IFERROR(MIN(dados!$T$2:$T$55),"") | K17: =IFERROR(PERCENTILE(dados!$T$2:$T$55,0.25),"") | L17: =IFERROR(PERCENTILE(dados!$T$2:$T$55,0.75),"") | M17: =IFERROR(MAX(dados!$T$2:$T$55),"") | N17: =IFERROR(M17-J17,"") | O17: =IFERROR(I17/G17,"")
A18: Instagram | B18: curtidas_periodo | C18: Curtidas no período | D18: curtidas | E18: =COUNT(dados!$U$2:$U$55) | F18: =ROWS(dados!$U$2:$U$55)-E18 | G18: =IFERROR(AVERAGE(dados!$U$2:$U$55),"") | H18: =IFERROR(MEDIAN(dados!$U$2:$U$55),"") | I18: =IFERROR(STDEV(dados!$U$2:$U$55),"") | J18: =IFERROR(MIN(dados!$U$2:$U$55),"") | K18: =IFERROR(PERCENTILE(dados!$U$2:$U$55,0.25),"") | L18: =IFERROR(PERCENTILE(dados!$U$2:$U$55,0.75),"") | M18: =IFERROR(MAX(dados!$U$2:$U$55),"") | N18: =IFERROR(M18-J18,"") | O18: =IFERROR(I18/G18,"")
A19: Instagram | B19: comentarios_periodo | C19: Comentários no período | D19: comentários | E19: =COUNT(dados!$V$2:$V$55) | F19: =ROWS(dados!$V$2:$V$55)-E19 | G19: =IFERROR(AVERAGE(dados!$V$2:$V$55),"") | H19: =IFERROR(MEDIAN(dados!$V$2:$V$55),"") | I19: =IFERROR(STDEV(dados!$V$2:$V$55),"") | J19: =IFERROR(MIN(dados!$V$2:$V$55),"") | K19: =IFERROR(PERCENTILE(dados!$V$2:$V$55,0.25),"") | L19: =IFERROR(PERCENTILE(dados!$V$2:$V$55,0.75),"") | M19: =IFERROR(MAX(dados!$V$2:$V$55),"") | N19: =IFERROR(M19-J19,"") | O19: =IFERROR(I19/G19,"")
A20: Instagram | B20: interacoes_por_post | C20: Interações por post no período (curtidas + comentários) | D20: interações | E20: =COUNT(dados!$W$2:$W$55) | F20: =ROWS(dados!$W$2:$W$55)-E20 | G20: =IFERROR(AVERAGE(dados!$W$2:$W$55),"") | H20: =IFERROR(MEDIAN(dados!$W$2:$W$55),"") | I20: =IFERROR(STDEV(dados!$W$2:$W$55),"") | J20: =IFERROR(MIN(dados!$W$2:$W$55),"") | K20: =IFERROR(PERCENTILE(dados!$W$2:$W$55,0.25),"") | L20: =IFERROR(PERCENTILE(dados!$W$2:$W$55,0.75),"") | M20: =IFERROR(MAX(dados!$W$2:$W$55),"") | N20: =IFERROR(M20-J20,"") | O20: =IFERROR(I20/G20,"")
A21: Instagram | B21: engajamento_pct | C21: Taxa de engajamento (interações por post ÷ seguidores) | D21: % | E21: =COUNT(dados!$X$2:$X$55) | F21: =ROWS(dados!$X$2:$X$55)-E21 | G21: =IFERROR(AVERAGE(dados!$X$2:$X$55),"") | H21: =IFERROR(MEDIAN(dados!$X$2:$X$55),"") | I21: =IFERROR(STDEV(dados!$X$2:$X$55),"") | J21: =IFERROR(MIN(dados!$X$2:$X$55),"") | K21: =IFERROR(PERCENTILE(dados!$X$2:$X$55,0.25),"") | L21: =IFERROR(PERCENTILE(dados!$X$2:$X$55,0.75),"") | M21: =IFERROR(MAX(dados!$X$2:$X$55),"") | N21: =IFERROR(M21-J21,"") | O21: =IFERROR(I21/G21,"")
A22: Cardápio | B22: itens_com_preco | C22: Itens com preço no cardápio | D22: itens | E22: =COUNT(dados!$Y$2:$Y$55) | F22: =ROWS(dados!$Y$2:$Y$55)-E22 | G22: =IFERROR(AVERAGE(dados!$Y$2:$Y$55),"") | H22: =IFERROR(MEDIAN(dados!$Y$2:$Y$55),"") | I22: =IFERROR(STDEV(dados!$Y$2:$Y$55),"") | J22: =IFERROR(MIN(dados!$Y$2:$Y$55),"") | K22: =IFERROR(PERCENTILE(dados!$Y$2:$Y$55,0.25),"") | L22: =IFERROR(PERCENTILE(dados!$Y$2:$Y$55,0.75),"") | M22: =IFERROR(MAX(dados!$Y$2:$Y$55),"") | N22: =IFERROR(M22-J22,"") | O22: =IFERROR(I22/G22,"")
A23: Cardápio | B23: couvert_mediana | C23: Couvert ou taxa de jogo (só casas que cobram) | D23: R$ | E23: =COUNT(dados!$Z$2:$Z$55) | F23: =ROWS(dados!$Z$2:$Z$55)-E23 | G23: =IFERROR(AVERAGE(dados!$Z$2:$Z$55),"") | H23: =IFERROR(MEDIAN(dados!$Z$2:$Z$55),"") | I23: =IFERROR(STDEV(dados!$Z$2:$Z$55),"") | J23: =IFERROR(MIN(dados!$Z$2:$Z$55),"") | K23: =IFERROR(PERCENTILE(dados!$Z$2:$Z$55,0.25),"") | L23: =IFERROR(PERCENTILE(dados!$Z$2:$Z$55,0.75),"") | M23: =IFERROR(MAX(dados!$Z$2:$Z$55),"") | N23: =IFERROR(M23-J23,"") | O23: =IFERROR(I23/G23,"")
A24: Cardápio | B24: bebida_mediana | C24: Bebida, mediana do cardápio | D24: R$ | E24: =COUNT(dados!$AA$2:$AA$55) | F24: =ROWS(dados!$AA$2:$AA$55)-E24 | G24: =IFERROR(AVERAGE(dados!$AA$2:$AA$55),"") | H24: =IFERROR(MEDIAN(dados!$AA$2:$AA$55),"") | I24: =IFERROR(STDEV(dados!$AA$2:$AA$55),"") | J24: =IFERROR(MIN(dados!$AA$2:$AA$55),"") | K24: =IFERROR(PERCENTILE(dados!$AA$2:$AA$55,0.25),"") | L24: =IFERROR(PERCENTILE(dados!$AA$2:$AA$55,0.75),"") | M24: =IFERROR(MAX(dados!$AA$2:$AA$55),"") | N24: =IFERROR(M24-J24,"") | O24: =IFERROR(I24/G24,"")
A25: Cardápio | B25: entrada_ou_prato_mediana | C25: Entrada ou prato, mediana do cardápio | D25: R$ | E25: =COUNT(dados!$AB$2:$AB$55) | F25: =ROWS(dados!$AB$2:$AB$55)-E25 | G25: =IFERROR(AVERAGE(dados!$AB$2:$AB$55),"") | H25: =IFERROR(MEDIAN(dados!$AB$2:$AB$55),"") | I25: =IFERROR(STDEV(dados!$AB$2:$AB$55),"") | J25: =IFERROR(MIN(dados!$AB$2:$AB$55),"") | K25: =IFERROR(PERCENTILE(dados!$AB$2:$AB$55,0.25),"") | L25: =IFERROR(PERCENTILE(dados!$AB$2:$AB$55,0.75),"") | M25: =IFERROR(MAX(dados!$AB$2:$AB$55),"") | N25: =IFERROR(M25-J25,"") | O25: =IFERROR(I25/G25,"")
A26: Cardápio | B26: consumo_baixa | C26: Consumo por pessoa (bebida + entrada ou prato), nível baixo (P25) | D26: R$ | E26: =COUNT(dados!$AC$2:$AC$55) | F26: =ROWS(dados!$AC$2:$AC$55)-E26 | G26: =IFERROR(AVERAGE(dados!$AC$2:$AC$55),"") | H26: =IFERROR(MEDIAN(dados!$AC$2:$AC$55),"") | I26: =IFERROR(STDEV(dados!$AC$2:$AC$55),"") | J26: =IFERROR(MIN(dados!$AC$2:$AC$55),"") | K26: =IFERROR(PERCENTILE(dados!$AC$2:$AC$55,0.25),"") | L26: =IFERROR(PERCENTILE(dados!$AC$2:$AC$55,0.75),"") | M26: =IFERROR(MAX(dados!$AC$2:$AC$55),"") | N26: =IFERROR(M26-J26,"") | O26: =IFERROR(I26/G26,"")
A27: Cardápio | B27: consumo_mediana | C27: Consumo por pessoa (bebida + entrada ou prato), nível mediano | D27: R$ | E27: =COUNT(dados!$AD$2:$AD$55) | F27: =ROWS(dados!$AD$2:$AD$55)-E27 | G27: =IFERROR(AVERAGE(dados!$AD$2:$AD$55),"") | H27: =IFERROR(MEDIAN(dados!$AD$2:$AD$55),"") | I27: =IFERROR(STDEV(dados!$AD$2:$AD$55),"") | J27: =IFERROR(MIN(dados!$AD$2:$AD$55),"") | K27: =IFERROR(PERCENTILE(dados!$AD$2:$AD$55,0.25),"") | L27: =IFERROR(PERCENTILE(dados!$AD$2:$AD$55,0.75),"") | M27: =IFERROR(MAX(dados!$AD$2:$AD$55),"") | N27: =IFERROR(M27-J27,"") | O27: =IFERROR(I27/G27,"")
A28: Cardápio | B28: consumo_alta | C28: Consumo por pessoa (bebida + entrada ou prato), nível alto (P75) | D28: R$ | E28: =COUNT(dados!$AE$2:$AE$55) | F28: =ROWS(dados!$AE$2:$AE$55)-E28 | G28: =IFERROR(AVERAGE(dados!$AE$2:$AE$55),"") | H28: =IFERROR(MEDIAN(dados!$AE$2:$AE$55),"") | I28: =IFERROR(STDEV(dados!$AE$2:$AE$55),"") | J28: =IFERROR(MIN(dados!$AE$2:$AE$55),"") | K28: =IFERROR(PERCENTILE(dados!$AE$2:$AE$55,0.25),"") | L28: =IFERROR(PERCENTILE(dados!$AE$2:$AE$55,0.75),"") | M28: =IFERROR(MAX(dados!$AE$2:$AE$55),"") | N28: =IFERROR(M28-J28,"") | O28: =IFERROR(I28/G28,"")
A29: Cardápio | B29: cesta_baixa | C29: Cesta completa (consumo + couvert encontrado), nível baixo (P25) | D29: R$ | E29: =COUNT(dados!$AF$2:$AF$55) | F29: =ROWS(dados!$AF$2:$AF$55)-E29 | G29: =IFERROR(AVERAGE(dados!$AF$2:$AF$55),"") | H29: =IFERROR(MEDIAN(dados!$AF$2:$AF$55),"") | I29: =IFERROR(STDEV(dados!$AF$2:$AF$55),"") | J29: =IFERROR(MIN(dados!$AF$2:$AF$55),"") | K29: =IFERROR(PERCENTILE(dados!$AF$2:$AF$55,0.25),"") | L29: =IFERROR(PERCENTILE(dados!$AF$2:$AF$55,0.75),"") | M29: =IFERROR(MAX(dados!$AF$2:$AF$55),"") | N29: =IFERROR(M29-J29,"") | O29: =IFERROR(I29/G29,"")
A30: Cardápio | B30: cesta_mediana | C30: Cesta completa (consumo + couvert encontrado), nível mediano | D30: R$ | E30: =COUNT(dados!$AG$2:$AG$55) | F30: =ROWS(dados!$AG$2:$AG$55)-E30 | G30: =IFERROR(AVERAGE(dados!$AG$2:$AG$55),"") | H30: =IFERROR(MEDIAN(dados!$AG$2:$AG$55),"") | I30: =IFERROR(STDEV(dados!$AG$2:$AG$55),"") | J30: =IFERROR(MIN(dados!$AG$2:$AG$55),"") | K30: =IFERROR(PERCENTILE(dados!$AG$2:$AG$55,0.25),"") | L30: =IFERROR(PERCENTILE(dados!$AG$2:$AG$55,0.75),"") | M30: =IFERROR(MAX(dados!$AG$2:$AG$55),"") | N30: =IFERROR(M30-J30,"") | O30: =IFERROR(I30/G30,"")
A31: Cardápio | B31: cesta_alta | C31: Cesta completa (consumo + couvert encontrado), nível alto (P75) | D31: R$ | E31: =COUNT(dados!$AH$2:$AH$55) | F31: =ROWS(dados!$AH$2:$AH$55)-E31 | G31: =IFERROR(AVERAGE(dados!$AH$2:$AH$55),"") | H31: =IFERROR(MEDIAN(dados!$AH$2:$AH$55),"") | I31: =IFERROR(STDEV(dados!$AH$2:$AH$55),"") | J31: =IFERROR(MIN(dados!$AH$2:$AH$55),"") | K31: =IFERROR(PERCENTILE(dados!$AH$2:$AH$55,0.25),"") | L31: =IFERROR(PERCENTILE(dados!$AH$2:$AH$55,0.75),"") | M31: =IFERROR(MAX(dados!$AH$2:$AH$55),"") | N31: =IFERROR(M31-J31,"") | O31: =IFERROR(I31/G31,"")
A32: Cardápio | B32: hamburguer_mediana | C32: Hambúrguer, mediana | D32: R$ | E32: =COUNT(dados!$AI$2:$AI$55) | F32: =ROWS(dados!$AI$2:$AI$55)-E32 | G32: =IFERROR(AVERAGE(dados!$AI$2:$AI$55),"") | H32: =IFERROR(MEDIAN(dados!$AI$2:$AI$55),"") | I32: =IFERROR(STDEV(dados!$AI$2:$AI$55),"") | J32: =IFERROR(MIN(dados!$AI$2:$AI$55),"") | K32: =IFERROR(PERCENTILE(dados!$AI$2:$AI$55,0.25),"") | L32: =IFERROR(PERCENTILE(dados!$AI$2:$AI$55,0.75),"") | M32: =IFERROR(MAX(dados!$AI$2:$AI$55),"") | N32: =IFERROR(M32-J32,"") | O32: =IFERROR(I32/G32,"")
A33: Cardápio | B33: batata_mediana | C33: Batata, mediana | D33: R$ | E33: =COUNT(dados!$AJ$2:$AJ$55) | F33: =ROWS(dados!$AJ$2:$AJ$55)-E33 | G33: =IFERROR(AVERAGE(dados!$AJ$2:$AJ$55),"") | H33: =IFERROR(MEDIAN(dados!$AJ$2:$AJ$55),"") | I33: =IFERROR(STDEV(dados!$AJ$2:$AJ$55),"") | J33: =IFERROR(MIN(dados!$AJ$2:$AJ$55),"") | K33: =IFERROR(PERCENTILE(dados!$AJ$2:$AJ$55,0.25),"") | L33: =IFERROR(PERCENTILE(dados!$AJ$2:$AJ$55,0.75),"") | M33: =IFERROR(MAX(dados!$AJ$2:$AJ$55),"") | N33: =IFERROR(M33-J33,"") | O33: =IFERROR(I33/G33,"")
A34: Cardápio | B34: cerveja_mediana | C34: Cerveja, mediana | D34: R$ | E34: =COUNT(dados!$AK$2:$AK$55) | F34: =ROWS(dados!$AK$2:$AK$55)-E34 | G34: =IFERROR(AVERAGE(dados!$AK$2:$AK$55),"") | H34: =IFERROR(MEDIAN(dados!$AK$2:$AK$55),"") | I34: =IFERROR(STDEV(dados!$AK$2:$AK$55),"") | J34: =IFERROR(MIN(dados!$AK$2:$AK$55),"") | K34: =IFERROR(PERCENTILE(dados!$AK$2:$AK$55,0.25),"") | L34: =IFERROR(PERCENTILE(dados!$AK$2:$AK$55,0.75),"") | M34: =IFERROR(MAX(dados!$AK$2:$AK$55),"") | N34: =IFERROR(M34-J34,"") | O34: =IFERROR(I34/G34,"")
A35: Cardápio | B35: refrigerante_mediana | C35: Refrigerante, mediana | D35: R$ | E35: =COUNT(dados!$AL$2:$AL$55) | F35: =ROWS(dados!$AL$2:$AL$55)-E35 | G35: =IFERROR(AVERAGE(dados!$AL$2:$AL$55),"") | H35: =IFERROR(MEDIAN(dados!$AL$2:$AL$55),"") | I35: =IFERROR(STDEV(dados!$AL$2:$AL$55),"") | J35: =IFERROR(MIN(dados!$AL$2:$AL$55),"") | K35: =IFERROR(PERCENTILE(dados!$AL$2:$AL$55,0.25),"") | L35: =IFERROR(PERCENTILE(dados!$AL$2:$AL$55,0.75),"") | M35: =IFERROR(MAX(dados!$AL$2:$AL$55),"") | N35: =IFERROR(M35-J35,"") | O35: =IFERROR(I35/G35,"")
A36: Cardápio | B36: drinks_mediana | C36: Drinks, mediana | D36: R$ | E36: =COUNT(dados!$AM$2:$AM$55) | F36: =ROWS(dados!$AM$2:$AM$55)-E36 | G36: =IFERROR(AVERAGE(dados!$AM$2:$AM$55),"") | H36: =IFERROR(MEDIAN(dados!$AM$2:$AM$55),"") | I36: =IFERROR(STDEV(dados!$AM$2:$AM$55),"") | J36: =IFERROR(MIN(dados!$AM$2:$AM$55),"") | K36: =IFERROR(PERCENTILE(dados!$AM$2:$AM$55,0.25),"") | L36: =IFERROR(PERCENTILE(dados!$AM$2:$AM$55,0.75),"") | M36: =IFERROR(MAX(dados!$AM$2:$AM$55),"") | N36: =IFERROR(M36-J36,"") | O36: =IFERROR(I36/G36,"")
A37: Acervo | B37: titulos_acervo | C37: Títulos no acervo publicado | D37: jogos | E37: =COUNT(dados!$AN$2:$AN$55) | F37: =ROWS(dados!$AN$2:$AN$55)-E37 | G37: =IFERROR(AVERAGE(dados!$AN$2:$AN$55),"") | H37: =IFERROR(MEDIAN(dados!$AN$2:$AN$55),"") | I37: =IFERROR(STDEV(dados!$AN$2:$AN$55),"") | J37: =IFERROR(MIN(dados!$AN$2:$AN$55),"") | K37: =IFERROR(PERCENTILE(dados!$AN$2:$AN$55,0.25),"") | L37: =IFERROR(PERCENTILE(dados!$AN$2:$AN$55,0.75),"") | M37: =IFERROR(MAX(dados!$AN$2:$AN$55),"") | N37: =IFERROR(M37-J37,"") | O37: =IFERROR(I37/G37,"")
A38: B2 | B38: avaliacoes_b2 | C38: Avaliações no recorte do B2 (até '3 meses atrás') | D38: avaliações | E38: =COUNT(dados!$AO$2:$AO$55) | F38: =ROWS(dados!$AO$2:$AO$55)-E38 | G38: =IFERROR(AVERAGE(dados!$AO$2:$AO$55),"") | H38: =IFERROR(MEDIAN(dados!$AO$2:$AO$55),"") | I38: =IFERROR(STDEV(dados!$AO$2:$AO$55),"") | J38: =IFERROR(MIN(dados!$AO$2:$AO$55),"") | K38: =IFERROR(PERCENTILE(dados!$AO$2:$AO$55,0.25),"") | L38: =IFERROR(PERCENTILE(dados!$AO$2:$AO$55,0.75),"") | M38: =IFERROR(MAX(dados!$AO$2:$AO$55),"") | N38: =IFERROR(M38-J38,"") | O38: =IFERROR(I38/G38,"")
A39: B2 | B39: avaliacoes_b2_com_texto | C39: Dessas, com texto | D39: avaliações | E39: =COUNT(dados!$AP$2:$AP$55) | F39: =ROWS(dados!$AP$2:$AP$55)-E39 | G39: =IFERROR(AVERAGE(dados!$AP$2:$AP$55),"") | H39: =IFERROR(MEDIAN(dados!$AP$2:$AP$55),"") | I39: =IFERROR(STDEV(dados!$AP$2:$AP$55),"") | J39: =IFERROR(MIN(dados!$AP$2:$AP$55),"") | K39: =IFERROR(PERCENTILE(dados!$AP$2:$AP$55,0.25),"") | L39: =IFERROR(PERCENTILE(dados!$AP$2:$AP$55,0.75),"") | M39: =IFERROR(MAX(dados!$AP$2:$AP$55),"") | N39: =IFERROR(M39-J39,"") | O39: =IFERROR(I39/G39,"")

Sheet frequencias
A1: tabela | B1: categoria | C1: casas | D1: % do total
A2: casas por região | B2: Norte | C2: =COUNTIF(dados!$D$2:$D$55,B2) | D2: =C2/COUNTA(dados!$A$2:$A$55)
A3: casas por região | B3: Nordeste | C3: =COUNTIF(dados!$D$2:$D$55,B3) | D3: =C3/COUNTA(dados!$A$2:$A$55)
A4: casas por região | B4: Centro-Oeste | C4: =COUNTIF(dados!$D$2:$D$55,B4) | D4: =C4/COUNTA(dados!$A$2:$A$55)
A5: casas por região | B5: Sudeste | C5: =COUNTIF(dados!$D$2:$D$55,B5) | D5: =C5/COUNTA(dados!$A$2:$A$55)
A6: casas por região | B6: Sul | C6: =COUNTIF(dados!$D$2:$D$55,B6) | D6: =C6/COUNTA(dados!$A$2:$A$55)
A7: casas por região | B7: Total | C7: =SUM(C2:C6) | D7: =SUM(D2:D6)
A8: casas por região | B8: Conferência (total − casas; deve ser 0) | C8: =C7-COUNTA(dados!$A$2:$A$55)
A9: casas por metrópole | B9: Belo Horizonte | C9: =COUNTIF(dados!$C$2:$C$55,B9) | D9: =C9/COUNTA(dados!$A$2:$A$55)
A10: casas por metrópole | B10: Belém | C10: =COUNTIF(dados!$C$2:$C$55,B10) | D10: =C10/COUNTA(dados!$A$2:$A$55)
A11: casas por metrópole | B11: Brasília | C11: =COUNTIF(dados!$C$2:$C$55,B11) | D11: =C11/COUNTA(dados!$A$2:$A$55)
A12: casas por metrópole | B12: Curitiba | C12: =COUNTIF(dados!$C$2:$C$55,B12) | D12: =C12/COUNTA(dados!$A$2:$A$55)
A13: casas por metrópole | B13: Florianópolis | C13: =COUNTIF(dados!$C$2:$C$55,B13) | D13: =C13/COUNTA(dados!$A$2:$A$55)
A14: casas por metrópole | B14: Fortaleza | C14: =COUNTIF(dados!$C$2:$C$55,B14) | D14: =C14/COUNTA(dados!$A$2:$A$55)
A15: casas por metrópole | B15: Goiânia | C15: =COUNTIF(dados!$C$2:$C$55,B15) | D15: =C15/COUNTA(dados!$A$2:$A$55)
A16: casas por metrópole | B16: Porto Alegre | C16: =COUNTIF(dados!$C$2:$C$55,B16) | D16: =C16/COUNTA(dados!$A$2:$A$55)
A17: casas por metrópole | B17: Recife | C17: =COUNTIF(dados!$C$2:$C$55,B17) | D17: =C17/COUNTA(dados!$A$2:$A$55)
A18: casas por metrópole | B18: Rio de Janeiro | C18: =COUNTIF(dados!$C$2:$C$55,B18) | D18: =C18/COUNTA(dados!$A$2:$A$55)
A19: casas por metrópole | B19: Salvador | C19: =COUNTIF(dados!$C$2:$C$55,B19) | D19: =C19/COUNTA(dados!$A$2:$A$55)
A20: casas por metrópole | B20: São Paulo | C20: =COUNTIF(dados!$C$2:$C$55,B20) | D20: =C20/COUNTA(dados!$A$2:$A$55)
A21: casas por metrópole | B21: Vitória | C21: =COUNTIF(dados!$C$2:$C$55,B21) | D21: =C21/COUNTA(dados!$A$2:$A$55)
A22: casas por metrópole | B22: Total | C22: =SUM(C9:C21) | D22: =SUM(D9:D21)
A23: casas por metrópole | B23: Conferência (total − casas; deve ser 0) | C23: =C22-COUNTA(dados!$A$2:$A$55)
A25: proporções (não exclusivas: cada linha tem seu próprio total) | B25: característica | C25: casas com a característica | D25: % das casas com dado
A26: proporção | B26: Com estação de metrô até 1000 m | C26: =SUM(dados!$AQ$2:$AQ$55) | D26: =IFERROR(SUM(dados!$AQ$2:$AQ$55)/COUNT(dados!$AQ$2:$AQ$55),"")
A27: proporção | B27: Com cardápio transcrito | C27: =SUM(dados!$AR$2:$AR$55) | D27: =IFERROR(SUM(dados!$AR$2:$AR$55)/COUNT(dados!$AR$2:$AR$55),"")
A28: proporção | B28: Couvert ou taxa de jogo encontrado (entre as com cardápio) | C28: =SUM(dados!$AS$2:$AS$55) | D28: =IFERROR(SUM(dados!$AS$2:$AS$55)/COUNT(dados!$AS$2:$AS$55),"")
A29: proporção | B29: Abre segunda | C29: =SUM(dados!$AT$2:$AT$55) | D29: =IFERROR(SUM(dados!$AT$2:$AT$55)/COUNT(dados!$AT$2:$AT$55),"")
A30: proporção | B30: Abre terça | C30: =SUM(dados!$AU$2:$AU$55) | D30: =IFERROR(SUM(dados!$AU$2:$AU$55)/COUNT(dados!$AU$2:$AU$55),"")
A31: proporção | B31: Abre quarta | C31: =SUM(dados!$AV$2:$AV$55) | D31: =IFERROR(SUM(dados!$AV$2:$AV$55)/COUNT(dados!$AV$2:$AV$55),"")
A32: proporção | B32: Abre quinta | C32: =SUM(dados!$AW$2:$AW$55) | D32: =IFERROR(SUM(dados!$AW$2:$AW$55)/COUNT(dados!$AW$2:$AW$55),"")
A33: proporção | B33: Abre sexta | C33: =SUM(dados!$AX$2:$AX$55) | D33: =IFERROR(SUM(dados!$AX$2:$AX$55)/COUNT(dados!$AX$2:$AX$55),"")
A34: proporção | B34: Abre sábado | C34: =SUM(dados!$AY$2:$AY$55) | D34: =IFERROR(SUM(dados!$AY$2:$AY$55)/COUNT(dados!$AY$2:$AY$55),"")
A35: proporção | B35: Abre domingo | C35: =SUM(dados!$AZ$2:$AZ$55) | D35: =IFERROR(SUM(dados!$AZ$2:$AZ$55)/COUNT(dados!$AZ$2:$AZ$55),"")

Sheet dados
A1: place_id | B1: nome | C1: metropole | D1: regiao | E1: avaliacao_media | F1: volume_avaliacoes | G1: dias_abertos | H1: horas_semana | I1: abre_cedo_h | J1: fecha_tarde_h | K1: metro_500m | L1: metro_1000m | M1: dist_metro_m | N1: shopping_porte_500m | O1: shopping_porte_1000m | P1: dist_shopping_m | Q1: seguidores | R1: n_posts_total | S1: idade_perfil_anos | T1: n_posts_periodo | U1: curtidas_periodo | V1: comentarios_periodo | W1: interacoes_por_post | X1: engajamento_pct | Y1: itens_com_preco | Z1: couvert_mediana | AA1: bebida_mediana | AB1: entrada_ou_prato_mediana | AC1: consumo_baixa | AD1: consumo_mediana | AE1: consumo_alta | AF1: cesta_baixa | AG1: cesta_mediana | AH1: cesta_alta | AI1: hamburguer_mediana | AJ1: batata_mediana | AK1: cerveja_mediana | AL1: refrigerante_mediana | AM1: drinks_mediana | AN1: titulos_acervo | AO1: avaliacoes_b2 | AP1: avaliacoes_b2_com_texto | AQ1: tem_metro_1000m | AR1: tem_cardapio | AS1: cobra_couvert | AT1: abre_segunda | AU1: abre_terca | AV1: abre_quarta | AW1: abre_quinta | AX1: abre_sexta | AY1: abre_sabado | AZ1: abre_domingo
A2: ChIJyXjE650xWpMRJL-J6QbGkt4 | B2: FORTALÚDICA - BURGERS & JOGOS | C2: Brasília | D2: Centro-Oeste | E2: 4.8 | F2: 105 | G2: 7 | H2: 46 | I2: 14 | J2: 24 | K2: 0 | L2: 1 | M2: 768 | P2: 305 | Q2: 2711 | R2: 185 | S2: 1.26 | T2: 9 | U2: 86 | V2: 11 | W2: 10.78 | X2: 0.00398 | Y2: 51 | AA2: 8.5 | AB2: 30 | AC2: 32 | AD2: 38.5 | AE2: 45 | AI2: 32 | AJ2: 15 | AK2: 8 | AL2: 7 | AO2: 23 | AP2: 15 | AQ2: 1 | AR2: 1 | AS2: 0 | AT2: 1 | AU2: 1 | AV2: 1 | AW2: 1 | AX2: 1 | AY2: 1 | AZ2: 1
A3: ChIJ172cu2U7WpMR-GxnGmUHCkc | B3: Gruta BSB | C3: Brasília | D3: Centro-Oeste | E3: 4.9 | F3: 112 | G3: 5 | H3: 30 | I3: 14 | J3: 23 | K3: 0 | L3: 0 | P3: 76 | Q3: 7631 | R3: 897 | S3: 5.63 | T3: 17 | U3: 450 | V3: 9 | W3: 27 | X3: 0.00354 | AO3: 12 | AP3: 8 | AQ3: 0 | AR3: 0 | AT3: 0 | AU3: 1 | AV3: 1 | AW3: 1 | AX3: 1 | AY3: 1 | AZ3: 0
A4: ChIJdUv4La46WpMRnBvNknmOqWo | B4: Inside Games | C4: Brasília | D4: Centro-Oeste | E4: 4.6 | F4: 640 | G4: 6 | H4: 64 | I4: 12 | J4: 24 | K4: 0 | L4: 2 | M4: 702 | Q4: 6058 | R4: 2542 | S4: 9.33 | T4: 39 | U4: 193 | V4: 2 | W4: 5 | X4: 0.00083 | Y4: 24 | AA4: 6 | AB4: 6 | AC4: 11 | AD4: 12 | AE4: 15.5 | AK4: 8 | AL4: 5 | AO4: 12 | AP4: 6 | AQ4: 1 | AR4: 1 | AS4: 0 | AT4: 0 | AU4: 1 | AV4: 1 | AW4: 1 | AX4: 1 | AY4: 1 | AZ4: 1
A5: ChIJzdFNP3AyWpMRH2P6HEuhE-I | B5: Loja de Jogos - Asgard | C5: Brasília | D5: Centro-Oeste | E5: 4.7 | F5: 754 | G5: 7 | H5: 63 | I5: 14 | J5: 23 | K5: 1 | L5: 1 | M5: 430 | P5: 169 | Q5: 7305 | R5: 608 | S5: 9.02 | T5: 1 | U5: 15 | V5: 0 | W5: 15 | X5: 0.00205 | Y5: 39 | Z5: 17.5 | AA5: 17 | AB5: 33 | AC5: 40.75 | AD5: 50 | AE5: 60.25 | AF5: 54.5 | AG5: 67.5 | AH5: 81.5 | AI5: 45 | AJ5: 30.5 | AK5: 12 | AL5: 6 | AM5: 22 | AN5: 150 | AO5: 11 | AP5: 4 | AQ5: 1 | AR5: 1 | AS5: 1 | AT5: 1 | AU5: 1 | AV5: 1 | AW5: 1 | AX5: 1 | AY5: 1 | AZ5: 1
A6: ChIJ15nLgwAwWpMRY1whwD29ZSo | B6: Ludoteca BGC | C6: Brasília | D6: Centro-Oeste | E6: 4.7 | F6: 1379 | G6: 6 | H6: 63 | I6: 12 | J6: 23.5 | K6: 2 | L6: 2 | M6: 465 | P6: 747 | Q6: 15000 | R6: 820 | S6: 10.37 | T6: 13 | U6: 144 | V6: 10 | W6: 11.85 | X6: 0.00079 | Y6: 60 | AA6: 9 | AB6: 31 | AC6: 34.75 | AD6: 40 | AE6: 46.75 | AK6: 8.5 | AL6: 6 | AM6: 14 | AN6: 952 | AO6: 24 | AP6: 13 | AQ6: 1 | AR6: 1 | AS6: 0 | AT6: 0 | AU6: 1 | AV6: 1 | AW6: 1 | AX6: 1 | AY6: 1 | AZ6: 1
A7: ChIJN8BZeb85WpMRgVKT05caxB4 | B7: Utopia Games & Food | C7: Brasília | D7: Centro-Oeste | E7: 4.8 | F7: 159 | G7: 6 | H7: 44 | I7: 14 | J7: 24 | K7: 0 | L7: 0 | P7: 162 | Q7: 2824 | R7: 208 | S7: 2.67 | T7: 27 | U7: 997 | V7: 64 | W7: 39.3 | X7: 0.01392 | Y7: 32 | AA7: 7 | AB7: 50 | AC7: 55 | AD7: 57 | AE7: 84.5 | AJ7: 25.5 | AK7: 11 | AL7: 6 | AO7: 31 | AP7: 22 | AQ7: 0 | AR7: 1 | AS7: 0 | AT7: 0 | AU7: 1 | AV7: 1 | AW7: 1 | AX7: 1 | AY7: 1 | AZ7: 1
A8: ChIJ89uEICDxXpMRdaEvN0XiWK0 | B8: Paladins Game Store | C8: Goiânia | D8: Centro-Oeste | E8: 4.7 | F8: 906 | G8: 7 | H8: 70 | I8: 10 | J8: 22 | K8: 0 | L8: 0 | P8: 5 | Q8: 9690 | R8: 1376 | S8: 11.71 | T8: 1 | U8: 154 | V8: 3 | W8: 157 | X8: 0.0162 | AN8: 214 | AO8: 14 | AP8: 7 | AQ8: 0 | AR8: 0 | AT8: 1 | AU8: 1 | AV8: 1 | AW8: 1 | AX8: 1 | AY8: 1 | AZ8: 1
A9: ChIJ0yXbI35IxwcR0_jLi-uINUU | B9: Balboa's Hobby Games | C9: Fortaleza | D9: Nordeste | E9: 4.8 | F9: 881 | G9: 5 | H9: 27 | I9: 15 | J9: 22 | K9: 0 | L9: 0 | P9: 228 | Q9: 21318 | R9: 1724 | S9: 12.37 | T9: 22 | U9: 2323 | V9: 108 | W9: 110.5 | X9: 0.00518 | Y9: 36 | AA9: 8 | AB9: 30 | AC9: 35 | AD9: 38 | AE9: 45 | AI9: 29.5 | AJ9: 26.5 | AK9: 15 | AL9: 7.5 | AM9: 15 | AN9: 1833 | AO9: 15 | AP9: 9 | AQ9: 0 | AR9: 1 | AS9: 0 | AT9: 0 | AU9: 0 | AV9: 1 | AW9: 1 | AX9: 1 | AY9: 1 | AZ9: 1
A10: ChIJQURqeMZJxwcR95O-XLbS2mk | B10: Dominaria Cards & Games | C10: Fortaleza | D10: Nordeste | E10: 4.7 | F10: 305 | G10: 7 | H10: 77 | I10: 8 | J10: 21 | K10: 1 | L10: 2 | M10: 95 | P10: 96 | AO10: 19 | AP10: 14 | AQ10: 1 | AR10: 0 | AT10: 1 | AU10: 1 | AV10: 1 | AW10: 1 | AX10: 1 | AY10: 1 | AZ10: 1
A11: ChIJRUjwU66WoGgRzc9yJU7jkwM | B11: Nala Land - Bar de Jogos de Tabuleiro em Recife | C11: Recife | D11: Nordeste | E11: 4.9 | F11: 206 | G11: 4 | H11: 28 | I11: 14 | J11: 24 | K11: 0 | L11: 0 | Q11: 27673 | R11: 655 | S11: 5.4 | T11: 17 | U11: 1058 | V11: 114 | W11: 68.94 | X11: 0.00249 | Y11: 28 | Z11: 25 | AA11: 12 | AB11: 22 | AC11: 29.5 | AD11: 34 | AE11: 37.5 | AF11: 52 | AG11: 59 | AH11: 62.5 | AI11: 34 | AJ11: 19 | AK11: 12 | AN11: 312 | AO11: 10 | AP11: 7 | AQ11: 0 | AR11: 1 | AS11: 1 | AT11: 0 | AU11: 0 | AV11: 0 | AW11: 1 | AX11: 1 | AY11: 1 | AZ11: 1
A12: ChIJoTlvBfMbFgcRHvuCKHBQrXQ | B12: São Jogue - Bela Vista | C12: Salvador | D12: Nordeste | E12: 4.8 | F12: 787 | G12: 7 | H12: 68 | I12: 12 | J12: 22 | K12: 1 | L12: 2 | M12: 387 | P12: 118 | Q12: 38492 | R12: 2036 | S12: 8.91 | T12: 26 | U12: 8448 | V12: 251 | W12: 334.58 | X12: 0.00869 | Y12: 56 | AA12: 16 | AB12: 32.5 | AC12: 36.25 | AD12: 48.5 | AE12: 60.5 | AI12: 45 | AJ12: 35 | AK12: 12 | AL12: 8.9 | AM12: 28 | AN12: 370 | AO12: 5 | AP12: 4 | AQ12: 1 | AR12: 1 | AS12: 0 | AT12: 1 | AU12: 1 | AV12: 1 | AW12: 1 | AX12: 1 | AY12: 1 | AZ12: 1
A13: ChIJ-97tiEeNpJIRb_eV7a-sxBs | B13: Ludoteca Sidequest | C13: Belém | D13: Norte | E13: 4.8 | F13: 327 | G13: 5 | H13: 42 | I13: 14 | J13: 24 | K13: 0 | L13: 0 | P13: 52 | Q13: 21601 | R13: 235 | S13: 2.98 | T13: 10 | U13: 3394 | V13: 92 | W13: 348.6 | X13: 0.01614 | Y13: 58 | Z13: 25.5 | AA13: 13 | AB13: 35 | AC13: 30 | AD13: 48 | AE13: 54.5 | AF13: 54.25 | AG13: 73.5 | AH13: 81.25 | AI13: 40 | AJ13: 30.5 | AK13: 13 | AL13: 7 | AM13: 13 | AN13: 468 | AO13: 40 | AP13: 26 | AQ13: 0 | AR13: 1 | AS13: 1 | AT13: 0 | AU13: 0 | AV13: 1 | AW13: 1 | AX13: 1 | AY13: 1 | AZ13: 1
A14: ChIJRcWOaPabpgARDvX2Bad0qb0 | B14: Bardo Mago | C14: Belo Horizonte | D14: Sudeste | E14: 4.8 | F14: 823 | G14: 5 | H14: 37 | I14: 13 | J14: 24 | K14: 1 | L14: 1 | M14: 307 | P14: 723 | R14: 616 | S14: 2.42 | T14: 31 | U14: 8610 | V14: 288 | W14: 287.03 | Y14: 112 | Z14: 20 | AA14: 20 | AB14: 34 | AC14: 40.5 | AD14: 54 | AE14: 71.5 | AF14: 58 | AG14: 74 | AH14: 94 | AI14: 42 | AK14: 12.5 | AL14: 8 | AM14: 26 | AN14: 588 | AQ14: 1 | AR14: 1 | AS14: 1 | AT14: 0 | AU14: 0 | AV14: 1 | AW14: 1 | AX14: 1 | AY14: 1 | AZ14: 1
A15: ChIJpzB8zc2XpgARoJTUu90J6Pw | B15: Comdado Bar e Jogos | C15: Belo Horizonte | D15: Sudeste | E15: 4.4 | F15: 158 | G15: 5 | H15: 45 | I15: 12 | J15: 25 | K15: 0 | L15: 0 | P15: 105 | Q15: 10671 | R15: 190 | S15: 3.98 | T15: 2 | U15: 100 | V15: 4 | W15: 52 | X15: 0.00487 | Y15: 55 | Z15: 17.5 | AA15: 18 | AB15: 50 | AC15: 54.75 | AD15: 68 | AE15: 80 | AF15: 71 | AG15: 85.5 | AH15: 98.75 | AI15: 50 | AK15: 12 | AM15: 25 | AN15: 190 | AO15: 12 | AP15: 6 | AQ15: 0 | AR15: 1 | AS15: 1 | AT15: 0 | AU15: 0 | AV15: 1 | AW15: 1 | AX15: 1 | AY15: 1 | AZ15: 1
A16: ChIJsUAT-dObpgARCT2C5QpnVKU | B16: Garagem do Nerd | C16: Belo Horizonte | D16: Sudeste | E16: 4.9 | F16: 244 | G16: 5 | H16: 34 | I16: 13 | J16: 25 | K16: 0 | L16: 0 | P16: 754 | Q16: 13420 | R16: 3023 | S16: 8.73 | T16: 30 | U16: 529 | V16: 10 | W16: 17.97 | X16: 0.00134 | Y16: 1 | Z16: 10 | AO16: 4 | AP16: 1 | AQ16: 0 | AR16: 1 | AS16: 1 | AT16: 0 | AU16: 1 | AV16: 1 | AW16: 1 | AX16: 1 | AY16: 1 | AZ16: 0
A17: ChIJ-17ZQDG9pgARc-AxpXmaNRU | B17: La Tabuleria | C17: Belo Horizonte | D17: Sudeste | E17: 4.7 | F17: 138 | G17: 5 | H17: 42 | I17: 15 | J17: 25 | K17: 0 | L17: 0 | P17: 137 | S17: 2.64 | T17: 8 | U17: 140 | V17: 1 | W17: 17.62 | Y17: 90 | Z17: 20 | AA17: 20 | AB17: 35 | AC17: 38.5 | AD17: 55 | AE17: 67.5 | AF17: 58.5 | AG17: 75 | AH17: 87.5 | AI17: 42 | AJ17: 37.5 | AK17: 12 | AL17: 8 | AM17: 25 | AN17: 192 | AQ17: 0 | AR17: 1 | AS17: 1 | AT17: 0 | AU17: 0 | AV17: 1 | AW17: 1 | AX17: 1 | AY17: 1 | AZ17: 1
A18: ChIJx5jr3zGXpgARQGx9eX7TDmY | B18: LudoCafé | C18: Belo Horizonte | D18: Sudeste | E18: 4.6 | F18: 585 | G18: 6 | H18: 41 | I18: 13 | J18: 24 | K18: 0 | L18: 0 | P18: 391 | Y18: 13 | Z18: 22.5 | AA18: 34.4 | AB18: 38.9 | AC18: 69.3 | AD18: 73.3 | AE18: 75.8 | AF18: 86.8 | AG18: 95.8 | AH18: 103.3 | AM18: 38.9 | AN18: 362 | AO18: 10 | AP18: 6 | AQ18: 0 | AR18: 1 | AS18: 1 | AT18: 0 | AU18: 1 | AV18: 1 | AW18: 1 | AX18: 1 | AY18: 1 | AZ18: 1
A19: ChIJ6ZLMZw-XpgAR_OR6SwY5xKo | B19: Shelf Bar e Jogos | C19: Belo Horizonte | D19: Sudeste | E19: 4.6 | F19: 1505 | G19: 6 | H19: 56 | I19: 15 | J19: 25 | K19: 0 | L19: 0 | P19: 221 | Q19: 31800 | R19: 630 | S19: 2.15 | T19: 32 | U19: 1557 | V19: 121 | W19: 52.44 | X19: 0.00165 | Y19: 138 | Z19: 20 | AA19: 25 | AB19: 52 | AC19: 56.5 | AD19: 77 | AE19: 96 | AF19: 74 | AG19: 97 | AH19: 121 | AI19: 54 | AJ19: 40 | AK19: 13 | AL19: 12 | AM19: 28 | AN19: 836 | AO19: 272 | AP19: 243 | AQ19: 0 | AR19: 1 | AS19: 1 | AT19: 0 | AU19: 1 | AV19: 1 | AW19: 1 | AX19: 1 | AY19: 1 | AZ19: 1
A20: ChIJu1yUroF_mQAR7qxqAfxKSw4 | B20: Game Of Boards | C20: Rio de Janeiro | D20: Sudeste | E20: 4.7 | F20: 1077 | G20: 5 | H20: 41 | I20: 14 | J20: 24 | K20: 0 | L20: 1 | M20: 555 | P20: 291 | Q20: 18453 | R20: 3266 | S20: 10.55 | T20: 21 | U20: 789 | V20: 76 | W20: 41.19 | X20: 0.00223 | Y20: 2 | Z20: 20 | AO20: 8 | AP20: 6 | AQ20: 1 | AR20: 1 | AS20: 1 | AT20: 0 | AU20: 0 | AV20: 1 | AW20: 1 | AX20: 1 | AY20: 1 | AZ20: 1
A21: ChIJ90Gs_9rVmwAReA7MnIyPLTE | B21: Luderia Carioca | C21: Rio de Janeiro | D21: Sudeste | E21: 4.7 | F21: 212 | G21: 5 | H21: 38 | I21: 14 | J21: 24 | K21: 2 | L21: 3 | M21: 302 | P21: 576 | Q21: 16137 | R21: 84 | S21: 1.59 | T21: 5 | U21: 809 | V21: 20 | W21: 165.8 | X21: 0.01027 | Y21: 37 | Z21: 20 | AA21: 12 | AB21: 32 | AC21: 35 | AD21: 44 | AE21: 54.5 | AF21: 55 | AG21: 64 | AH21: 74.5 | AI21: 38 | AJ21: 24 | AK21: 16.5 | AL21: 9 | AN21: 780 | AO21: 99 | AP21: 69 | AQ21: 1 | AR21: 1 | AS21: 1 | AT21: 0 | AU21: 0 | AV21: 1 | AW21: 1 | AX21: 1 | AY21: 1 | AZ21: 1
A22: ChIJYzHxUhR-mQARpqVtYD9th0c | B22: Magic Store Brazil | C22: Rio de Janeiro | D22: Sudeste | E22: 4.7 | F22: 465 | G22: 6 | H22: 32 | I22: 13 | J22: 21 | K22: 0 | L22: 0 | P22: 312 | Q22: 23364 | R22: 308 | S22: 7.89 | T22: 4 | U22: 132 | V22: 3 | W22: 33.75 | X22: 0.00144 | AO22: 15 | AP22: 7 | AQ22: 0 | AR22: 0 | AT22: 0 | AU22: 1 | AV22: 1 | AW22: 1 | AX22: 1 | AY22: 1 | AZ22: 1
A23: ChIJ1SAzAGF_mQARQgP-yrPBxbQ | B23: RED jogos | C23: Rio de Janeiro | D23: Sudeste | E23: 4.7 | F23: 800 | G23: 6 | H23: 47 | I23: 11 | J23: 20 | K23: 2 | L23: 3 | M23: 161 | P23: 496 | Q23: 21522 | R23: 1164 | S23: 11.02 | T23: 12 | U23: 968 | V23: 103 | W23: 89.25 | X23: 0.00415 | AO23: 10 | AP23: 6 | AQ23: 1 | AR23: 0 | AT23: 1 | AU23: 1 | AV23: 1 | AW23: 1 | AX23: 1 | AY23: 1 | AZ23: 0
A24: ChIJOcVssmeDmQARZZrnWu2mnwA | B24: TabuClub | C24: Rio de Janeiro | D24: Sudeste | E24: 4.7 | F24: 105 | G24: 6 | H24: 43 | I24: 14 | J24: 24 | K24: 0 | L24: 0 | P24: 153 | S24: 3.23 | T24: 8 | U24: 1576 | V24: 85 | W24: 207.62 | Y24: 77 | Z24: 22.5 | AA24: 25 | AB24: 36 | AC24: 41 | AD24: 61 | AE24: 75.75 | AF24: 62.25 | AG24: 83.5 | AH24: 99.5 | AI24: 49 | AJ24: 22 | AK24: 23 | AL24: 9 | AM24: 32 | AN24: 1357 | AQ24: 0 | AR24: 1 | AS24: 1 | AT24: 0 | AU24: 1 | AV24: 1 | AW24: 1 | AX24: 1 | AY24: 1 | AZ24: 1
A25: ChIJYTHwWgBbzpQRFenbJdM5cxU | B25: Arena BG | Jogos de Tabuleiro | Hamburgueria | C25: São Paulo | D25: Sudeste | E25: 4.8 | F25: 145 | G25: 5 | H25: 33 | I25: 14 | J25: 25 | K25: 1 | L25: 1 | M25: 351 | Q25: 6682 | R25: 520 | S25: 2.44 | T25: 32 | U25: 688 | V25: 67 | W25: 23.59 | X25: 0.00353 | Y25: 65 | Z25: 12.5 | AA25: 11 | AB25: 39.5 | AC25: 43.25 | AD25: 50.5 | AE25: 65 | AF25: 49.5 | AG25: 63 | AH25: 83.75 | AI25: 42 | AJ25: 28.5 | AK25: 11 | AL25: 8 | AM25: 25 | AN25: 540 | AO25: 17 | AP25: 13 | AQ25: 1 | AR25: 1 | AS25: 1 | AT25: 0 | AU25: 0 | AV25: 1 | AW25: 1 | AX25: 1 | AY25: 1 | AZ25: 1
A26: ChIJKeHwNv5ZzpQRlmzx9rCTWdM | B26: Bodogami Restaurante e Cafeteria | C26: São Paulo | D26: Sudeste | E26: 4.6 | F26: 3386 | G26: 7 | H26: 77 | I26: 11 | J26: 22.5 | K26: 1 | L26: 2 | M26: 204 | P26: 163 | Q26: 74000 | R26: 2374 | S26: 9.75 | T26: 4 | U26: 444 | V26: 8 | W26: 113 | X26: 0.00153 | Y26: 89 | AA26: 17 | AB26: 43 | AC26: 40 | AD26: 60 | AE26: 77.5 | AI26: 49.5 | AJ26: 39 | AK26: 15 | AL26: 8 | AM26: 36.5 | AN26: 934 | AO26: 712 | AP26: 453 | AQ26: 1 | AR26: 1 | AS26: 0 | AT26: 1 | AU26: 1 | AV26: 1 | AW26: 1 | AX26: 1 | AY26: 1 | AZ26: 1
A27: ChIJ__9TTnxCzpQRwVSzrOijkRY | B27: Bravo Jogos | C27: São Paulo | D27: Sudeste | E27: 4.9 | F27: 1719 | G27: 5 | H27: 55 | I27: 10 | J27: 21 | K27: 0 | L27: 0 | P27: 684 | Q27: 65145 | R27: 1782 | T27: 14 | U27: 7178 | V27: 222 | W27: 528.57 | X27: 0.00811 | AO27: 32 | AP27: 24 | AQ27: 0 | AR27: 0 | AT27: 0 | AU27: 1 | AV27: 1 | AW27: 1 | AX27: 1 | AY27: 1 | AZ27: 0
A28: ChIJrT_EWwBZzpQRGAZzptZbtsY | B28: Cartola Luderia Bar | C28: São Paulo | D28: Sudeste | E28: 4.7 | F28: 242 | G28: 3 | H28: 19.5 | I28: 17 | J28: 23.5 | K28: 0 | L28: 2 | M28: 607 | P28: 907 | Q28: 11500 | R28: 670 | S28: 2.56 | T28: 21 | U28: 1061 | V28: 24 | W28: 51.67 | X28: 0.00449 | Y28: 50 | AA28: 36 | AB28: 39 | AC28: 58.75 | AD28: 75 | AE28: 78 | AJ28: 68 | AM28: 36 | AO28: 51 | AP28: 38 | AQ28: 1 | AR28: 1 | AS28: 0 | AT28: 0 | AU28: 0 | AV28: 0 | AW28: 1 | AX28: 1 | AY28: 1 | AZ28: 0
A29: ChIJbZRHQPRfzpQRz97-ZOg0yXA | B29: Castelos Bar & Boardgames | C29: São Paulo | D29: Sudeste | E29: 4.6 | F29: 617 | G29: 5 | H29: 29 | I29: 14 | J29: 23 | K29: 0 | L29: 1 | M29: 577 | Q29: 41545 | R29: 1358 | S29: 6.91 | T29: 1 | U29: 20 | V29: 0 | W29: 20 | X29: 0.00048 | Y29: 66 | AA29: 26.9 | AB29: 43.4 | AC29: 54.15 | AD29: 70.3 | AE29: 83.55 | AI29: 43.9 | AJ29: 39.9 | AK29: 15 | AL29: 9 | AM29: 37.4 | AN29: 225 | AO29: 80 | AP29: 48 | AQ29: 1 | AR29: 1 | AS29: 0 | AT29: 0 | AU29: 0 | AV29: 1 | AW29: 1 | AX29: 1 | AY29: 1 | AZ29: 1
A30: ChIJF9j3OCRbzpQRkk74_QtOk_0 | B30: Coletivo Geek | C30: São Paulo | D30: Sudeste | E30: 4.7 | F30: 477 | G30: 6 | H30: 47 | I30: 13 | J30: 23 | K30: 0 | L30: 1 | M30: 555 | P30: 494 | Q30: 13059 | R30: 501 | S30: 7.53 | T30: 3 | U30: 159 | V30: 5 | W30: 54.67 | X30: 0.00419 | Y30: 71 | AA30: 28 | AB30: 32 | AC30: 47.5 | AD30: 60 | AE30: 69 | AI30: 28 | AJ30: 28 | AK30: 22 | AL30: 8 | AM30: 30 | AO30: 12 | AP30: 3 | AQ30: 1 | AR30: 1 | AS30: 0 | AT30: 0 | AU30: 1 | AV30: 1 | AW30: 1 | AX30: 1 | AY30: 1 | AZ30: 1
A31: ChIJ7_DDAlH1zpQRJVJ0UHnItH8 | B31: Covil Game Bar | C31: São Paulo | D31: Sudeste | E31: 4.6 | F31: 1714 | G31: 5 | H31: 32 | I31: 18 | J31: 25 | K31: 0 | L31: 0 | P31: 424 | Q31: 206000 | R31: 790 | S31: 9.87 | T31: 13 | U31: 90413 | V31: 949 | W31: 7027.85 | X31: 0.03412 | Y31: 73 | Z31: 17.5 | AA31: 18 | AB31: 34 | AC31: 43 | AD31: 52 | AE31: 60 | AF31: 59.25 | AG31: 69.5 | AH31: 78.75 | AI31: 29 | AJ31: 50 | AK31: 17 | AL31: 8 | AM31: 21.5 | AN31: 239 | AO31: 17 | AP31: 6 | AQ31: 0 | AR31: 1 | AS31: 1 | AT31: 0 | AU31: 0 | AV31: 1 | AW31: 1 | AX31: 1 | AY31: 1 | AZ31: 1
A32: ChIJiZJ_DnIDz5QRaVafFCXGkUE | B32: Dungeon Games Store | C32: São Paulo | D32: Sudeste | E32: 4.9 | F32: 217 | G32: 5 | H32: 33 | I32: 13 | J32: 22 | K32: 0 | L32: 0 | Q32: 2732 | R32: 270 | S32: 4.93 | T32: 5 | U32: 107 | V32: 46 | W32: 30.6 | X32: 0.0112 | Y32: 42 | AA32: 14 | AB32: 30 | AC32: 35.75 | AD32: 44 | AE32: 52.5 | AI32: 31 | AJ32: 30 | AK32: 12 | AL32: 8 | AM32: 28 | AN32: 90 | AO32: 7 | AP32: 4 | AQ32: 0 | AR32: 1 | AS32: 0 | AT32: 0 | AU32: 0 | AV32: 1 | AW32: 1 | AX32: 1 | AY32: 1 | AZ32: 1
A33: ChIJZz29dnVXzpQRvRh7_YKyUN4 | B33: Encounter | Jogos de Tabuleiro | Board Games | C33: São Paulo | D33: Sudeste | E33: 4.8 | F33: 1123 | G33: 6 | H33: 45 | I33: 13 | J33: 25 | K33: 0 | L33: 1 | M33: 687 | P33: 835 | Q33: 22391 | R33: 1163 | S33: 9.71 | T33: 15 | U33: 1020 | V33: 60 | W33: 72 | X33: 0.00322 | Y33: 26 | Z33: 40 | AA33: 27.9 | AB33: 39.9 | AC33: 62.8 | AD33: 67.8 | AE33: 76.8 | AF33: 101.55 | AG33: 107.8 | AH33: 118.05 | AI33: 38 | AJ33: 24.9 | AO33: 81 | AP33: 62 | AQ33: 1 | AR33: 1 | AS33: 1 | AT33: 0 | AU33: 1 | AV33: 1 | AW33: 1 | AX33: 1 | AY33: 1 | AZ33: 1
A34: ChIJ_aN4OAxXzpQR0UH63sAeVCA | B34: Fan Hour Games and Burgers | C34: São Paulo | D34: Sudeste | E34: 4.5 | F34: 2363 | G34: 6 | H34: 36.5 | I34: 13 | J34: 23 | K34: 0 | L34: 2 | M34: 628 | Q34: 110000 | R34: 1403 | S34: 6.89 | T34: 25 | U34: 3092 | V34: 119 | W34: 128.44 | X34: 0.00117 | Y34: 27 | Z34: 20 | AA34: 32.4 | AB34: 37.3 | AC34: 58.35 | AD34: 69.7 | AE34: 87.8 | AF34: 78.35 | AG34: 89.7 | AH34: 107.8 | AI34: 50.3 | AJ34: 26.7 | AO34: 120 | AP34: 79 | AQ34: 1 | AR34: 1 | AS34: 1 | AT34: 0 | AU34: 1 | AV34: 1 | AW34: 1 | AX34: 1 | AY34: 1 | AZ34: 1
A35: ChIJa3UsDhRczpQRPPSuDl6acO8 | B35: Flow Games - Burgers, Cards & Comunidade | C35: São Paulo | D35: Sudeste | E35: 4.6 | F35: 503 | G35: 5 | H35: 37 | I35: 11 | J35: 22 | K35: 1 | L35: 1 | M35: 435 | P35: 818 | Q35: 8944 | R35: 1666 | S35: 10.76 | T35: 17 | U35: 393 | V35: 19 | W35: 24.24 | X35: 0.00271 | Y35: 16 | AA35: 6 | AB35: 14 | AC35: 17 | AD35: 20 | AE35: 41.9 | AI35: 12 | AJ35: 10 | AK35: 6.5 | AL35: 6 | AO35: 29 | AP35: 16 | AQ35: 1 | AR35: 1 | AS35: 0 | AT35: 0 | AU35: 1 | AV35: 1 | AW35: 1 | AX35: 1 | AY35: 1 | AZ35: 0
A36: ChIJn7uU0RNbzpQRI4GI9KHOo_s | B36: Jogasampa | C36: São Paulo | D36: Sudeste | E36: 4.7 | F36: 402 | G36: 6 | H36: 48 | I36: 13 | J36: 21 | K36: 0 | L36: 1 | M36: 587 | P36: 438 | Q36: 5966 | R36: 756 | S36: 9.86 | T36: 8 | U36: 111 | V36: 0 | W36: 13.88 | X36: 0.00233 | Y36: 7 | AA36: 6 | AL36: 6 | AN36: 331 | AO36: 5 | AP36: 3 | AQ36: 1 | AR36: 1 | AS36: 0 | AT36: 0 | AU36: 1 | AV36: 1 | AW36: 1 | AX36: 1 | AY36: 1 | AZ36: 1
A37: ChIJTaG5ALpZzpQRUDErQ-RkfTs | B37: Ludus Luderia | C37: São Paulo | D37: Sudeste | E37: 4.6 | F37: 5137 | G37: 4 | H37: 31 | I37: 13 | J37: 25 | K37: 0 | L37: 3 | M37: 768 | P37: 119 | Q37: 90400 | S37: 4.97 | T37: 12 | U37: 1505 | V37: 92 | W37: 133.08 | X37: 0.00147 | Y37: 161 | Z37: 0 | AA37: 34 | AB37: 48 | AC37: 63 | AD37: 82 | AE37: 92.5 | AF37: 63 | AG37: 82 | AH37: 92.5 | AI37: 42 | AJ37: 48 | AK37: 18.5 | AL37: 9 | AM37: 36 | AN37: 199 | AO37: 51 | AP37: 28 | AQ37: 1 | AR37: 1 | AS37: 1 | AT37: 0 | AU37: 0 | AV37: 0 | AW37: 1 | AX37: 1 | AY37: 1 | AZ37: 1
A38: ChIJE43rt29ZzpQRnvADt6pXfto | B38: OMNIVERSE | C38: São Paulo | D38: Sudeste | E38: 4.8 | F38: 1145 | G38: 5 | H38: 46 | I38: 12 | J38: 24 | K38: 0 | L38: 2 | M38: 820 | Q38: 8510 | R38: 918 | S38: 13.68 | T38: 8 | U38: 510 | V38: 27 | W38: 67.12 | X38: 0.00789 | AN38: 59 | AO38: 31 | AP38: 18 | AQ38: 1 | AR38: 0 | AT38: 0 | AU38: 0 | AV38: 1 | AW38: 1 | AX38: 1 | AY38: 1 | AZ38: 1
A39: ChIJo-6lZMlezpQRmgUpUPfmRIs | B39: Pitta's Board Games | C39: São Paulo | D39: Sudeste | E39: 4.9 | F39: 663 | G39: 6 | H39: 58 | I39: 11 | J39: 22 | K39: 0 | L39: 1 | M39: 566 | Q39: 23415 | R39: 2269 | S39: 11.21 | T39: 21 | U39: 1389 | V39: 63 | W39: 69.14 | X39: 0.00295 | AN39: 227 | AO39: 14 | AP39: 7 | AQ39: 1 | AR39: 0 | AT39: 0 | AU39: 1 | AV39: 1 | AW39: 1 | AX39: 1 | AY39: 1 | AZ39: 1
A40: ChIJkWsGmd1czpQRGLydxc29vbw | B40: Place Games | C40: São Paulo | D40: Sudeste | E40: 4.8 | F40: 572 | G40: 5 | H40: 46 | I40: 10 | J40: 22 | K40: 0 | L40: 0 | P40: 251 | Q40: 14021 | R40: 2362 | S40: 10.55 | T40: 23 | U40: 1917 | V40: 148 | W40: 89.78 | X40: 0.0064 | Y40: 56 | Z40: 12.5 | AA40: 9 | AB40: 29 | AC40: 17.9 | AD40: 38 | AE40: 52.72 | AF40: 24.15 | AG40: 50.5 | AH40: 71.47 | AI40: 38.9 | AJ40: 33 | AK40: 13 | AL40: 6.9 | AN40: 633 | AO40: 18 | AP40: 11 | AQ40: 0 | AR40: 1 | AS40: 1 | AT40: 0 | AU40: 0 | AV40: 1 | AW40: 1 | AX40: 1 | AY40: 1 | AZ40: 1
...

Sheet dicionario
A1: coluna | B1: grupo | C1: descrição | D1: unidade
A2: avaliacao_media | B2: Google Maps | C2: Nota média no Google | D2: 1 a 5
A3: volume_avaliacoes | B3: Google Maps | C3: Nº de avaliações no Google | D3: avaliações
A4: dias_abertos | B4: Horários | C4: Dias abertos por semana | D4: dias
A5: horas_semana | B5: Horários | C5: Horas abertas por semana | D5: horas
A6: abre_cedo_h | B6: Horários | C6: Abertura mais cedo da semana | D6: hora do dia
A7: fecha_tarde_h | B7: Horários | C7: Fechamento mais tarde da semana (25 = 1h da manhã) | D7: hora do dia
A8: metro_500m | B8: Entorno | C8: Estações de metrô até 500 m | D8: estações
A9: metro_1000m | B9: Entorno | C9: Estações de metrô até 1000 m | D9: estações
A10: dist_metro_m | B10: Entorno | C10: Distância à estação de metrô mais próxima | D10: metros (linha reta)
A11: shopping_porte_500m | B11: Entorno | C11: Shoppings de porte até 500 m (onde o porte foi buscado) | D11: shoppings
A12: shopping_porte_1000m | B12: Entorno | C12: Shoppings de porte até 1000 m (onde o porte foi buscado) | D12: shoppings
... A51: — | B51: Regras | C51: Cada casa conta uma vez, na metrópole do endereço. Instagram de LudoCafé e Dominaria vazio (perfil coletado não é o da casa). Couvert só nas casas com couvert encontrado. Shoppings de porte só onde o porte foi buscado. Distâncias em linha reta (coletor de entorno). Desvio padrão amostral; quartis pelo método inclusivo. | D51: —
