Workbook

Sheet regiao_painel
A1: região | B1: casas | C1: % das casas | D1: nota média (mediana) | E1: avaliações no Google (mediana) | F1: horas abertas por semana (média) | G1: fechamento mais tarde (mediana, h) | H1: abre domingo (%) | I1: abre segunda (%) | J1: metrô até 1000 m (%) | K1: seguidores (mediana) | L1: posts no período (média) | M1: interações por post (mediana) | N1: com cardápio (casas) | O1: cesta mediana (mediana, R$) | P1: cesta mediana (mín., R$) | Q1: cesta mediana (máx., R$) | R1: avaliações no B2 (soma)
A2: Norte | B2: =COUNTIF(dados!$D$2:$D$55,A2) | C2: =B2/COUNTA(dados!$A$2:$A$55) | D2: {=IFERROR(MEDIAN(IF((dados!$D$2:$D$55=$A2)*(dados!$E$2:$E$55<>""),dados!$E$2:$E$55)),"")} | E2: {=IFERROR(MEDIAN(IF((dados!$D$2:$D$55=$A2)*(dados!$F$2:$F$55<>""),dados!$F$2:$F$55)),"")} | F2: =IFERROR(AVERAGEIFS(dados!$H$2:$H$55,dados!$D$2:$D$55,$A2),"") | G2: {=IFERROR(MEDIAN(IF((dados!$D$2:$D$55=$A2)*(dados!$J$2:$J$55<>""),dados!$J$2:$J$55)),"")} | H2: =IFERROR(AVERAGEIFS(dados!$AW$2:$AW$55,dados!$D$2:$D$55,$A2),"") | I2: =IFERROR(AVERAGEIFS(dados!$AQ$2:$AQ$55,dados!$D$2:$D$55,$A2),"") | J2: =IFERROR(AVERAGEIFS(dados!$AN$2:$AN$55,dados!$D$2:$D$55,$A2),"") | K2: {=IFERROR(MEDIAN(IF((dados!$D$2:$D$55=$A2)*(dados!$Q$2:$Q$55<>""),dados!$Q$2:$Q$55)),"")} | L2: =IFERROR(AVERAGEIFS(dados!$T$2:$T$55,dados!$D$2:$D$55,$A2),"") | M2: {=IFERROR(MEDIAN(IF((dados!$D$2:$D$55=$A2)*(dados!$W$2:$W$55<>""),dados!$W$2:$W$55)),"")} | N2: =SUMIF(dados!$D$2:$D$55,$A2,dados!$AO$2:$AO$55) | O2: {=IFERROR(MEDIAN(IF((dados!$D$2:$D$55=$A2)*(dados!$AD$2:$AD$55<>""),dados!$AD$2:$AD$55)),"")} | P2: =IF(COUNTIFS(dados!$D$2:$D$55,$A2,dados!$AD$2:$AD$55,"<>")=0,"",_xlfn.MINIFS(dados!$AD$2:$AD$55,dados!$D$2:$D$55,$A2)) | Q2: =IF(COUNTIFS(dados!$D$2:$D$55,$A2,dados!$AD$2:$AD$55,"<>")=0,"",_xlfn.MAXIFS(dados!$AD$2:$AD$55,dados!$D$2:$D$55,$A2)) | R2: =SUMIF(dados!$D$2:$D$55,$A2,dados!$AL$2:$AL$55)
A3: Nordeste | B3: =COUNTIF(dados!$D$2:$D$55,A3) | C3: =B3/COUNTA(dados!$A$2:$A$55) | D3: {=IFERROR(MEDIAN(IF((dados!$D$2:$D$55=$A3)*(dados!$E$2:$E$55<>""),dados!$E$2:$E$55)),"")} | E3: {=IFERROR(MEDIAN(IF((dados!$D$2:$D$55=$A3)*(dados!$F$2:$F$55<>""),dados!$F$2:$F$55)),"")} | F3: =IFERROR(AVERAGEIFS(dados!$H$2:$H$55,dados!$D$2:$D$55,$A3),"") | G3: {=IFERROR(MEDIAN(IF((dados!$D$2:$D$55=$A3)*(dados!$J$2:$J$55<>""),dados!$J$2:$J$55)),"")} | H3: =IFERROR(AVERAGEIFS(dados!$AW$2:$AW$55,dados!$D$2:$D$55,$A3),"") | I3: =IFERROR(AVERAGEIFS(dados!$AQ$2:$AQ$55,dados!$D$2:$D$55,$A3),"") | J3: =IFERROR(AVERAGEIFS(dados!$AN$2:$AN$55,dados!$D$2:$D$55,$A3),"") | K3: {=IFERROR(MEDIAN(IF((dados!$D$2:$D$55=$A3)*(dados!$Q$2:$Q$55<>""),dados!$Q$2:$Q$55)),"")} | L3: =IFERROR(AVERAGEIFS(dados!$T$2:$T$55,dados!$D$2:$D$55,$A3),"") | M3: {=IFERROR(MEDIAN(IF((dados!$D$2:$D$55=$A3)*(dados!$W$2:$W$55<>""),dados!$W$2:$W$55)),"")} | N3: =SUMIF(dados!$D$2:$D$55,$A3,dados!$AO$2:$AO$55) | O3: {=IFERROR(MEDIAN(IF((dados!$D$2:$D$55=$A3)*(dados!$AD$2:$AD$55<>""),dados!$AD$2:$AD$55)),"")} | P3: =IF(COUNTIFS(dados!$D$2:$D$55,$A3,dados!$AD$2:$AD$55,"<>")=0,"",_xlfn.MINIFS(dados!$AD$2:$AD$55,dados!$D$2:$D$55,$A3)) | Q3: =IF(COUNTIFS(dados!$D$2:$D$55,$A3,dados!$AD$2:$AD$55,"<>")=0,"",_xlfn.MAXIFS(dados!$AD$2:$AD$55,dados!$D$2:$D$55,$A3)) | R3: =SUMIF(dados!$D$2:$D$55,$A3,dados!$AL$2:$AL$55)
A4: Centro-Oeste | B4: =COUNTIF(dados!$D$2:$D$55,A4) | C4: =B4/COUNTA(dados!$A$2:$A$55) | D4: {=IFERROR(MEDIAN(IF((dados!$D$2:$D$55=$A4)*(dados!$E$2:$E$55<>""),dados!$E$2:$E$55)),"")} | E4: {=IFERROR(MEDIAN(IF((dados!$D$2:$D$55=$A4)*(dados!$F$2:$F$55<>""),dados!$F$2:$F$55)),"")} | F4: =IFERROR(AVERAGEIFS(dados!$H$2:$H$55,dados!$D$2:$D$55,$A4),"") | G4: {=IFERROR(MEDIAN(IF((dados!$D$2:$D$55=$A4)*(dados!$J$2:$J$55<>""),dados!$J$2:$J$55)),"")} | H4: =IFERROR(AVERAGEIFS(dados!$AW$2:$AW$55,dados!$D$2:$D$55,$A4),"") | I4: =IFERROR(AVERAGEIFS(dados!$AQ$2:$AQ$55,dados!$D$2:$D$55,$A4),"") | J4: =IFERROR(AVERAGEIFS(dados!$AN$2:$AN$55,dados!$D$2:$D$55,$A4),"") | K4: {=IFERROR(MEDIAN(IF((dados!$D$2:$D$55=$A4)*(dados!$Q$2:$Q$55<>""),dados!$Q$2:$Q$55)),"")} | L4: =IFERROR(AVERAGEIFS(dados!$T$2:$T$55,dados!$D$2:$D$55,$A4),"") | M4: {=IFERROR(MEDIAN(IF((dados!$D$2:$D$55=$A4)*(dados!$W$2:$W$55<>""),dados!$W$2:$W$55)),"")} | N4: =SUMIF(dados!$D$2:$D$55,$A4,dados!$AO$2:$AO$55) | O4: {=IFERROR(MEDIAN(IF((dados!$D$2:$D$55=$A4)*(dados!$AD$2:$AD$55<>""),dados!$AD$2:$AD$55)),"")} | P4: =IF(COUNTIFS(dados!$D$2:$D$55,$A4,dados!$AD$2:$AD$55,"<>")=0,"",_xlfn.MINIFS(dados!$AD$2:$AD$55,dados!$D$2:$D$55,$A4)) | Q4: =IF(COUNTIFS(dados!$D$2:$D$55,$A4,dados!$AD$2:$AD$55,"<>")=0,"",_xlfn.MAXIFS(dados!$AD$2:$AD$55,dados!$D$2:$D$55,$A4)) | R4: =SUMIF(dados!$D$2:$D$55,$A4,dados!$AL$2:$AL$55)
A5: Sudeste | B5: =COUNTIF(dados!$D$2:$D$55,A5) | C5: =B5/COUNTA(dados!$A$2:$A$55) | D5: {=IFERROR(MEDIAN(IF((dados!$D$2:$D$55=$A5)*(dados!$E$2:$E$55<>""),dados!$E$2:$E$55)),"")} | E5: {=IFERROR(MEDIAN(IF((dados!$D$2:$D$55=$A5)*(dados!$F$2:$F$55<>""),dados!$F$2:$F$55)),"")} | F5: =IFERROR(AVERAGEIFS(dados!$H$2:$H$55,dados!$D$2:$D$55,$A5),"") | G5: {=IFERROR(MEDIAN(IF((dados!$D$2:$D$55=$A5)*(dados!$J$2:$J$55<>""),dados!$J$2:$J$55)),"")} | H5: =IFERROR(AVERAGEIFS(dados!$AW$2:$AW$55,dados!$D$2:$D$55,$A5),"") | I5: =IFERROR(AVERAGEIFS(dados!$AQ$2:$AQ$55,dados!$D$2:$D$55,$A5),"") | J5: =IFERROR(AVERAGEIFS(dados!$AN$2:$AN$55,dados!$D$2:$D$55,$A5),"") | K5: {=IFERROR(MEDIAN(IF((dados!$D$2:$D$55=$A5)*(dados!$Q$2:$Q$55<>""),dados!$Q$2:$Q$55)),"")} | L5: =IFERROR(AVERAGEIFS(dados!$T$2:$T$55,dados!$D$2:$D$55,$A5),"") | M5: {=IFERROR(MEDIAN(IF((dados!$D$2:$D$55=$A5)*(dados!$W$2:$W$55<>""),dados!$W$2:$W$55)),"")} | N5: =SUMIF(dados!$D$2:$D$55,$A5,dados!$AO$2:$AO$55) | O5: {=IFERROR(MEDIAN(IF((dados!$D$2:$D$55=$A5)*(dados!$AD$2:$AD$55<>""),dados!$AD$2:$AD$55)),"")} | P5: =IF(COUNTIFS(dados!$D$2:$D$55,$A5,dados!$AD$2:$AD$55,"<>")=0,"",_xlfn.MINIFS(dados!$AD$2:$AD$55,dados!$D$2:$D$55,$A5)) | Q5: =IF(COUNTIFS(dados!$D$2:$D$55,$A5,dados!$AD$2:$AD$55,"<>")=0,"",_xlfn.MAXIFS(dados!$AD$2:$AD$55,dados!$D$2:$D$55,$A5)) | R5: =SUMIF(dados!$D$2:$D$55,$A5,dados!$AL$2:$AL$55)
A6: Sul | B6: =COUNTIF(dados!$D$2:$D$55,A6) | C6: =B6/COUNTA(dados!$A$2:$A$55) | D6: {=IFERROR(MEDIAN(IF((dados!$D$2:$D$55=$A6)*(dados!$E$2:$E$55<>""),dados!$E$2:$E$55)),"")} | E6: {=IFERROR(MEDIAN(IF((dados!$D$2:$D$55=$A6)*(dados!$F$2:$F$55<>""),dados!$F$2:$F$55)),"")} | F6: =IFERROR(AVERAGEIFS(dados!$H$2:$H$55,dados!$D$2:$D$55,$A6),"") | G6: {=IFERROR(MEDIAN(IF((dados!$D$2:$D$55=$A6)*(dados!$J$2:$J$55<>""),dados!$J$2:$J$55)),"")} | H6: =IFERROR(AVERAGEIFS(dados!$AW$2:$AW$55,dados!$D$2:$D$55,$A6),"") | I6: =IFERROR(AVERAGEIFS(dados!$AQ$2:$AQ$55,dados!$D$2:$D$55,$A6),"") | J6: =IFERROR(AVERAGEIFS(dados!$AN$2:$AN$55,dados!$D$2:$D$55,$A6),"") | K6: {=IFERROR(MEDIAN(IF((dados!$D$2:$D$55=$A6)*(dados!$Q$2:$Q$55<>""),dados!$Q$2:$Q$55)),"")} | L6: =IFERROR(AVERAGEIFS(dados!$T$2:$T$55,dados!$D$2:$D$55,$A6),"") | M6: {=IFERROR(MEDIAN(IF((dados!$D$2:$D$55=$A6)*(dados!$W$2:$W$55<>""),dados!$W$2:$W$55)),"")} | N6: =SUMIF(dados!$D$2:$D$55,$A6,dados!$AO$2:$AO$55) | O6: {=IFERROR(MEDIAN(IF((dados!$D$2:$D$55=$A6)*(dados!$AD$2:$AD$55<>""),dados!$AD$2:$AD$55)),"")} | P6: =IF(COUNTIFS(dados!$D$2:$D$55,$A6,dados!$AD$2:$AD$55,"<>")=0,"",_xlfn.MINIFS(dados!$AD$2:$AD$55,dados!$D$2:$D$55,$A6)) | Q6: =IF(COUNTIFS(dados!$D$2:$D$55,$A6,dados!$AD$2:$AD$55,"<>")=0,"",_xlfn.MAXIFS(dados!$AD$2:$AD$55,dados!$D$2:$D$55,$A6)) | R6: =SUMIF(dados!$D$2:$D$55,$A6,dados!$AL$2:$AL$55)
A7: Total | B7: =SUM(B2:B6) | C7: =SUM(C2:C6)
A8: Conferência (total − casas da aba dados; deve ser 0) | B8: =B7-COUNTA(dados!$A$2:$A$55)

Sheet metropole_painel
A1: metrópole | B1: região | C1: casas | D1: % das casas | E1: nota média (mediana) | F1: avaliações no Google (mediana) | G1: horas abertas por semana (média) | H1: fechamento mais tarde (mediana, h) | I1: abre domingo (%) | J1: abre segunda (%) | K1: metrô até 1000 m (%) | L1: seguidores (mediana) | M1: posts no período (média) | N1: interações por post (mediana) | O1: com cardápio (casas) | P1: cesta mediana (mediana, R$) | Q1: cesta mediana (mín., R$) | R1: cesta mediana (máx., R$) | S1: avaliações no B2 (soma)
A2: Belo Horizonte | B2: Sudeste | C2: =COUNTIF(dados!$C$2:$C$55,A2) | D2: =C2/COUNTA(dados!$A$2:$A$55) | E2: {=IFERROR(MEDIAN(IF((dados!$C$2:$C$55=$A2)*(dados!$E$2:$E$55<>""),dados!$E$2:$E$55)),"")} | F2: {=IFERROR(MEDIAN(IF((dados!$C$2:$C$55=$A2)*(dados!$F$2:$F$55<>""),dados!$F$2:$F$55)),"")} | G2: =IFERROR(AVERAGEIFS(dados!$H$2:$H$55,dados!$C$2:$C$55,$A2),"") | H2: {=IFERROR(MEDIAN(IF((dados!$C$2:$C$55=$A2)*(dados!$J$2:$J$55<>""),dados!$J$2:$J$55)),"")} | I2: =IFERROR(AVERAGEIFS(dados!$AW$2:$AW$55,dados!$C$2:$C$55,$A2),"") | J2: =IFERROR(AVERAGEIFS(dados!$AQ$2:$AQ$55,dados!$C$2:$C$55,$A2),"") | K2: =IFERROR(AVERAGEIFS(dados!$AN$2:$AN$55,dados!$C$2:$C$55,$A2),"") | L2: {=IFERROR(MEDIAN(IF((dados!$C$2:$C$55=$A2)*(dados!$Q$2:$Q$55<>""),dados!$Q$2:$Q$55)),"")} | M2: =IFERROR(AVERAGEIFS(dados!$T$2:$T$55,dados!$C$2:$C$55,$A2),"") | N2: {=IFERROR(MEDIAN(IF((dados!$C$2:$C$55=$A2)*(dados!$W$2:$W$55<>""),dados!$W$2:$W$55)),"")} | O2: =SUMIF(dados!$C$2:$C$55,$A2,dados!$AO$2:$AO$55) | P2: {=IFERROR(MEDIAN(IF((dados!$C$2:$C$55=$A2)*(dados!$AD$2:$AD$55<>""),dados!$AD$2:$AD$55)),"")} | Q2: =IF(COUNTIFS(dados!$C$2:$C$55,$A2,dados!$AD$2:$AD$55,"<>")=0,"",_xlfn.MINIFS(dados!$AD$2:$AD$55,dados!$C$2:$C$55,$A2)) | R2: =IF(COUNTIFS(dados!$C$2:$C$55,$A2,dados!$AD$2:$AD$55,"<>")=0,"",_xlfn.MAXIFS(dados!$AD$2:$AD$55,dados!$C$2:$C$55,$A2)) | S2: =SUMIF(dados!$C$2:$C$55,$A2,dados!$AL$2:$AL$55)
A3: Belém | B3: Norte | C3: =COUNTIF(dados!$C$2:$C$55,A3) | D3: =C3/COUNTA(dados!$A$2:$A$55) | E3: {=IFERROR(MEDIAN(IF((dados!$C$2:$C$55=$A3)*(dados!$E$2:$E$55<>""),dados!$E$2:$E$55)),"")} | F3: {=IFERROR(MEDIAN(IF((dados!$C$2:$C$55=$A3)*(dados!$F$2:$F$55<>""),dados!$F$2:$F$55)),"")} | G3: =IFERROR(AVERAGEIFS(dados!$H$2:$H$55,dados!$C$2:$C$55,$A3),"") | H3: {=IFERROR(MEDIAN(IF((dados!$C$2:$C$55=$A3)*(dados!$J$2:$J$55<>""),dados!$J$2:$J$55)),"")} | I3: =IFERROR(AVERAGEIFS(dados!$AW$2:$AW$55,dados!$C$2:$C$55,$A3),"") | J3: =IFERROR(AVERAGEIFS(dados!$AQ$2:$AQ$55,dados!$C$2:$C$55,$A3),"") | K3: =IFERROR(AVERAGEIFS(dados!$AN$2:$AN$55,dados!$C$2:$C$55,$A3),"") | L3: {=IFERROR(MEDIAN(IF((dados!$C$2:$C$55=$A3)*(dados!$Q$2:$Q$55<>""),dados!$Q$2:$Q$55)),"")} | M3: =IFERROR(AVERAGEIFS(dados!$T$2:$T$55,dados!$C$2:$C$55,$A3),"") | N3: {=IFERROR(MEDIAN(IF((dados!$C$2:$C$55=$A3)*(dados!$W$2:$W$55<>""),dados!$W$2:$W$55)),"")} | O3: =SUMIF(dados!$C$2:$C$55,$A3,dados!$AO$2:$AO$55) | P3: {=IFERROR(MEDIAN(IF((dados!$C$2:$C$55=$A3)*(dados!$AD$2:$AD$55<>""),dados!$AD$2:$AD$55)),"")} | Q3: =IF(COUNTIFS(dados!$C$2:$C$55,$A3,dados!$AD$2:$AD$55,"<>")=0,"",_xlfn.MINIFS(dados!$AD$2:$AD$55,dados!$C$2:$C$55,$A3)) | R3: =IF(COUNTIFS(dados!$C$2:$C$55,$A3,dados!$AD$2:$AD$55,"<>")=0,"",_xlfn.MAXIFS(dados!$AD$2:$AD$55,dados!$C$2:$C$55,$A3)) | S3: =SUMIF(dados!$C$2:$C$55,$A3,dados!$AL$2:$AL$55)
A4: Brasília | B4: Centro-Oeste | C4: =COUNTIF(dados!$C$2:$C$55,A4) | D4: =C4/COUNTA(dados!$A$2:$A$55) | E4: {=IFERROR(MEDIAN(IF((dados!$C$2:$C$55=$A4)*(dados!$E$2:$E$55<>""),dados!$E$2:$E$55)),"")} | F4: {=IFERROR(MEDIAN(IF((dados!$C$2:$C$55=$A4)*(dados!$F$2:$F$55<>""),dados!$F$2:$F$55)),"")} | G4: =IFERROR(AVERAGEIFS(dados!$H$2:$H$55,dados!$C$2:$C$55,$A4),"") | H4: {=IFERROR(MEDIAN(IF((dados!$C$2:$C$55=$A4)*(dados!$J$2:$J$55<>""),dados!$J$2:$J$55)),"")} | I4: =IFERROR(AVERAGEIFS(dados!$AW$2:$AW$55,dados!$C$2:$C$55,$A4),"") | J4: =IFERROR(AVERAGEIFS(dados!$AQ$2:$AQ$55,dados!$C$2:$C$55,$A4),"") | K4: =IFERROR(AVERAGEIFS(dados!$AN$2:$AN$55,dados!$C$2:$C$55,$A4),"") | L4: {=IFERROR(MEDIAN(IF((dados!$C$2:$C$55=$A4)*(dados!$Q$2:$Q$55<>""),dados!$Q$2:$Q$55)),"")} | M4: =IFERROR(AVERAGEIFS(dados!$T$2:$T$55,dados!$C$2:$C$55,$A4),"") | N4: {=IFERROR(MEDIAN(IF((dados!$C$2:$C$55=$A4)*(dados!$W$2:$W$55<>""),dados!$W$2:$W$55)),"")} | O4: =SUMIF(dados!$C$2:$C$55,$A4,dados!$AO$2:$AO$55) | P4: {=IFERROR(MEDIAN(IF((dados!$C$2:$C$55=$A4)*(dados!$AD$2:$AD$55<>""),dados!$AD$2:$AD$55)),"")} | Q4: =IF(COUNTIFS(dados!$C$2:$C$55,$A4,dados!$AD$2:$AD$55,"<>")=0,"",_xlfn.MINIFS(dados!$AD$2:$AD$55,dados!$C$2:$C$55,$A4)) | R4: =IF(COUNTIFS(dados!$C$2:$C$55,$A4,dados!$AD$2:$AD$55,"<>")=0,"",_xlfn.MAXIFS(dados!$AD$2:$AD$55,dados!$C$2:$C$55,$A4)) | S4: =SUMIF(dados!$C$2:$C$55,$A4,dados!$AL$2:$AL$55)
A5: Curitiba | B5: Sul | C5: =COUNTIF(dados!$C$2:$C$55,A5) | D5: =C5/COUNTA(dados!$A$2:$A$55) | E5: {=IFERROR(MEDIAN(IF((dados!$C$2:$C$55=$A5)*(dados!$E$2:$E$55<>""),dados!$E$2:$E$55)),"")} | F5: {=IFERROR(MEDIAN(IF((dados!$C$2:$C$55=$A5)*(dados!$F$2:$F$55<>""),dados!$F$2:$F$55)),"")} | G5: =IFERROR(AVERAGEIFS(dados!$H$2:$H$55,dados!$C$2:$C$55,$A5),"") | H5: {=IFERROR(MEDIAN(IF((dados!$C$2:$C$55=$A5)*(dados!$J$2:$J$55<>""),dados!$J$2:$J$55)),"")} | I5: =IFERROR(AVERAGEIFS(dados!$AW$2:$AW$55,dados!$C$2:$C$55,$A5),"") | J5: =IFERROR(AVERAGEIFS(dados!$AQ$2:$AQ$55,dados!$C$2:$C$55,$A5),"") | K5: =IFERROR(AVERAGEIFS(dados!$AN$2:$AN$55,dados!$C$2:$C$55,$A5),"") | L5: {=IFERROR(MEDIAN(IF((dados!$C$2:$C$55=$A5)*(dados!$Q$2:$Q$55<>""),dados!$Q$2:$Q$55)),"")} | M5: =IFERROR(AVERAGEIFS(dados!$T$2:$T$55,dados!$C$2:$C$55,$A5),"") | N5: {=IFERROR(MEDIAN(IF((dados!$C$2:$C$55=$A5)*(dados!$W$2:$W$55<>""),dados!$W$2:$W$55)),"")} | O5: =SUMIF(dados!$C$2:$C$55,$A5,dados!$AO$2:$AO$55) | P5: {=IFERROR(MEDIAN(IF((dados!$C$2:$C$55=$A5)*(dados!$AD$2:$AD$55<>""),dados!$AD$2:$AD$55)),"")} | Q5: =IF(COUNTIFS(dados!$C$2:$C$55,$A5,dados!$AD$2:$AD$55,"<>")=0,"",_xlfn.MINIFS(dados!$AD$2:$AD$55,dados!$C$2:$C$55,$A5)) | R5: =IF(COUNTIFS(dados!$C$2:$C$55,$A5,dados!$AD$2:$AD$55,"<>")=0,"",_xlfn.MAXIFS(dados!$AD$2:$AD$55,dados!$C$2:$C$55,$A5)) | S5: =SUMIF(dados!$C$2:$C$55,$A5,dados!$AL$2:$AL$55)
A6: Florianópolis | B6: Sul | C6: =COUNTIF(dados!$C$2:$C$55,A6) | D6: =C6/COUNTA(dados!$A$2:$A$55) | E6: {=IFERROR(MEDIAN(IF((dados!$C$2:$C$55=$A6)*(dados!$E$2:$E$55<>""),dados!$E$2:$E$55)),"")} | F6: {=IFERROR(MEDIAN(IF((dados!$C$2:$C$55=$A6)*(dados!$F$2:$F$55<>""),dados!$F$2:$F$55)),"")} | G6: =IFERROR(AVERAGEIFS(dados!$H$2:$H$55,dados!$C$2:$C$55,$A6),"") | H6: {=IFERROR(MEDIAN(IF((dados!$C$2:$C$55=$A6)*(dados!$J$2:$J$55<>""),dados!$J$2:$J$55)),"")} | I6: =IFERROR(AVERAGEIFS(dados!$AW$2:$AW$55,dados!$C$2:$C$55,$A6),"") | J6: =IFERROR(AVERAGEIFS(dados!$AQ$2:$AQ$55,dados!$C$2:$C$55,$A6),"") | K6: =IFERROR(AVERAGEIFS(dados!$AN$2:$AN$55,dados!$C$2:$C$55,$A6),"") | L6: {=IFERROR(MEDIAN(IF((dados!$C$2:$C$55=$A6)*(dados!$Q$2:$Q$55<>""),dados!$Q$2:$Q$55)),"")} | M6: =IFERROR(AVERAGEIFS(dados!$T$2:$T$55,dados!$C$2:$C$55,$A6),"") | N6: {=IFERROR(MEDIAN(IF((dados!$C$2:$C$55=$A6)*(dados!$W$2:$W$55<>""),dados!$W$2:$W$55)),"")} | O6: =SUMIF(dados!$C$2:$C$55,$A6,dados!$AO$2:$AO$55) | P6: {=IFERROR(MEDIAN(IF((dados!$C$2:$C$55=$A6)*(dados!$AD$2:$AD$55<>""),dados!$AD$2:$AD$55)),"")} | Q6: =IF(COUNTIFS(dados!$C$2:$C$55,$A6,dados!$AD$2:$AD$55,"<>")=0,"",_xlfn.MINIFS(dados!$AD$2:$AD$55,dados!$C$2:$C$55,$A6)) | R6: =IF(COUNTIFS(dados!$C$2:$C$55,$A6,dados!$AD$2:$AD$55,"<>")=0,"",_xlfn.MAXIFS(dados!$AD$2:$AD$55,dados!$C$2:$C$55,$A6)) | S6: =SUMIF(dados!$C$2:$C$55,$A6,dados!$AL$2:$AL$55)
A7: Fortaleza | B7: Nordeste | C7: =COUNTIF(dados!$C$2:$C$55,A7) | D7: =C7/COUNTA(dados!$A$2:$A$55) | E7: {=IFERROR(MEDIAN(IF((dados!$C$2:$C$55=$A7)*(dados!$E$2:$E$55<>""),dados!$E$2:$E$55)),"")} | F7: {=IFERROR(MEDIAN(IF((dados!$C$2:$C$55=$A7)*(dados!$F$2:$F$55<>""),dados!$F$2:$F$55)),"")} | G7: =IFERROR(AVERAGEIFS(dados!$H$2:$H$55,dados!$C$2:$C$55,$A7),"") | H7: {=IFERROR(MEDIAN(IF((dados!$C$2:$C$55=$A7)*(dados!$J$2:$J$55<>""),dados!$J$2:$J$55)),"")} | I7: =IFERROR(AVERAGEIFS(dados!$AW$2:$AW$55,dados!$C$2:$C$55,$A7),"") | J7: =IFERROR(AVERAGEIFS(dados!$AQ$2:$AQ$55,dados!$C$2:$C$55,$A7),"") | K7: =IFERROR(AVERAGEIFS(dados!$AN$2:$AN$55,dados!$C$2:$C$55,$A7),"") | L7: {=IFERROR(MEDIAN(IF((dados!$C$2:$C$55=$A7)*(dados!$Q$2:$Q$55<>""),dados!$Q$2:$Q$55)),"")} | M7: =IFERROR(AVERAGEIFS(dados!$T$2:$T$55,dados!$C$2:$C$55,$A7),"") | N7: {=IFERROR(MEDIAN(IF((dados!$C$2:$C$55=$A7)*(dados!$W$2:$W$55<>""),dados!$W$2:$W$55)),"")} | O7: =SUMIF(dados!$C$2:$C$55,$A7,dados!$AO$2:$AO$55) | P7: {=IFERROR(MEDIAN(IF((dados!$C$2:$C$55=$A7)*(dados!$AD$2:$AD$55<>""),dados!$AD$2:$AD$55)),"")} | Q7: =IF(COUNTIFS(dados!$C$2:$C$55,$A7,dados!$AD$2:$AD$55,"<>")=0,"",_xlfn.MINIFS(dados!$AD$2:$AD$55,dados!$C$2:$C$55,$A7)) | R7: =IF(COUNTIFS(dados!$C$2:$C$55,$A7,dados!$AD$2:$AD$55,"<>")=0,"",_xlfn.MAXIFS(dados!$AD$2:$AD$55,dados!$C$2:$C$55,$A7)) | S7: =SUMIF(dados!$C$2:$C$55,$A7,dados!$AL$2:$AL$55)
A8: Goiânia | B8: Centro-Oeste | C8: =COUNTIF(dados!$C$2:$C$55,A8) | D8: =C8/COUNTA(dados!$A$2:$A$55) | E8: {=IFERROR(MEDIAN(IF((dados!$C$2:$C$55=$A8)*(dados!$E$2:$E$55<>""),dados!$E$2:$E$55)),"")} | F8: {=IFERROR(MEDIAN(IF((dados!$C$2:$C$55=$A8)*(dados!$F$2:$F$55<>""),dados!$F$2:$F$55)),"")} | G8: =IFERROR(AVERAGEIFS(dados!$H$2:$H$55,dados!$C$2:$C$55,$A8),"") | H8: {=IFERROR(MEDIAN(IF((dados!$C$2:$C$55=$A8)*(dados!$J$2:$J$55<>""),dados!$J$2:$J$55)),"")} | I8: =IFERROR(AVERAGEIFS(dados!$AW$2:$AW$55,dados!$C$2:$C$55,$A8),"") | J8: =IFERROR(AVERAGEIFS(dados!$AQ$2:$AQ$55,dados!$C$2:$C$55,$A8),"") | K8: =IFERROR(AVERAGEIFS(dados!$AN$2:$AN$55,dados!$C$2:$C$55,$A8),"") | L8: {=IFERROR(MEDIAN(IF((dados!$C$2:$C$55=$A8)*(dados!$Q$2:$Q$55<>""),dados!$Q$2:$Q$55)),"")} | M8: =IFERROR(AVERAGEIFS(dados!$T$2:$T$55,dados!$C$2:$C$55,$A8),"") | N8: {=IFERROR(MEDIAN(IF((dados!$C$2:$C$55=$A8)*(dados!$W$2:$W$55<>""),dados!$W$2:$W$55)),"")} | O8: =SUMIF(dados!$C$2:$C$55,$A8,dados!$AO$2:$AO$55) | P8: {=IFERROR(MEDIAN(IF((dados!$C$2:$C$55=$A8)*(dados!$AD$2:$AD$55<>""),dados!$AD$2:$AD$55)),"")} | Q8: =IF(COUNTIFS(dados!$C$2:$C$55,$A8,dados!$AD$2:$AD$55,"<>")=0,"",_xlfn.MINIFS(dados!$AD$2:$AD$55,dados!$C$2:$C$55,$A8)) | R8: =IF(COUNTIFS(dados!$C$2:$C$55,$A8,dados!$AD$2:$AD$55,"<>")=0,"",_xlfn.MAXIFS(dados!$AD$2:$AD$55,dados!$C$2:$C$55,$A8)) | S8: =SUMIF(dados!$C$2:$C$55,$A8,dados!$AL$2:$AL$55)
A9: Porto Alegre | B9: Sul | C9: =COUNTIF(dados!$C$2:$C$55,A9) | D9: =C9/COUNTA(dados!$A$2:$A$55) | E9: {=IFERROR(MEDIAN(IF((dados!$C$2:$C$55=$A9)*(dados!$E$2:$E$55<>""),dados!$E$2:$E$55)),"")} | F9: {=IFERROR(MEDIAN(IF((dados!$C$2:$C$55=$A9)*(dados!$F$2:$F$55<>""),dados!$F$2:$F$55)),"")} | G9: =IFERROR(AVERAGEIFS(dados!$H$2:$H$55,dados!$C$2:$C$55,$A9),"") | H9: {=IFERROR(MEDIAN(IF((dados!$C$2:$C$55=$A9)*(dados!$J$2:$J$55<>""),dados!$J$2:$J$55)),"")} | I9: =IFERROR(AVERAGEIFS(dados!$AW$2:$AW$55,dados!$C$2:$C$55,$A9),"") | J9: =IFERROR(AVERAGEIFS(dados!$AQ$2:$AQ$55,dados!$C$2:$C$55,$A9),"") | K9: =IFERROR(AVERAGEIFS(dados!$AN$2:$AN$55,dados!$C$2:$C$55,$A9),"") | L9: {=IFERROR(MEDIAN(IF((dados!$C$2:$C$55=$A9)*(dados!$Q$2:$Q$55<>""),dados!$Q$2:$Q$55)),"")} | M9: =IFERROR(AVERAGEIFS(dados!$T$2:$T$55,dados!$C$2:$C$55,$A9),"") | N9: {=IFERROR(MEDIAN(IF((dados!$C$2:$C$55=$A9)*(dados!$W$2:$W$55<>""),dados!$W$2:$W$55)),"")} | O9: =SUMIF(dados!$C$2:$C$55,$A9,dados!$AO$2:$AO$55) | P9: {=IFERROR(MEDIAN(IF((dados!$C$2:$C$55=$A9)*(dados!$AD$2:$AD$55<>""),dados!$AD$2:$AD$55)),"")} | Q9: =IF(COUNTIFS(dados!$C$2:$C$55,$A9,dados!$AD$2:$AD$55,"<>")=0,"",_xlfn.MINIFS(dados!$AD$2:$AD$55,dados!$C$2:$C$55,$A9)) | R9: =IF(COUNTIFS(dados!$C$2:$C$55,$A9,dados!$AD$2:$AD$55,"<>")=0,"",_xlfn.MAXIFS(dados!$AD$2:$AD$55,dados!$C$2:$C$55,$A9)) | S9: =SUMIF(dados!$C$2:$C$55,$A9,dados!$AL$2:$AL$55)
A10: Recife | B10: Nordeste | C10: =COUNTIF(dados!$C$2:$C$55,A10) | D10: =C10/COUNTA(dados!$A$2:$A$55) | E10: {=IFERROR(MEDIAN(IF((dados!$C$2:$C$55=$A10)*(dados!$E$2:$E$55<>""),dados!$E$2:$E$55)),"")} | F10: {=IFERROR(MEDIAN(IF((dados!$C$2:$C$55=$A10)*(dados!$F$2:$F$55<>""),dados!$F$2:$F$55)),"")} | G10: =IFERROR(AVERAGEIFS(dados!$H$2:$H$55,dados!$C$2:$C$55,$A10),"") | H10: {=IFERROR(MEDIAN(IF((dados!$C$2:$C$55=$A10)*(dados!$J$2:$J$55<>""),dados!$J$2:$J$55)),"")} | I10: =IFERROR(AVERAGEIFS(dados!$AW$2:$AW$55,dados!$C$2:$C$55,$A10),"") | J10: =IFERROR(AVERAGEIFS(dados!$AQ$2:$AQ$55,dados!$C$2:$C$55,$A10),"") | K10: =IFERROR(AVERAGEIFS(dados!$AN$2:$AN$55,dados!$C$2:$C$55,$A10),"") | L10: {=IFERROR(MEDIAN(IF((dados!$C$2:$C$55=$A10)*(dados!$Q$2:$Q$55<>""),dados!$Q$2:$Q$55)),"")} | M10: =IFERROR(AVERAGEIFS(dados!$T$2:$T$55,dados!$C$2:$C$55,$A10),"") | N10: {=IFERROR(MEDIAN(IF((dados!$C$2:$C$55=$A10)*(dados!$W$2:$W$55<>""),dados!$W$2:$W$55)),"")} | O10: =SUMIF(dados!$C$2:$C$55,$A10,dados!$AO$2:$AO$55) | P10: {=IFERROR(MEDIAN(IF((dados!$C$2:$C$55=$A10)*(dados!$AD$2:$AD$55<>""),dados!$AD$2:$AD$55)),"")} | Q10: =IF(COUNTIFS(dados!$C$2:$C$55,$A10,dados!$AD$2:$AD$55,"<>")=0,"",_xlfn.MINIFS(dados!$AD$2:$AD$55,dados!$C$2:$C$55,$A10)) | R10: =IF(COUNTIFS(dados!$C$2:$C$55,$A10,dados!$AD$2:$AD$55,"<>")=0,"",_xlfn.MAXIFS(dados!$AD$2:$AD$55,dados!$C$2:$C$55,$A10)) | S10: =SUMIF(dados!$C$2:$C$55,$A10,dados!$AL$2:$AL$55)
A11: Rio de Janeiro | B11: Sudeste | C11: =COUNTIF(dados!$C$2:$C$55,A11) | D11: =C11/COUNTA(dados!$A$2:$A$55) | E11: {=IFERROR(MEDIAN(IF((dados!$C$2:$C$55=$A11)*(dados!$E$2:$E$55<>""),dados!$E$2:$E$55)),"")} | F11: {=IFERROR(MEDIAN(IF((dados!$C$2:$C$55=$A11)*(dados!$F$2:$F$55<>""),dados!$F$2:$F$55)),"")} | G11: =IFERROR(AVERAGEIFS(dados!$H$2:$H$55,dados!$C$2:$C$55,$A11),"") | H11: {=IFERROR(MEDIAN(IF((dados!$C$2:$C$55=$A11)*(dados!$J$2:$J$55<>""),dados!$J$2:$J$55)),"")} | I11: =IFERROR(AVERAGEIFS(dados!$AW$2:$AW$55,dados!$C$2:$C$55,$A11),"") | J11: =IFERROR(AVERAGEIFS(dados!$AQ$2:$AQ$55,dados!$C$2:$C$55,$A11),"") | K11: =IFERROR(AVERAGEIFS(dados!$AN$2:$AN$55,dados!$C$2:$C$55,$A11),"") | L11: {=IFERROR(MEDIAN(IF((dados!$C$2:$C$55=$A11)*(dados!$Q$2:$Q$55<>""),dados!$Q$2:$Q$55)),"")} | M11: =IFERROR(AVERAGEIFS(dados!$T$2:$T$55,dados!$C$2:$C$55,$A11),"") | N11: {=IFERROR(MEDIAN(IF((dados!$C$2:$C$55=$A11)*(dados!$W$2:$W$55<>""),dados!$W$2:$W$55)),"")} | O11: =SUMIF(dados!$C$2:$C$55,$A11,dados!$AO$2:$AO$55) | P11: {=IFERROR(MEDIAN(IF((dados!$C$2:$C$55=$A11)*(dados!$AD$2:$AD$55<>""),dados!$AD$2:$AD$55)),"")} | Q11: =IF(COUNTIFS(dados!$C$2:$C$55,$A11,dados!$AD$2:$AD$55,"<>")=0,"",_xlfn.MINIFS(dados!$AD$2:$AD$55,dados!$C$2:$C$55,$A11)) | R11: =IF(COUNTIFS(dados!$C$2:$C$55,$A11,dados!$AD$2:$AD$55,"<>")=0,"",_xlfn.MAXIFS(dados!$AD$2:$AD$55,dados!$C$2:$C$55,$A11)) | S11: =SUMIF(dados!$C$2:$C$55,$A11,dados!$AL$2:$AL$55)
A12: Salvador | B12: Nordeste | C12: =COUNTIF(dados!$C$2:$C$55,A12) | D12: =C12/COUNTA(dados!$A$2:$A$55) | E12: {=IFERROR(MEDIAN(IF((dados!$C$2:$C$55=$A12)*(dados!$E$2:$E$55<>""),dados!$E$2:$E$55)),"")} | F12: {=IFERROR(MEDIAN(IF((dados!$C$2:$C$55=$A12)*(dados!$F$2:$F$55<>""),dados!$F$2:$F$55)),"")} | G12: =IFERROR(AVERAGEIFS(dados!$H$2:$H$55,dados!$C$2:$C$55,$A12),"") | H12: {=IFERROR(MEDIAN(IF((dados!$C$2:$C$55=$A12)*(dados!$J$2:$J$55<>""),dados!$J$2:$J$55)),"")} | I12: =IFERROR(AVERAGEIFS(dados!$AW$2:$AW$55,dados!$C$2:$C$55,$A12),"") | J12: =IFERROR(AVERAGEIFS(dados!$AQ$2:$AQ$55,dados!$C$2:$C$55,$A12),"") | K12: =IFERROR(AVERAGEIFS(dados!$AN$2:$AN$55,dados!$C$2:$C$55,$A12),"") | L12: {=IFERROR(MEDIAN(IF((dados!$C$2:$C$55=$A12)*(dados!$Q$2:$Q$55<>""),dados!$Q$2:$Q$55)),"")} | M12: =IFERROR(AVERAGEIFS(dados!$T$2:$T$55,dados!$C$2:$C$55,$A12),"") | N12: {=IFERROR(MEDIAN(IF((dados!$C$2:$C$55=$A12)*(dados!$W$2:$W$55<>""),dados!$W$2:$W$55)),"")} | O12: =SUMIF(dados!$C$2:$C$55,$A12,dados!$AO$2:$AO$55) | P12: {=IFERROR(MEDIAN(IF((dados!$C$2:$C$55=$A12)*(dados!$AD$2:$AD$55<>""),dados!$AD$2:$AD$55)),"")} | Q12: =IF(COUNTIFS(dados!$C$2:$C$55,$A12,dados!$AD$2:$AD$55,"<>")=0,"",_xlfn.MINIFS(dados!$AD$2:$AD$55,dados!$C$2:$C$55,$A12)) | R12: =IF(COUNTIFS(dados!$C$2:$C$55,$A12,dados!$AD$2:$AD$55,"<>")=0,"",_xlfn.MAXIFS(dados!$AD$2:$AD$55,dados!$C$2:$C$55,$A12)) | S12: =SUMIF(dados!$C$2:$C$55,$A12,dados!$AL$2:$AL$55)
A13: São Paulo | B13: Sudeste | C13: =COUNTIF(dados!$C$2:$C$55,A13) | D13: =C13/COUNTA(dados!$A$2:$A$55) | E13: {=IFERROR(MEDIAN(IF((dados!$C$2:$C$55=$A13)*(dados!$E$2:$E$55<>""),dados!$E$2:$E$55)),"")} | F13: {=IFERROR(MEDIAN(IF((dados!$C$2:$C$55=$A13)*(dados!$F$2:$F$55<>""),dados!$F$2:$F$55)),"")} | G13: =IFERROR(AVERAGEIFS(dados!$H$2:$H$55,dados!$C$2:$C$55,$A13),"") | H13: {=IFERROR(MEDIAN(IF((dados!$C$2:$C$55=$A13)*(dados!$J$2:$J$55<>""),dados!$J$2:$J$55)),"")} | I13: =IFERROR(AVERAGEIFS(dados!$AW$2:$AW$55,dados!$C$2:$C$55,$A13),"") | J13: =IFERROR(AVERAGEIFS(dados!$AQ$2:$AQ$55,dados!$C$2:$C$55,$A13),"") | K13: =IFERROR(AVERAGEIFS(dados!$AN$2:$AN$55,dados!$C$2:$C$55,$A13),"") | L13: {=IFERROR(MEDIAN(IF((dados!$C$2:$C$55=$A13)*(dados!$Q$2:$Q$55<>""),dados!$Q$2:$Q$55)),"")} | M13: =IFERROR(AVERAGEIFS(dados!$T$2:$T$55,dados!$C$2:$C$55,$A13),"") | N13: {=IFERROR(MEDIAN(IF((dados!$C$2:$C$55=$A13)*(dados!$W$2:$W$55<>""),dados!$W$2:$W$55)),"")} | O13: =SUMIF(dados!$C$2:$C$55,$A13,dados!$AO$2:$AO$55) | P13: {=IFERROR(MEDIAN(IF((dados!$C$2:$C$55=$A13)*(dados!$AD$2:$AD$55<>""),dados!$AD$2:$AD$55)),"")} | Q13: =IF(COUNTIFS(dados!$C$2:$C$55,$A13,dados!$AD$2:$AD$55,"<>")=0,"",_xlfn.MINIFS(dados!$AD$2:$AD$55,dados!$C$2:$C$55,$A13)) | R13: =IF(COUNTIFS(dados!$C$2:$C$55,$A13,dados!$AD$2:$AD$55,"<>")=0,"",_xlfn.MAXIFS(dados!$AD$2:$AD$55,dados!$C$2:$C$55,$A13)) | S13: =SUMIF(dados!$C$2:$C$55,$A13,dados!$AL$2:$AL$55)
A14: Vitória | B14: Sudeste | C14: =COUNTIF(dados!$C$2:$C$55,A14) | D14: =C14/COUNTA(dados!$A$2:$A$55) | E14: {=IFERROR(MEDIAN(IF((dados!$C$2:$C$55=$A14)*(dados!$E$2:$E$55<>""),dados!$E$2:$E$55)),"")} | F14: {=IFERROR(MEDIAN(IF((dados!$C$2:$C$55=$A14)*(dados!$F$2:$F$55<>""),dados!$F$2:$F$55)),"")} | G14: =IFERROR(AVERAGEIFS(dados!$H$2:$H$55,dados!$C$2:$C$55,$A14),"") | H14: {=IFERROR(MEDIAN(IF((dados!$C$2:$C$55=$A14)*(dados!$J$2:$J$55<>""),dados!$J$2:$J$55)),"")} | I14: =IFERROR(AVERAGEIFS(dados!$AW$2:$AW$55,dados!$C$2:$C$55,$A14),"") | J14: =IFERROR(AVERAGEIFS(dados!$AQ$2:$AQ$55,dados!$C$2:$C$55,$A14),"") | K14: =IFERROR(AVERAGEIFS(dados!$AN$2:$AN$55,dados!$C$2:$C$55,$A14),"") | L14: {=IFERROR(MEDIAN(IF((dados!$C$2:$C$55=$A14)*(dados!$Q$2:$Q$55<>""),dados!$Q$2:$Q$55)),"")} | M14: =IFERROR(AVERAGEIFS(dados!$T$2:$T$55,dados!$C$2:$C$55,$A14),"") | N14: {=IFERROR(MEDIAN(IF((dados!$C$2:$C$55=$A14)*(dados!$W$2:$W$55<>""),dados!$W$2:$W$55)),"")} | O14: =SUMIF(dados!$C$2:$C$55,$A14,dados!$AO$2:$AO$55) | P14: {=IFERROR(MEDIAN(IF((dados!$C$2:$C$55=$A14)*(dados!$AD$2:$AD$55<>""),dados!$AD$2:$AD$55)),"")} | Q14: =IF(COUNTIFS(dados!$C$2:$C$55,$A14,dados!$AD$2:$AD$55,"<>")=0,"",_xlfn.MINIFS(dados!$AD$2:$AD$55,dados!$C$2:$C$55,$A14)) | R14: =IF(COUNTIFS(dados!$C$2:$C$55,$A14,dados!$AD$2:$AD$55,"<>")=0,"",_xlfn.MAXIFS(dados!$AD$2:$AD$55,dados!$C$2:$C$55,$A14)) | S14: =SUMIF(dados!$C$2:$C$55,$A14,dados!$AL$2:$AL$55)
A15: Total | C15: =SUM(C2:C14) | D15: =SUM(D2:D14)
A16: Conferência (total − casas da aba dados; deve ser 0) | C16: =C15-COUNTA(dados!$A$2:$A$55)

Sheet regiao_detalhe
A1: região | B1: grupo | C1: variável | D1: descrição | E1: n | F1: média | G1: mediana | H1: desvio padrão | I1: mínimo | J1: máximo | K1: amplitude
A2: Norte | B2: Google Maps | C2: avaliacao_media | D2: Nota média no Google | E2: =COUNTIFS(dados!$D$2:$D$55,$A2,dados!$E$2:$E$55,"<>") | F2: =IFERROR(AVERAGEIFS(dados!$E$2:$E$55,dados!$D$2:$D$55,$A2),"") | G2: {=IFERROR(MEDIAN(IF((dados!$D$2:$D$55=$A2)*(dados!$E$2:$E$55<>""),dados!$E$2:$E$55)),"")} | H2: {=IFERROR(STDEV(IF((dados!$D$2:$D$55=$A2)*(dados!$E$2:$E$55<>""),dados!$E$2:$E$55)),"")} | I2: =IF(COUNTIFS(dados!$D$2:$D$55,$A2,dados!$E$2:$E$55,"<>")=0,"",_xlfn.MINIFS(dados!$E$2:$E$55,dados!$D$2:$D$55,$A2)) | J2: =IF(COUNTIFS(dados!$D$2:$D$55,$A2,dados!$E$2:$E$55,"<>")=0,"",_xlfn.MAXIFS(dados!$E$2:$E$55,dados!$D$2:$D$55,$A2)) | K2: =IFERROR(J2-I2,"")
A3: Norte | B3: Google Maps | C3: volume_avaliacoes | D3: Nº de avaliações no Google | E3: =COUNTIFS(dados!$D$2:$D$55,$A3,dados!$F$2:$F$55,"<>") | F3: =IFERROR(AVERAGEIFS(dados!$F$2:$F$55,dados!$D$2:$D$55,$A3),"") | G3: {=IFERROR(MEDIAN(IF((dados!$D$2:$D$55=$A3)*(dados!$F$2:$F$55<>""),dados!$F$2:$F$55)),"")} | H3: {=IFERROR(STDEV(IF((dados!$D$2:$D$55=$A3)*(dados!$F$2:$F$55<>""),dados!$F$2:$F$55)),"")} | I3: =IF(COUNTIFS(dados!$D$2:$D$55,$A3,dados!$F$2:$F$55,"<>")=0,"",_xlfn.MINIFS(dados!$F$2:$F$55,dados!$D$2:$D$55,$A3)) | J3: =IF(COUNTIFS(dados!$D$2:$D$55,$A3,dados!$F$2:$F$55,"<>")=0,"",_xlfn.MAXIFS(dados!$F$2:$F$55,dados!$D$2:$D$55,$A3)) | K3: =IFERROR(J3-I3,"")
A4: Norte | B4: Horários | C4: dias_abertos | D4: Dias abertos por semana | E4: =COUNTIFS(dados!$D$2:$D$55,$A4,dados!$G$2:$G$55,"<>") | F4: =IFERROR(AVERAGEIFS(dados!$G$2:$G$55,dados!$D$2:$D$55,$A4),"") | G4: {=IFERROR(MEDIAN(IF((dados!$D$2:$D$55=$A4)*(dados!$G$2:$G$55<>""),dados!$G$2:$G$55)),"")} | H4: {=IFERROR(STDEV(IF((dados!$D$2:$D$55=$A4)*(dados!$G$2:$G$55<>""),dados!$G$2:$G$55)),"")} | I4: =IF(COUNTIFS(dados!$D$2:$D$55,$A4,dados!$G$2:$G$55,"<>")=0,"",_xlfn.MINIFS(dados!$G$2:$G$55,dados!$D$2:$D$55,$A4)) | J4: =IF(COUNTIFS(dados!$D$2:$D$55,$A4,dados!$G$2:$G$55,"<>")=0,"",_xlfn.MAXIFS(dados!$G$2:$G$55,dados!$D$2:$D$55,$A4)) | K4: =IFERROR(J4-I4,"")
A5: Norte | B5: Horários | C5: horas_semana | D5: Horas abertas por semana | E5: =COUNTIFS(dados!$D$2:$D$55,$A5,dados!$H$2:$H$55,"<>") | F5: =IFERROR(AVERAGEIFS(dados!$H$2:$H$55,dados!$D$2:$D$55,$A5),"") | G5: {=IFERROR(MEDIAN(IF((dados!$D$2:$D$55=$A5)*(dados!$H$2:$H$55<>""),dados!$H$2:$H$55)),"")} | H5: {=IFERROR(STDEV(IF((dados!$D$2:$D$55=$A5)*(dados!$H$2:$H$55<>""),dados!$H$2:$H$55)),"")} | I5: =IF(COUNTIFS(dados!$D$2:$D$55,$A5,dados!$H$2:$H$55,"<>")=0,"",_xlfn.MINIFS(dados!$H$2:$H$55,dados!$D$2:$D$55,$A5)) | J5: =IF(COUNTIFS(dados!$D$2:$D$55,$A5,dados!$H$2:$H$55,"<>")=0,"",_xlfn.MAXIFS(dados!$H$2:$H$55,dados!$D$2:$D$55,$A5)) | K5: =IFERROR(J5-I5,"")
A6: Norte | B6: Horários | C6: abre_cedo_h | D6: Abertura mais cedo da semana | E6: =COUNTIFS(dados!$D$2:$D$55,$A6,dados!$I$2:$I$55,"<>") | F6: =IFERROR(AVERAGEIFS(dados!$I$2:$I$55,dados!$D$2:$D$55,$A6),"") | G6: {=IFERROR(MEDIAN(IF((dados!$D$2:$D$55=$A6)*(dados!$I$2:$I$55<>""),dados!$I$2:$I$55)),"")} | H6: {=IFERROR(STDEV(IF((dados!$D$2:$D$55=$A6)*(dados!$I$2:$I$55<>""),dados!$I$2:$I$55)),"")} | I6: =IF(COUNTIFS(dados!$D$2:$D$55,$A6,dados!$I$2:$I$55,"<>")=0,"",_xlfn.MINIFS(dados!$I$2:$I$55,dados!$D$2:$D$55,$A6)) | J6: =IF(COUNTIFS(dados!$D$2:$D$55,$A6,dados!$I$2:$I$55,"<>")=0,"",_xlfn.MAXIFS(dados!$I$2:$I$55,dados!$D$2:$D$55,$A6)) | K6: =IFERROR(J6-I6,"")
A7: Norte | B7: Horários | C7: fecha_tarde_h | D7: Fechamento mais tarde da semana (25 = 1h da manhã) | E7: =COUNTIFS(dados!$D$2:$D$55,$A7,dados!$J$2:$J$55,"<>") | F7: =IFERROR(AVERAGEIFS(dados!$J$2:$J$55,dados!$D$2:$D$55,$A7),"") | G7: {=IFERROR(MEDIAN(IF((dados!$D$2:$D$55=$A7)*(dados!$J$2:$J$55<>""),dados!$J$2:$J$55)),"")} | H7: {=IFERROR(STDEV(IF((dados!$D$2:$D$55=$A7)*(dados!$J$2:$J$55<>""),dados!$J$2:$J$55)),"")} | I7: =IF(COUNTIFS(dados!$D$2:$D$55,$A7,dados!$J$2:$J$55,"<>")=0,"",_xlfn.MINIFS(dados!$J$2:$J$55,dados!$D$2:$D$55,$A7)) | J7: =IF(COUNTIFS(dados!$D$2:$D$55,$A7,dados!$J$2:$J$55,"<>")=0,"",_xlfn.MAXIFS(dados!$J$2:$J$55,dados!$D$2:$D$55,$A7)) | K7: =IFERROR(J7-I7,"")
A8: Norte | B8: Entorno | C8: metro_500m | D8: Estações de metrô até 500 m | E8: =COUNTIFS(dados!$D$2:$D$55,$A8,dados!$K$2:$K$55,"<>") | F8: =IFERROR(AVERAGEIFS(dados!$K$2:$K$55,dados!$D$2:$D$55,$A8),"") | G8: {=IFERROR(MEDIAN(IF((dados!$D$2:$D$55=$A8)*(dados!$K$2:$K$55<>""),dados!$K$2:$K$55)),"")} | H8: {=IFERROR(STDEV(IF((dados!$D$2:$D$55=$A8)*(dados!$K$2:$K$55<>""),dados!$K$2:$K$55)),"")} | I8: =IF(COUNTIFS(dados!$D$2:$D$55,$A8,dados!$K$2:$K$55,"<>")=0,"",_xlfn.MINIFS(dados!$K$2:$K$55,dados!$D$2:$D$55,$A8)) | J8: =IF(COUNTIFS(dados!$D$2:$D$55,$A8,dados!$K$2:$K$55,"<>")=0,"",_xlfn.MAXIFS(dados!$K$2:$K$55,dados!$D$2:$D$55,$A8)) | K8: =IFERROR(J8-I8,"")
A9: Norte | B9: Entorno | C9: metro_1000m | D9: Estações de metrô até 1000 m | E9: =COUNTIFS(dados!$D$2:$D$55,$A9,dados!$L$2:$L$55,"<>") | F9: =IFERROR(AVERAGEIFS(dados!$L$2:$L$55,dados!$D$2:$D$55,$A9),"") | G9: {=IFERROR(MEDIAN(IF((dados!$D$2:$D$55=$A9)*(dados!$L$2:$L$55<>""),dados!$L$2:$L$55)),"")} | H9: {=IFERROR(STDEV(IF((dados!$D$2:$D$55=$A9)*(dados!$L$2:$L$55<>""),dados!$L$2:$L$55)),"")} | I9: =IF(COUNTIFS(dados!$D$2:$D$55,$A9,dados!$L$2:$L$55,"<>")=0,"",_xlfn.MINIFS(dados!$L$2:$L$55,dados!$D$2:$D$55,$A9)) | J9: =IF(COUNTIFS(dados!$D$2:$D$55,$A9,dados!$L$2:$L$55,"<>")=0,"",_xlfn.MAXIFS(dados!$L$2:$L$55,dados!$D$2:$D$55,$A9)) | K9: =IFERROR(J9-I9,"")
A10: Norte | B10: Entorno | C10: dist_metro_m | D10: Distância à estação de metrô mais próxima | E10: =COUNTIFS(dados!$D$2:$D$55,$A10,dados!$M$2:$M$55,"<>") | F10: =IFERROR(AVERAGEIFS(dados!$M$2:$M$55,dados!$D$2:$D$55,$A10),"") | G10: {=IFERROR(MEDIAN(IF((dados!$D$2:$D$55=$A10)*(dados!$M$2:$M$55<>""),dados!$M$2:$M$55)),"")} | H10: {=IFERROR(STDEV(IF((dados!$D$2:$D$55=$A10)*(dados!$M$2:$M$55<>""),dados!$M$2:$M$55)),"")} | I10: =IF(COUNTIFS(dados!$D$2:$D$55,$A10,dados!$M$2:$M$55,"<>")=0,"",_xlfn.MINIFS(dados!$M$2:$M$55,dados!$D$2:$D$55,$A10)) | J10: =IF(COUNTIFS(dados!$D$2:$D$55,$A10,dados!$M$2:$M$55,"<>")=0,"",_xlfn.MAXIFS(dados!$M$2:$M$55,dados!$D$2:$D$55,$A10)) | K10: =IFERROR(J10-I10,"")
A11: Norte | B11: Entorno | C11: shopping_porte_500m | D11: Shoppings de porte até 500 m (onde o porte foi buscado) | E11: =COUNTIFS(dados!$D$2:$D$55,$A11,dados!$N$2:$N$55,"<>") | F11: =IFERROR(AVERAGEIFS(dados!$N$2:$N$55,dados!$D$2:$D$55,$A11),"") | G11: {=IFERROR(MEDIAN(IF((dados!$D$2:$D$55=$A11)*(dados!$N$2:$N$55<>""),dados!$N$2:$N$55)),"")} | H11: {=IFERROR(STDEV(IF((dados!$D$2:$D$55=$A11)*(dados!$N$2:$N$55<>""),dados!$N$2:$N$55)),"")} | I11: =IF(COUNTIFS(dados!$D$2:$D$55,$A11,dados!$N$2:$N$55,"<>")=0,"",_xlfn.MINIFS(dados!$N$2:$N$55,dados!$D$2:$D$55,$A11)) | J11: =IF(COUNTIFS(dados!$D$2:$D$55,$A11,dados!$N$2:$N$55,"<>")=0,"",_xlfn.MAXIFS(dados!$N$2:$N$55,dados!$D$2:$D$55,$A11)) | K11: =IFERROR(J11-I11,"")
A12: Norte | B12: Entorno | C12: shopping_porte_1000m | D12: Shoppings de porte até 1000 m (onde o porte foi buscado) | E12: =COUNTIFS(dados!$D$2:$D$55,$A12,dados!$O$2:$O$55,"<>") | F12: =IFERROR(AVERAGEIFS(dados!$O$2:$O$55,dados!$D$2:$D$55,$A12),"") | G12: {=IFERROR(MEDIAN(IF((dados!$D$2:$D$55=$A12)*(dados!$O$2:$O$55<>""),dados!$O$2:$O$55)),"")} | H12: {=IFERROR(STDEV(IF((dados!$D$2:$D$55=$A12)*(dados!$O$2:$O$55<>""),dados!$O$2:$O$55)),"")} | I12: =IF(COUNTIFS(dados!$D$2:$D$55,$A12,dados!$O$2:$O$55,"<>")=0,"",_xlfn.MINIFS(dados!$O$2:$O$55,dados!$D$2:$D$55,$A12)) | J12: =IF(COUNTIFS(dados!$D$2:$D$55,$A12,dados!$O$2:$O$55,"<>")=0,"",_xlfn.MAXIFS(dados!$O$2:$O$55,dados!$D$2:$D$55,$A12)) | K12: =IFERROR(J12-I12,"")
A13: Norte | B13: Entorno | C13: dist_shopping_m | D13: Distância ao shopping mais próximo (qualquer porte) | E13: =COUNTIFS(dados!$D$2:$D$55,$A13,dados!$P$2:$P$55,"<>") | F13: =IFERROR(AVERAGEIFS(dados!$P$2:$P$55,dados!$D$2:$D$55,$A13),"") | G13: {=IFERROR(MEDIAN(IF((dados!$D$2:$D$55=$A13)*(dados!$P$2:$P$55<>""),dados!$P$2:$P$55)),"")} | H13: {=IFERROR(STDEV(IF((dados!$D$2:$D$55=$A13)*(dados!$P$2:$P$55<>""),dados!$P$2:$P$55)),"")} | I13: =IF(COUNTIFS(dados!$D$2:$D$55,$A13,dados!$P$2:$P$55,"<>")=0,"",_xlfn.MINIFS(dados!$P$2:$P$55,dados!$D$2:$D$55,$A13)) | J13: =IF(COUNTIFS(dados!$D$2:$D$55,$A13,dados!$P$2:$P$55,"<>")=0,"",_xlfn.MAXIFS(dados!$P$2:$P$55,dados!$D$2:$D$55,$A13)) | K13: =IFERROR(J13-I13,"")
A14: Norte | B14: Instagram | C14: seguidores | D14: Seguidores | E14: =COUNTIFS(dados!$D$2:$D$55,$A14,dados!$Q$2:$Q$55,"<>") | F14: =IFERROR(AVERAGEIFS(dados!$Q$2:$Q$55,dados!$D$2:$D$55,$A14),"") | G14: {=IFERROR(MEDIAN(IF((dados!$D$2:$D$55=$A14)*(dados!$Q$2:$Q$55<>""),dados!$Q$2:$Q$55)),"")} | H14: {=IFERROR(STDEV(IF((dados!$D$2:$D$55=$A14)*(dados!$Q$2:$Q$55<>""),dados!$Q$2:$Q$55)),"")} | I14: =IF(COUNTIFS(dados!$D$2:$D$55,$A14,dados!$Q$2:$Q$55,"<>")=0,"",_xlfn.MINIFS(dados!$Q$2:$Q$55,dados!$D$2:$D$55,$A14)) | J14: =IF(COUNTIFS(dados!$D$2:$D$55,$A14,dados!$Q$2:$Q$55,"<>")=0,"",_xlfn.MAXIFS(dados!$Q$2:$Q$55,dados!$D$2:$D$55,$A14)) | K14: =IFERROR(J14-I14,"")
A15: Norte | B15: Instagram | C15: n_posts_total | D15: Posts desde a criação do perfil | E15: =COUNTIFS(dados!$D$2:$D$55,$A15,dados!$R$2:$R$55,"<>") | F15: =IFERROR(AVERAGEIFS(dados!$R$2:$R$55,dados!$D$2:$D$55,$A15),"") | G15: {=IFERROR(MEDIAN(IF((dados!$D$2:$D$55=$A15)*(dados!$R$2:$R$55<>""),dados!$R$2:$R$55)),"")} | H15: {=IFERROR(STDEV(IF((dados!$D$2:$D$55=$A15)*(dados!$R$2:$R$55<>""),dados!$R$2:$R$55)),"")} | I15: =IF(COUNTIFS(dados!$D$2:$D$55,$A15,dados!$R$2:$R$55,"<>")=0,"",_xlfn.MINIFS(dados!$R$2:$R$55,dados!$D$2:$D$55,$A15)) | J15: =IF(COUNTIFS(dados!$D$2:$D$55,$A15,dados!$R$2:$R$55,"<>")=0,"",_xlfn.MAXIFS(dados!$R$2:$R$55,dados!$D$2:$D$55,$A15)) | K15: =IFERROR(J15-I15,"")
A16: Norte | B16: Instagram | C16: idade_perfil_anos | D16: Idade do perfil (desde o primeiro post até 15/10/2026) | E16: =COUNTIFS(dados!$D$2:$D$55,$A16,dados!$S$2:$S$55,"<>") | F16: =IFERROR(AVERAGEIFS(dados!$S$2:$S$55,dados!$D$2:$D$55,$A16),"") | G16: {=IFERROR(MEDIAN(IF((dados!$D$2:$D$55=$A16)*(dados!$S$2:$S$55<>""),dados!$S$2:$S$55)),"")} | H16: {=IFERROR(STDEV(IF((dados!$D$2:$D$55=$A16)*(dados!$S$2:$S$55<>""),dados!$S$2:$S$55)),"")} | I16: =IF(COUNTIFS(dados!$D$2:$D$55,$A16,dados!$S$2:$S$55,"<>")=0,"",_xlfn.MINIFS(dados!$S$2:$S$55,dados!$D$2:$D$55,$A16)) | J16: =IF(COUNTIFS(dados!$D$2:$D$55,$A16,dados!$S$2:$S$55,"<>")=0,"",_xlfn.MAXIFS(dados!$S$2:$S$55,dados!$D$2:$D$55,$A16)) | K16: =IFERROR(J16-I16,"")
A17: Norte | B17: Instagram | C17: n_posts_periodo | D17: Posts de 01/09 a 01/10/2026 | E17: =COUNTIFS(dados!$D$2:$D$55,$A17,dados!$T$2:$T$55,"<>") | F17: =IFERROR(AVERAGEIFS(dados!$T$2:$T$55,dados!$D$2:$D$55,$A17),"") | G17: {=IFERROR(MEDIAN(IF((dados!$D$2:$D$55=$A17)*(dados!$T$2:$T$55<>""),dados!$T$2:$T$55)),"")} | H17: {=IFERROR(STDEV(IF((dados!$D$2:$D$55=$A17)*(dados!$T$2:$T$55<>""),dados!$T$2:$T$55)),"")} | I17: =IF(COUNTIFS(dados!$D$2:$D$55,$A17,dados!$T$2:$T$55,"<>")=0,"",_xlfn.MINIFS(dados!$T$2:$T$55,dados!$D$2:$D$55,$A17)) | J17: =IF(COUNTIFS(dados!$D$2:$D$55,$A17,dados!$T$2:$T$55,"<>")=0,"",_xlfn.MAXIFS(dados!$T$2:$T$55,dados!$D$2:$D$55,$A17)) | K17: =IFERROR(J17-I17,"")
A18: Norte | B18: Instagram | C18: curtidas_periodo | D18: Curtidas no período | E18: =COUNTIFS(dados!$D$2:$D$55,$A18,dados!$U$2:$U$55,"<>") | F18: =IFERROR(AVERAGEIFS(dados!$U$2:$U$55,dados!$D$2:$D$55,$A18),"") | G18: {=IFERROR(MEDIAN(IF((dados!$D$2:$D$55=$A18)*(dados!$U$2:$U$55<>""),dados!$U$2:$U$55)),"")} | H18: {=IFERROR(STDEV(IF((dados!$D$2:$D$55=$A18)*(dados!$U$2:$U$55<>""),dados!$U$2:$U$55)),"")} | I18: =IF(COUNTIFS(dados!$D$2:$D$55,$A18,dados!$U$2:$U$55,"<>")=0,"",_xlfn.MINIFS(dados!$U$2:$U$55,dados!$D$2:$D$55,$A18)) | J18: =IF(COUNTIFS(dados!$D$2:$D$55,$A18,dados!$U$2:$U$55,"<>")=0,"",_xlfn.MAXIFS(dados!$U$2:$U$55,dados!$D$2:$D$55,$A18)) | K18: =IFERROR(J18-I18,"")
A19: Norte | B19: Instagram | C19: comentarios_periodo | D19: Comentários no período | E19: =COUNTIFS(dados!$D$2:$D$55,$A19,dados!$V$2:$V$55,"<>") | F19: =IFERROR(AVERAGEIFS(dados!$V$2:$V$55,dados!$D$2:$D$55,$A19),"") | G19: {=IFERROR(MEDIAN(IF((dados!$D$2:$D$55=$A19)*(dados!$V$2:$V$55<>""),dados!$V$2:$V$55)),"")} | H19: {=IFERROR(STDEV(IF((dados!$D$2:$D$55=$A19)*(dados!$V$2:$V$55<>""),dados!$V$2:$V$55)),"")} | I19: =IF(COUNTIFS(dados!$D$2:$D$55,$A19,dados!$V$2:$V$55,"<>")=0,"",_xlfn.MINIFS(dados!$V$2:$V$55,dados!$D$2:$D$55,$A19)) | J19: =IF(COUNTIFS(dados!$D$2:$D$55,$A19,dados!$V$2:$V$55,"<>")=0,"",_xlfn.MAXIFS(dados!$V$2:$V$55,dados!$D$2:$D$55,$A19)) | K19: =IFERROR(J19-I19,"")
A20: Norte | B20: Instagram | C20: interacoes_por_post | D20: Interações por post no período (curtidas + comentários) | E20: =COUNTIFS(dados!$D$2:$D$55,$A20,dados!$W$2:$W$55,"<>") | F20: =IFERROR(AVERAGEIFS(dados!$W$2:$W$55,dados!$D$2:$D$55,$A20),"") | G20: {=IFERROR(MEDIAN(IF((dados!$D$2:$D$55=$A20)*(dados!$W$2:$W$55<>""),dados!$W$2:$W$55)),"")} | H20: {=IFERROR(STDEV(IF((dados!$D$2:$D$55=$A20)*(dados!$W$2:$W$55<>""),dados!$W$2:$W$55)),"")} | I20: =IF(COUNTIFS(dados!$D$2:$D$55,$A20,dados!$W$2:$W$55,"<>")=0,"",_xlfn.MINIFS(dados!$W$2:$W$55,dados!$D$2:$D$55,$A20)) | J20: =IF(COUNTIFS(dados!$D$2:$D$55,$A20,dados!$W$2:$W$55,"<>")=0,"",_xlfn.MAXIFS(dados!$W$2:$W$55,dados!$D$2:$D$55,$A20)) | K20: =IFERROR(J20-I20,"")
A21: Norte | B21: Instagram | C21: engajamento_pct | D21: Taxa de engajamento (interações por post ÷ seguidores) | E21: =COUNTIFS(dados!$D$2:$D$55,$A21,dados!$X$2:$X$55,"<>") | F21: =IFERROR(AVERAGEIFS(dados!$X$2:$X$55,dados!$D$2:$D$55,$A21),"") | G21: {=IFERROR(MEDIAN(IF((dados!$D$2:$D$55=$A21)*(dados!$X$2:$X$55<>""),dados!$X$2:$X$55)),"")} | H21: {=IFERROR(STDEV(IF((dados!$D$2:$D$55=$A21)*(dados!$X$2:$X$55<>""),dados!$X$2:$X$55)),"")} | I21: =IF(COUNTIFS(dados!$D$2:$D$55,$A21,dados!$X$2:$X$55,"<>")=0,"",_xlfn.MINIFS(dados!$X$2:$X$55,dados!$D$2:$D$55,$A21)) | J21: =IF(COUNTIFS(dados!$D$2:$D$55,$A21,dados!$X$2:$X$55,"<>")=0,"",_xlfn.MAXIFS(dados!$X$2:$X$55,dados!$D$2:$D$55,$A21)) | K21: =IFERROR(J21-I21,"")
A22: Norte | B22: Cardápio | C22: itens_com_preco | D22: Itens com preço no cardápio | E22: =COUNTIFS(dados!$D$2:$D$55,$A22,dados!$Y$2:$Y$55,"<>") | F22: =IFERROR(AVERAGEIFS(dados!$Y$2:$Y$55,dados!$D$2:$D$55,$A22),"") | G22: {=IFERROR(MEDIAN(IF((dados!$D$2:$D$55=$A22)*(dados!$Y$2:$Y$55<>""),dados!$Y$2:$Y$55)),"")} | H22: {=IFERROR(STDEV(IF((dados!$D$2:$D$55=$A22)*(dados!$Y$2:$Y$55<>""),dados!$Y$2:$Y$55)),"")} | I22: =IF(COUNTIFS(dados!$D$2:$D$55,$A22,dados!$Y$2:$Y$55,"<>")=0,"",_xlfn.MINIFS(dados!$Y$2:$Y$55,dados!$D$2:$D$55,$A22)) | J22: =IF(COUNTIFS(dados!$D$2:$D$55,$A22,dados!$Y$2:$Y$55,"<>")=0,"",_xlfn.MAXIFS(dados!$Y$2:$Y$55,dados!$D$2:$D$55,$A22)) | K22: =IFERROR(J22-I22,"")
A23: Norte | B23: Cardápio | C23: couvert_mediana | D23: Couvert ou taxa de jogo (só casas que cobram) | E23: =COUNTIFS(dados!$D$2:$D$55,$A23,dados!$Z$2:$Z$55,"<>") | F23: =IFERROR(AVERAGEIFS(dados!$Z$2:$Z$55,dados!$D$2:$D$55,$A23),"") | G23: {=IFERROR(MEDIAN(IF((dados!$D$2:$D$55=$A23)*(dados!$Z$2:$Z$55<>""),dados!$Z$2:$Z$55)),"")} | H23: {=IFERROR(STDEV(IF((dados!$D$2:$D$55=$A23)*(dados!$Z$2:$Z$55<>""),dados!$Z$2:$Z$55)),"")} | I23: =IF(COUNTIFS(dados!$D$2:$D$55,$A23,dados!$Z$2:$Z$55,"<>")=0,"",_xlfn.MINIFS(dados!$Z$2:$Z$55,dados!$D$2:$D$55,$A23)) | J23: =IF(COUNTIFS(dados!$D$2:$D$55,$A23,dados!$Z$2:$Z$55,"<>")=0,"",_xlfn.MAXIFS(dados!$Z$2:$Z$55,dados!$D$2:$D$55,$A23)) | K23: =IFERROR(J23-I23,"")
A24: Norte | B24: Cardápio | C24: bebida_mediana | D24: Bebida, mediana do cardápio | E24: =COUNTIFS(dados!$D$2:$D$55,$A24,dados!$AA$2:$AA$55,"<>") | F24: =IFERROR(AVERAGEIFS(dados!$AA$2:$AA$55,dados!$D$2:$D$55,$A24),"") | G24: {=IFERROR(MEDIAN(IF((dados!$D$2:$D$55=$A24)*(dados!$AA$2:$AA$55<>""),dados!$AA$2:$AA$55)),"")} | H24: {=IFERROR(STDEV(IF((dados!$D$2:$D$55=$A24)*(dados!$AA$2:$AA$55<>""),dados!$AA$2:$AA$55)),"")} | I24: =IF(COUNTIFS(dados!$D$2:$D$55,$A24,dados!$AA$2:$AA$55,"<>")=0,"",_xlfn.MINIFS(dados!$AA$2:$AA$55,dados!$D$2:$D$55,$A24)) | J24: =IF(COUNTIFS(dados!$D$2:$D$55,$A24,dados!$AA$2:$AA$55,"<>")=0,"",_xlfn.MAXIFS(dados!$AA$2:$AA$55,dados!$D$2:$D$55,$A24)) | K24: =IFERROR(J24-I24,"")
A25: Norte | B25: Cardápio | C25: entrada_ou_prato_mediana | D25: Entrada ou prato, mediana do cardápio | E25: =COUNTIFS(dados!$D$2:$D$55,$A25,dados!$AB$2:$AB$55,"<>") | F25: =IFERROR(AVERAGEIFS(dados!$AB$2:$AB$55,dados!$D$2:$D$55,$A25),"") | G25: {=IFERROR(MEDIAN(IF((dados!$D$2:$D$55=$A25)*(dados!$AB$2:$AB$55<>""),dados!$AB$2:$AB$55)),"")} | H25: {=IFERROR(STDEV(IF((dados!$D$2:$D$55=$A25)*(dados!$AB$2:$AB$55<>""),dados!$AB$2:$AB$55)),"")} | I25: =IF(COUNTIFS(dados!$D$2:$D$55,$A25,dados!$AB$2:$AB$55,"<>")=0,"",_xlfn.MINIFS(dados!$AB$2:$AB$55,dados!$D$2:$D$55,$A25)) | J25: =IF(COUNTIFS(dados!$D$2:$D$55,$A25,dados!$AB$2:$AB$55,"<>")=0,"",_xlfn.MAXIFS(dados!$AB$2:$AB$55,dados!$D$2:$D$55,$A25)) | K25: =IFERROR(J25-I25,"")
A26: Norte | B26: Cardápio | C26: cesta_baixa | D26: Cesta por pessoa, nível baixo (P25) | E26: =COUNTIFS(dados!$D$2:$D$55,$A26,dados!$AC$2:$AC$55,"<>") | F26: =IFERROR(AVERAGEIFS(dados!$AC$2:$AC$55,dados!$D$2:$D$55,$A26),"") | G26: {=IFERROR(MEDIAN(IF((dados!$D$2:$D$55=$A26)*(dados!$AC$2:$AC$55<>""),dados!$AC$2:$AC$55)),"")} | H26: {=IFERROR(STDEV(IF((dados!$D$2:$D$55=$A26)*(dados!$AC$2:$AC$55<>""),dados!$AC$2:$AC$55)),"")} | I26: =IF(COUNTIFS(dados!$D$2:$D$55,$A26,dados!$AC$2:$AC$55,"<>")=0,"",_xlfn.MINIFS(dados!$AC$2:$AC$55,dados!$D$2:$D$55,$A26)) | J26: =IF(COUNTIFS(dados!$D$2:$D$55,$A26,dados!$AC$2:$AC$55,"<>")=0,"",_xlfn.MAXIFS(dados!$AC$2:$AC$55,dados!$D$2:$D$55,$A26)) | K26: =IFERROR(J26-I26,"")
A27: Norte | B27: Cardápio | C27: cesta_mediana | D27: Cesta por pessoa, nível mediano | E27: =COUNTIFS(dados!$D$2:$D$55,$A27,dados!$AD$2:$AD$55,"<>") | F27: =IFERROR(AVERAGEIFS(dados!$AD$2:$AD$55,dados!$D$2:$D$55,$A27),"") | G27: {=IFERROR(MEDIAN(IF((dados!$D$2:$D$55=$A27)*(dados!$AD$2:$AD$55<>""),dados!$AD$2:$AD$55)),"")} | H27: {=IFERROR(STDEV(IF((dados!$D$2:$D$55=$A27)*(dados!$AD$2:$AD$55<>""),dados!$AD$2:$AD$55)),"")} | I27: =IF(COUNTIFS(dados!$D$2:$D$55,$A27,dados!$AD$2:$AD$55,"<>")=0,"",_xlfn.MINIFS(dados!$AD$2:$AD$55,dados!$D$2:$D$55,$A27)) | J27: =IF(COUNTIFS(dados!$D$2:$D$55,$A27,dados!$AD$2:$AD$55,"<>")=0,"",_xlfn.MAXIFS(dados!$AD$2:$AD$55,dados!$D$2:$D$55,$A27)) | K27: =IFERROR(J27-I27,"")
A28: Norte | B28: Cardápio | C28: cesta_alta | D28: Cesta por pessoa, nível alto (P75) | E28: =COUNTIFS(dados!$D$2:$D$55,$A28,dados!$AE$2:$AE$55,"<>") | F28: =IFERROR(AVERAGEIFS(dados!$AE$2:$AE$55,dados!$D$2:$D$55,$A28),"") | G28: {=IFERROR(MEDIAN(IF((dados!$D$2:$D$55=$A28)*(dados!$AE$2:$AE$55<>""),dados!$AE$2:$AE$55)),"")} | H28: {=IFERROR(STDEV(IF((dados!$D$2:$D$55=$A28)*(dados!$AE$2:$AE$55<>""),dados!$AE$2:$AE$55)),"")} | I28: =IF(COUNTIFS(dados!$D$2:$D$55,$A28,dados!$AE$2:$AE$55,"<>")=0,"",_xlfn.MINIFS(dados!$AE$2:$AE$55,dados!$D$2:$D$55,$A28)) | J28: =IF(COUNTIFS(dados!$D$2:$D$55,$A28,dados!$AE$2:$AE$55,"<>")=0,"",_xlfn.MAXIFS(dados!$AE$2:$AE$55,dados!$D$2:$D$55,$A28)) | K28: =IFERROR(J28-I28,"")
A29: Norte | B29: Cardápio | C29: hamburguer_mediana | D29: Hambúrguer, mediana | E29: =COUNTIFS(dados!$D$2:$D$55,$A29,dados!$AF$2:$AF$55,"<>") | F29: =IFERROR(AVERAGEIFS(dados!$AF$2:$AF$55,dados!$D$2:$D$55,$A29),"") | G29: {=IFERROR(MEDIAN(IF((dados!$D$2:$D$55=$A29)*(dados!$AF$2:$AF$55<>""),dados!$AF$2:$AF$55)),"")} | H29: {=IFERROR(STDEV(IF((dados!$D$2:$D$55=$A29)*(dados!$AF$2:$AF$55<>""),dados!$AF$2:$AF$55)),"")} | I29: =IF(COUNTIFS(dados!$D$2:$D$55,$A29,dados!$AF$2:$AF$55,"<>")=0,"",_xlfn.MINIFS(dados!$AF$2:$AF$55,dados!$D$2:$D$55,$A29)) | J29: =IF(COUNTIFS(dados!$D$2:$D$55,$A29,dados!$AF$2:$AF$55,"<>")=0,"",_xlfn.MAXIFS(dados!$AF$2:$AF$55,dados!$D$2:$D$55,$A29)) | K29: =IFERROR(J29-I29,"")
A30: Norte | B30: Cardápio | C30: batata_mediana | D30: Batata, mediana | E30: =COUNTIFS(dados!$D$2:$D$55,$A30,dados!$AG$2:$AG$55,"<>") | F30: =IFERROR(AVERAGEIFS(dados!$AG$2:$AG$55,dados!$D$2:$D$55,$A30),"") | G30: {=IFERROR(MEDIAN(IF((dados!$D$2:$D$55=$A30)*(dados!$AG$2:$AG$55<>""),dados!$AG$2:$AG$55)),"")} | H30: {=IFERROR(STDEV(IF((dados!$D$2:$D$55=$A30)*(dados!$AG$2:$AG$55<>""),dados!$AG$2:$AG$55)),"")} | I30: =IF(COUNTIFS(dados!$D$2:$D$55,$A30,dados!$AG$2:$AG$55,"<>")=0,"",_xlfn.MINIFS(dados!$AG$2:$AG$55,dados!$D$2:$D$55,$A30)) | J30: =IF(COUNTIFS(dados!$D$2:$D$55,$A30,dados!$AG$2:$AG$55,"<>")=0,"",_xlfn.MAXIFS(dados!$AG$2:$AG$55,dados!$D$2:$D$55,$A30)) | K30: =IFERROR(J30-I30,"")
A31: Norte | B31: Cardápio | C31: cerveja_mediana | D31: Cerveja, mediana | E31: =COUNTIFS(dados!$D$2:$D$55,$A31,dados!$AH$2:$AH$55,"<>") | F31: =IFERROR(AVERAGEIFS(dados!$AH$2:$AH$55,dados!$D$2:$D$55,$A31),"") | G31: {=IFERROR(MEDIAN(IF((dados!$D$2:$D$55=$A31)*(dados!$AH$2:$AH$55<>""),dados!$AH$2:$AH$55)),"")} | H31: {=IFERROR(STDEV(IF((dados!$D$2:$D$55=$A31)*(dados!$AH$2:$AH$55<>""),dados!$AH$2:$AH$55)),"")} | I31: =IF(COUNTIFS(dados!$D$2:$D$55,$A31,dados!$AH$2:$AH$55,"<>")=0,"",_xlfn.MINIFS(dados!$AH$2:$AH$55,dados!$D$2:$D$55,$A31)) | J31: =IF(COUNTIFS(dados!$D$2:$D$55,$A31,dados!$AH$2:$AH$55,"<>")=0,"",_xlfn.MAXIFS(dados!$AH$2:$AH$55,dados!$D$2:$D$55,$A31)) | K31: =IFERROR(J31-I31,"")
A32: Norte | B32: Cardápio | C32: refrigerante_mediana | D32: Refrigerante, mediana | E32: =COUNTIFS(dados!$D$2:$D$55,$A32,dados!$AI$2:$AI$55,"<>") | F32: =IFERROR(AVERAGEIFS(dados!$AI$2:$AI$55,dados!$D$2:$D$55,$A32),"") | G32: {=IFERROR(MEDIAN(IF((dados!$D$2:$D$55=$A32)*(dados!$AI$2:$AI$55<>""),dados!$AI$2:$AI$55)),"")} | H32: {=IFERROR(STDEV(IF((dados!$D$2:$D$55=$A32)*(dados!$AI$2:$AI$55<>""),dados!$AI$2:$AI$55)),"")} | I32: =IF(COUNTIFS(dados!$D$2:$D$55,$A32,dados!$AI$2:$AI$55,"<>")=0,"",_xlfn.MINIFS(dados!$AI$2:$AI$55,dados!$D$2:$D$55,$A32)) | J32: =IF(COUNTIFS(dados!$D$2:$D$55,$A32,dados!$AI$2:$AI$55,"<>")=0,"",_xlfn.MAXIFS(dados!$AI$2:$AI$55,dados!$D$2:$D$55,$A32)) | K32: =IFERROR(J32-I32,"")
A33: Norte | B33: Cardápio | C33: drinks_mediana | D33: Drinks, mediana | E33: =COUNTIFS(dados!$D$2:$D$55,$A33,dados!$AJ$2:$AJ$55,"<>") | F33: =IFERROR(AVERAGEIFS(dados!$AJ$2:$AJ$55,dados!$D$2:$D$55,$A33),"") | G33: {=IFERROR(MEDIAN(IF((dados!$D$2:$D$55=$A33)*(dados!$AJ$2:$AJ$55<>""),dados!$AJ$2:$AJ$55)),"")} | H33: {=IFERROR(STDEV(IF((dados!$D$2:$D$55=$A33)*(dados!$AJ$2:$AJ$55<>""),dados!$AJ$2:$AJ$55)),"")} | I33: =IF(COUNTIFS(dados!$D$2:$D$55,$A33,dados!$AJ$2:$AJ$55,"<>")=0,"",_xlfn.MINIFS(dados!$AJ$2:$AJ$55,dados!$D$2:$D$55,$A33)) | J33: =IF(COUNTIFS(dados!$D$2:$D$55,$A33,dados!$AJ$2:$AJ$55,"<>")=0,"",_xlfn.MAXIFS(dados!$AJ$2:$AJ$55,dados!$D$2:$D$55,$A33)) | K33: =IFERROR(J33-I33,"")
A34: Norte | B34: Acervo | C34: titulos_acervo | D34: Títulos no acervo publicado | E34: =COUNTIFS(dados!$D$2:$D$55,$A34,dados!$AK$2:$AK$55,"<>") | F34: =IFERROR(AVERAGEIFS(dados!$AK$2:$AK$55,dados!$D$2:$D$55,$A34),"") | G34: {=IFERROR(MEDIAN(IF((dados!$D$2:$D$55=$A34)*(dados!$AK$2:$AK$55<>""),dados!$AK$2:$AK$55)),"")} | H34: {=IFERROR(STDEV(IF((dados!$D$2:$D$55=$A34)*(dados!$AK$2:$AK$55<>""),dados!$AK$2:$AK$55)),"")} | I34: =IF(COUNTIFS(dados!$D$2:$D$55,$A34,dados!$AK$2:$AK$55,"<>")=0,"",_xlfn.MINIFS(dados!$AK$2:$AK$55,dados!$D$2:$D$55,$A34)) | J34: =IF(COUNTIFS(dados!$D$2:$D$55,$A34,dados!$AK$2:$AK$55,"<>")=0,"",_xlfn.MAXIFS(dados!$AK$2:$AK$55,dados!$D$2:$D$55,$A34)) | K34: =IFERROR(J34-I34,"")
A35: Norte | B35: B2 | C35: avaliacoes_b2 | D35: Avaliações no recorte do B2 (até '3 meses atrás') | E35: =COUNTIFS(dados!$D$2:$D$55,$A35,dados!$AL$2:$AL$55,"<>") | F35: =IFERROR(AVERAGEIFS(dados!$AL$2:$AL$55,dados!$D$2:$D$55,$A35),"") | G35: {=IFERROR(MEDIAN(IF((dados!$D$2:$D$55=$A35)*(dados!$AL$2:$AL$55<>""),dados!$AL$2:$AL$55)),"")} | H35: {=IFERROR(STDEV(IF((dados!$D$2:$D$55=$A35)*(dados!$AL$2:$AL$55<>""),dados!$AL$2:$AL$55)),"")} | I35: =IF(COUNTIFS(dados!$D$2:$D$55,$A35,dados!$AL$2:$AL$55,"<>")=0,"",_xlfn.MINIFS(dados!$AL$2:$AL$55,dados!$D$2:$D$55,$A35)) | J35: =IF(COUNTIFS(dados!$D$2:$D$55,$A35,dados!$AL$2:$AL$55,"<>")=0,"",_xlfn.MAXIFS(dados!$AL$2:$AL$55,dados!$D$2:$D$55,$A35)) | K35: =IFERROR(J35-I35,"")
A36: Norte | B36: B2 | C36: avaliacoes_b2_com_texto | D36: Dessas, com texto | E36: =COUNTIFS(dados!$D$2:$D$55,$A36,dados!$AM$2:$AM$55,"<>") | F36: =IFERROR(AVERAGEIFS(dados!$AM$2:$AM$55,dados!$D$2:$D$55,$A36),"") | G36: {=IFERROR(MEDIAN(IF((dados!$D$2:$D$55=$A36)*(dados!$AM$2:$AM$55<>""),dados!$AM$2:$AM$55)),"")} | H36: {=IFERROR(STDEV(IF((dados!$D$2:$D$55=$A36)*(dados!$AM$2:$AM$55<>""),dados!$AM$2:$AM$55)),"")} | I36: =IF(COUNTIFS(dados!$D$2:$D$55,$A36,dados!$AM$2:$AM$55,"<>")=0,"",_xlfn.MINIFS(dados!$AM$2:$AM$55,dados!$D$2:$D$55,$A36)) | J36: =IF(COUNTIFS(dados!$D$2:$D$55,$A36,dados!$AM$2:$AM$55,"<>")=0,"",_xlfn.MAXIFS(dados!$AM$2:$AM$55,dados!$D$2:$D$55,$A36)) | K36: =IFERROR(J36-I36,"")
A37: Nordeste | B37: Google Maps | C37: avaliacao_media | D37: Nota média no Google | E37: =COUNTIFS(dados!$D$2:$D$55,$A37,dados!$E$2:$E$55,"<>") | F37: =IFERROR(AVERAGEIFS(dados!$E$2:$E$55,dados!$D$2:$D$55,$A37),"") | G37: {=IFERROR(MEDIAN(IF((dados!$D$2:$D$55=$A37)*(dados!$E$2:$E$55<>""),dados!$E$2:$E$55)),"")} | H37: {=IFERROR(STDEV(IF((dados!$D$2:$D$55=$A37)*(dados!$E$2:$E$55<>""),dados!$E$2:$E$55)),"")} | I37: =IF(COUNTIFS(dados!$D$2:$D$55,$A37,dados!$E$2:$E$55,"<>")=0,"",_xlfn.MINIFS(dados!$E$2:$E$55,dados!$D$2:$D$55,$A37)) | J37: =IF(COUNTIFS(dados!$D$2:$D$55,$A37,dados!$E$2:$E$55,"<>")=0,"",_xlfn.MAXIFS(dados!$E$2:$E$55,dados!$D$2:$D$55,$A37)) | K37: =IFERROR(J37-I37,"")
A38: Nordeste | B38: Google Maps | C38: volume_avaliacoes | D38: Nº de avaliações no Google | E38: =COUNTIFS(dados!$D$2:$D$55,$A38,dados!$F$2:$F$55,"<>") | F38: =IFERROR(AVERAGEIFS(dados!$F$2:$F$55,dados!$D$2:$D$55,$A38),"") | G38: {=IFERROR(MEDIAN(IF((dados!$D$2:$D$55=$A38)*(dados!$F$2:$F$55<>""),dados!$F$2:$F$55)),"")} | H38: {=IFERROR(STDEV(IF((dados!$D$2:$D$55=$A38)*(dados!$F$2:$F$55<>""),dados!$F$2:$F$55)),"")} | I38: =IF(COUNTIFS(dados!$D$2:$D$55,$A38,dados!$F$2:$F$55,"<>")=0,"",_xlfn.MINIFS(dados!$F$2:$F$55,dados!$D$2:$D$55,$A38)) | J38: =IF(COUNTIFS(dados!$D$2:$D$55,$A38,dados!$F$2:$F$55,"<>")=0,"",_xlfn.MAXIFS(dados!$F$2:$F$55,dados!$D$2:$D$55,$A38)) | K38: =IFERROR(J38-I38,"")
A39: Nordeste | B39: Horários | C39: dias_abertos | D39: Dias abertos por semana | E39: =COUNTIFS(dados!$D$2:$D$55,$A39,dados!$G$2:$G$55,"<>") | F39: =IFERROR(AVERAGEIFS(dados!$G$2:$G$55,dados!$D$2:$D$55,$A39),"") | G39: {=IFERROR(MEDIAN(IF((dados!$D$2:$D$55=$A39)*(dados!$G$2:$G$55<>""),dados!$G$2:$G$55)),"")} | H39: {=IFERROR(STDEV(IF((dados!$D$2:$D$55=$A39)*(dados!$G$2:$G$55<>""),dados!$G$2:$G$55)),"")} | I39: =IF(COUNTIFS(dados!$D$2:$D$55,$A39,dados!$G$2:$G$55,"<>")=0,"",_xlfn.MINIFS(dados!$G$2:$G$55,dados!$D$2:$D$55,$A39)) | J39: =IF(COUNTIFS(dados!$D$2:$D$55,$A39,dados!$G$2:$G$55,"<>")=0,"",_xlfn.MAXIFS(dados!$G$2:$G$55,dados!$D$2:$D$55,$A39)) | K39: =IFERROR(J39-I39,"")
A40: Nordeste | B40: Horários | C40: horas_semana | D40: Horas abertas por semana | E40: =COUNTIFS(dados!$D$2:$D$55,$A40,dados!$H$2:$H$55,"<>") | F40: =IFERROR(AVERAGEIFS(dados!$H$2:$H$55,dados!$D$2:$D$55,$A40),"") | G40: {=IFERROR(MEDIAN(IF((dados!$D$2:$D$55=$A40)*(dados!$H$2:$H$55<>""),dados!$H$2:$H$55)),"")} | H40: {=IFERROR(STDEV(IF((dados!$D$2:$D$55=$A40)*(dados!$H$2:$H$55<>""),dados!$H$2:$H$55)),"")} | I40: =IF(COUNTIFS(dados!$D$2:$D$55,$A40,dados!$H$2:$H$55,"<>")=0,"",_xlfn.MINIFS(dados!$H$2:$H$55,dados!$D$2:$D$55,$A40)) | J40: =IF(COUNTIFS(dados!$D$2:$D$55,$A40,dados!$H$2:$H$55,"<>")=0,"",_xlfn.MAXIFS(dados!$H$2:$H$55,dados!$D$2:$D$55,$A40)) | K40: =IFERROR(J40-I40,"")
...

Sheet metropole_detalhe
A1: metrópole | B1: grupo | C1: variável | D1: descrição | E1: n | F1: média | G1: mediana | H1: desvio padrão | I1: mínimo | J1: máximo | K1: amplitude
A2: Belo Horizonte | B2: Google Maps | C2: avaliacao_media | D2: Nota média no Google | E2: =COUNTIFS(dados!$C$2:$C$55,$A2,dados!$E$2:$E$55,"<>") | F2: =IFERROR(AVERAGEIFS(dados!$E$2:$E$55,dados!$C$2:$C$55,$A2),"") | G2: {=IFERROR(MEDIAN(IF((dados!$C$2:$C$55=$A2)*(dados!$E$2:$E$55<>""),dados!$E$2:$E$55)),"")} | H2: {=IFERROR(STDEV(IF((dados!$C$2:$C$55=$A2)*(dados!$E$2:$E$55<>""),dados!$E$2:$E$55)),"")} | I2: =IF(COUNTIFS(dados!$C$2:$C$55,$A2,dados!$E$2:$E$55,"<>")=0,"",_xlfn.MINIFS(dados!$E$2:$E$55,dados!$C$2:$C$55,$A2)) | J2: =IF(COUNTIFS(dados!$C$2:$C$55,$A2,dados!$E$2:$E$55,"<>")=0,"",_xlfn.MAXIFS(dados!$E$2:$E$55,dados!$C$2:$C$55,$A2)) | K2: =IFERROR(J2-I2,"")
A3: Belo Horizonte | B3: Google Maps | C3: volume_avaliacoes | D3: Nº de avaliações no Google | E3: =COUNTIFS(dados!$C$2:$C$55,$A3,dados!$F$2:$F$55,"<>") | F3: =IFERROR(AVERAGEIFS(dados!$F$2:$F$55,dados!$C$2:$C$55,$A3),"") | G3: {=IFERROR(MEDIAN(IF((dados!$C$2:$C$55=$A3)*(dados!$F$2:$F$55<>""),dados!$F$2:$F$55)),"")} | H3: {=IFERROR(STDEV(IF((dados!$C$2:$C$55=$A3)*(dados!$F$2:$F$55<>""),dados!$F$2:$F$55)),"")} | I3: =IF(COUNTIFS(dados!$C$2:$C$55,$A3,dados!$F$2:$F$55,"<>")=0,"",_xlfn.MINIFS(dados!$F$2:$F$55,dados!$C$2:$C$55,$A3)) | J3: =IF(COUNTIFS(dados!$C$2:$C$55,$A3,dados!$F$2:$F$55,"<>")=0,"",_xlfn.MAXIFS(dados!$F$2:$F$55,dados!$C$2:$C$55,$A3)) | K3: =IFERROR(J3-I3,"")
A4: Belo Horizonte | B4: Horários | C4: dias_abertos | D4: Dias abertos por semana | E4: =COUNTIFS(dados!$C$2:$C$55,$A4,dados!$G$2:$G$55,"<>") | F4: =IFERROR(AVERAGEIFS(dados!$G$2:$G$55,dados!$C$2:$C$55,$A4),"") | G4: {=IFERROR(MEDIAN(IF((dados!$C$2:$C$55=$A4)*(dados!$G$2:$G$55<>""),dados!$G$2:$G$55)),"")} | H4: {=IFERROR(STDEV(IF((dados!$C$2:$C$55=$A4)*(dados!$G$2:$G$55<>""),dados!$G$2:$G$55)),"")} | I4: =IF(COUNTIFS(dados!$C$2:$C$55,$A4,dados!$G$2:$G$55,"<>")=0,"",_xlfn.MINIFS(dados!$G$2:$G$55,dados!$C$2:$C$55,$A4)) | J4: =IF(COUNTIFS(dados!$C$2:$C$55,$A4,dados!$G$2:$G$55,"<>")=0,"",_xlfn.MAXIFS(dados!$G$2:$G$55,dados!$C$2:$C$55,$A4)) | K4: =IFERROR(J4-I4,"")
A5: Belo Horizonte | B5: Horários | C5: horas_semana | D5: Horas abertas por semana | E5: =COUNTIFS(dados!$C$2:$C$55,$A5,dados!$H$2:$H$55,"<>") | F5: =IFERROR(AVERAGEIFS(dados!$H$2:$H$55,dados!$C$2:$C$55,$A5),"") | G5: {=IFERROR(MEDIAN(IF((dados!$C$2:$C$55=$A5)*(dados!$H$2:$H$55<>""),dados!$H$2:$H$55)),"")} | H5: {=IFERROR(STDEV(IF((dados!$C$2:$C$55=$A5)*(dados!$H$2:$H$55<>""),dados!$H$2:$H$55)),"")} | I5: =IF(COUNTIFS(dados!$C$2:$C$55,$A5,dados!$H$2:$H$55,"<>")=0,"",_xlfn.MINIFS(dados!$H$2:$H$55,dados!$C$2:$C$55,$A5)) | J5: =IF(COUNTIFS(dados!$C$2:$C$55,$A5,dados!$H$2:$H$55,"<>")=0,"",_xlfn.MAXIFS(dados!$H$2:$H$55,dados!$C$2:$C$55,$A5)) | K5: =IFERROR(J5-I5,"")
A6: Belo Horizonte | B6: Horários | C6: abre_cedo_h | D6: Abertura mais cedo da semana | E6: =COUNTIFS(dados!$C$2:$C$55,$A6,dados!$I$2:$I$55,"<>") | F6: =IFERROR(AVERAGEIFS(dados!$I$2:$I$55,dados!$C$2:$C$55,$A6),"") | G6: {=IFERROR(MEDIAN(IF((dados!$C$2:$C$55=$A6)*(dados!$I$2:$I$55<>""),dados!$I$2:$I$55)),"")} | H6: {=IFERROR(STDEV(IF((dados!$C$2:$C$55=$A6)*(dados!$I$2:$I$55<>""),dados!$I$2:$I$55)),"")} | I6: =IF(COUNTIFS(dados!$C$2:$C$55,$A6,dados!$I$2:$I$55,"<>")=0,"",_xlfn.MINIFS(dados!$I$2:$I$55,dados!$C$2:$C$55,$A6)) | J6: =IF(COUNTIFS(dados!$C$2:$C$55,$A6,dados!$I$2:$I$55,"<>")=0,"",_xlfn.MAXIFS(dados!$I$2:$I$55,dados!$C$2:$C$55,$A6)) | K6: =IFERROR(J6-I6,"")
A7: Belo Horizonte | B7: Horários | C7: fecha_tarde_h | D7: Fechamento mais tarde da semana (25 = 1h da manhã) | E7: =COUNTIFS(dados!$C$2:$C$55,$A7,dados!$J$2:$J$55,"<>") | F7: =IFERROR(AVERAGEIFS(dados!$J$2:$J$55,dados!$C$2:$C$55,$A7),"") | G7: {=IFERROR(MEDIAN(IF((dados!$C$2:$C$55=$A7)*(dados!$J$2:$J$55<>""),dados!$J$2:$J$55)),"")} | H7: {=IFERROR(STDEV(IF((dados!$C$2:$C$55=$A7)*(dados!$J$2:$J$55<>""),dados!$J$2:$J$55)),"")} | I7: =IF(COUNTIFS(dados!$C$2:$C$55,$A7,dados!$J$2:$J$55,"<>")=0,"",_xlfn.MINIFS(dados!$J$2:$J$55,dados!$C$2:$C$55,$A7)) | J7: =IF(COUNTIFS(dados!$C$2:$C$55,$A7,dados!$J$2:$J$55,"<>")=0,"",_xlfn.MAXIFS(dados!$J$2:$J$55,dados!$C$2:$C$55,$A7)) | K7: =IFERROR(J7-I7,"")
A8: Belo Horizonte | B8: Entorno | C8: metro_500m | D8: Estações de metrô até 500 m | E8: =COUNTIFS(dados!$C$2:$C$55,$A8,dados!$K$2:$K$55,"<>") | F8: =IFERROR(AVERAGEIFS(dados!$K$2:$K$55,dados!$C$2:$C$55,$A8),"") | G8: {=IFERROR(MEDIAN(IF((dados!$C$2:$C$55=$A8)*(dados!$K$2:$K$55<>""),dados!$K$2:$K$55)),"")} | H8: {=IFERROR(STDEV(IF((dados!$C$2:$C$55=$A8)*(dados!$K$2:$K$55<>""),dados!$K$2:$K$55)),"")} | I8: =IF(COUNTIFS(dados!$C$2:$C$55,$A8,dados!$K$2:$K$55,"<>")=0,"",_xlfn.MINIFS(dados!$K$2:$K$55,dados!$C$2:$C$55,$A8)) | J8: =IF(COUNTIFS(dados!$C$2:$C$55,$A8,dados!$K$2:$K$55,"<>")=0,"",_xlfn.MAXIFS(dados!$K$2:$K$55,dados!$C$2:$C$55,$A8)) | K8: =IFERROR(J8-I8,"")
A9: Belo Horizonte | B9: Entorno | C9: metro_1000m | D9: Estações de metrô até 1000 m | E9: =COUNTIFS(dados!$C$2:$C$55,$A9,dados!$L$2:$L$55,"<>") | F9: =IFERROR(AVERAGEIFS(dados!$L$2:$L$55,dados!$C$2:$C$55,$A9),"") | G9: {=IFERROR(MEDIAN(IF((dados!$C$2:$C$55=$A9)*(dados!$L$2:$L$55<>""),dados!$L$2:$L$55)),"")} | H9: {=IFERROR(STDEV(IF((dados!$C$2:$C$55=$A9)*(dados!$L$2:$L$55<>""),dados!$L$2:$L$55)),"")} | I9: =IF(COUNTIFS(dados!$C$2:$C$55,$A9,dados!$L$2:$L$55,"<>")=0,"",_xlfn.MINIFS(dados!$L$2:$L$55,dados!$C$2:$C$55,$A9)) | J9: =IF(COUNTIFS(dados!$C$2:$C$55,$A9,dados!$L$2:$L$55,"<>")=0,"",_xlfn.MAXIFS(dados!$L$2:$L$55,dados!$C$2:$C$55,$A9)) | K9: =IFERROR(J9-I9,"")
