Workbook

Sheet Índice
A1: Dados agregados da pesquisa – TCC Luderia (B1, B3 e B4)
A2: Aba | B2: Tabela | C2: Fonte
A3: Tab 1 | B3: Tabela 1 – Casas do B1 por região e metrópole: São Paulo concentra 19 das 54; Salvador tem uma | C3: B1, Google Places API (09/2026 e 15/10/2026), coletor de entorno do Google Maps (15/10/2026), Instagram (01/09 a 01/10/2026) e cardápios
A4: Tab 2 | B4: Tabela 2 – Estatística descritiva das 54 casas do B1 | C4: B1, Google Places API (09/2026 e 15/10/2026), coletor de entorno do Google Maps (15/10/2026), Instagram (01/09 a 01/10/2026) e cardápios
A5: Tab 3 | B5: Tabela 3 – Dias de funcionamento: todas abrem de quinta a sábado; só 28% abrem na segunda | C5: B1, Google Places API (regularOpeningHours, 15/10/2026)
A6: Tab 4 | B6: Tabela 4 – Painel por região: o Sudeste reúne 31 das 54 casas; no Sul nenhuma tem metrô a até 1 km | C6: B1, Google Places API (09/2026 e 15/10/2026), coletor de entorno do Google Maps (15/10/2026), Instagram (01/09 a 01/10/2026) e cardápios
A7: Tab 5 | B7: Tabela 5 – Painel por metrópole: a cesta por pessoa varia de metrópole para metrópole | C7: B1, Google Places API (09/2026 e 15/10/2026), coletor de entorno do Google Maps (15/10/2026), Instagram (01/09 a 01/10/2026) e cardápios
A8: Tab 6 | B8: Tabela 6 – Entorno pelo Google Maps: a maioria das casas tem shopping a até 1 km; metrô perto é minoria | C8: B1, coletor de entorno do Google Maps (15/10/2026)
A9: Tab 7 | B9: Tabela 7 – Preços nos cardápios: a cesta mediana por pessoa fica em R$ 54 (metade das casas entre R$ 38,50 e R$ 70) | C9: B1, cardápios transcritos (B1_cardapios_itens_precos.xlsx)
A10: Tab 8 | B10: Tabela 8 – Couvert: encontrado no cardápio de 8 das 36 casas com cardápio | C10: B1, cardápios transcritos (B1_cardapios_itens_precos.xlsx)
A11: Tab 9 | B11: Tabela 9 – Modelos de cobrança citados no Instagram: couvert lúdico e inscrição em evento são os mais comuns | C11: B1, legendas do Instagram das casas (coletor do Instagram, 2026), análise de legendas
A12: Tab 10 | B12: Tabela 10 – Eventos no Instagram: encontros/RPG, competições e noites temáticas puxam a agenda | C12: B1, legendas do Instagram das casas (coletor do Instagram, 2026), análise de legendas
A13: Tab 11 | B13: Tabela 11 – Dia citado nos eventos: casas de jogos anunciam mais domingo e quinta; lojas, sábado | C13: B1, legendas do Instagram das casas (coletor do Instagram, 2026), análise de legendas
... A24: Dados B1 | B24: Base das 54 casas do B1 | C24: B1, Google Places API (09/2026 e 15/10/2026), coletor de entorno do Google Maps (15/10/2026), Instagram (01/09 a 01/10/2026) e cardápios
A26: Fora desta planilha, por pedido do autor (30/10/2026): comentários do B2 e dados do OpenStreetMap no entorno.
A27: Gráficos em PNG de 300 dpi em dados/Dados agregados/graficos/. Gerado por _src/extras/gerar_planilha_agregada.py.

Sheet Tab 1
A1: Tabela 1 – Casas do B1 por região e metrópole: São Paulo concentra 19 das 54; Salvador tem uma
A2: Região | B2: Metrópole | C2: Casas | D2: % do total
A3: Norte | B3: Belém | C3: =COUNTIF('Dados B1'!$B$3:$B$56,B3) | D3: =C3/C$16
A4: Nordeste | B4: Fortaleza | C4: =COUNTIF('Dados B1'!$B$3:$B$56,B4) | D4: =C4/C$16
A5: Nordeste | B5: Recife | C5: =COUNTIF('Dados B1'!$B$3:$B$56,B5) | D5: =C5/C$16
A6: Nordeste | B6: Salvador | C6: =COUNTIF('Dados B1'!$B$3:$B$56,B6) | D6: =C6/C$16
A7: Centro-Oeste | B7: Brasília | C7: =COUNTIF('Dados B1'!$B$3:$B$56,B7) | D7: =C7/C$16
A8: Centro-Oeste | B8: Goiânia | C8: =COUNTIF('Dados B1'!$B$3:$B$56,B8) | D8: =C8/C$16
A9: Sudeste | B9: São Paulo | C9: =COUNTIF('Dados B1'!$B$3:$B$56,B9) | D9: =C9/C$16
A10: Sudeste | B10: Belo Horizonte | C10: =COUNTIF('Dados B1'!$B$3:$B$56,B10) | D10: =C10/C$16
A11: Sudeste | B11: Rio de Janeiro | C11: =COUNTIF('Dados B1'!$B$3:$B$56,B11) | D11: =C11/C$16
A12: Sudeste | B12: Vitória | C12: =COUNTIF('Dados B1'!$B$3:$B$56,B12) | D12: =C12/C$16
A13: Sul | B13: Curitiba | C13: =COUNTIF('Dados B1'!$B$3:$B$56,B13) | D13: =C13/C$16
A14: Sul | B14: Florianópolis | C14: =COUNTIF('Dados B1'!$B$3:$B$56,B14) | D14: =C14/C$16
A15: Sul | B15: Porto Alegre | C15: =COUNTIF('Dados B1'!$B$3:$B$56,B15) | D15: =C15/C$16
A16: Total | C16: =SUM(C3:C15) | D16: =SUM(D3:D15)
A17: Conferência (total − casas da base; deve ser 0) | C17: =C16-COUNTA('Dados B1'!$A$3:$A$56)
A18: Fonte: B1, Google Places API (09/2026 e 15/10/2026), coletor de entorno do Google Maps (15/10/2026), Instagram (01/09 a 01/10/2026) e cardápios
A19: Nota: cada casa conta uma vez, na metrópole do endereço.

Sheet Tab 2
A1: Tabela 2 – Estatística descritiva das 54 casas do B1
A2: Grupo | B2: Variável | C2: n (com dado) | D2: Sem dado | E2: Média | F2: Mediana | G2: Desvio padrão | H2: Mínimo | I2: 1º quartil | J2: 3º quartil | K2: Máximo
A3: Google Maps | B3: Nota média no Google (1 a 5) | C3: =COUNT('Dados B1'!$D$3:$D$56) | D3: =ROWS('Dados B1'!$D$3:$D$56)-COUNT('Dados B1'!$D$3:$D$56) | E3: =IFERROR(AVERAGE('Dados B1'!$D$3:$D$56),"") | F3: =IFERROR(MEDIAN('Dados B1'!$D$3:$D$56),"") | G3: =IFERROR(STDEV('Dados B1'!$D$3:$D$56),"") | H3: =IFERROR(MIN('Dados B1'!$D$3:$D$56),"") | I3: =IFERROR(PERCENTILE('Dados B1'!$D$3:$D$56,0.25),"") | J3: =IFERROR(PERCENTILE('Dados B1'!$D$3:$D$56,0.75),"") | K3: =IFERROR(MAX('Dados B1'!$D$3:$D$56),"")
A4: Google Maps | B4: Avaliações no Google | C4: =COUNT('Dados B1'!$E$3:$E$56) | D4: =ROWS('Dados B1'!$E$3:$E$56)-COUNT('Dados B1'!$E$3:$E$56) | E4: =IFERROR(AVERAGE('Dados B1'!$E$3:$E$56),"") | F4: =IFERROR(MEDIAN('Dados B1'!$E$3:$E$56),"") | G4: =IFERROR(STDEV('Dados B1'!$E$3:$E$56),"") | H4: =IFERROR(MIN('Dados B1'!$E$3:$E$56),"") | I4: =IFERROR(PERCENTILE('Dados B1'!$E$3:$E$56,0.25),"") | J4: =IFERROR(PERCENTILE('Dados B1'!$E$3:$E$56,0.75),"") | K4: =IFERROR(MAX('Dados B1'!$E$3:$E$56),"")
A5: Horários | B5: Dias abertos por semana | C5: =COUNT('Dados B1'!$F$3:$F$56) | D5: =ROWS('Dados B1'!$F$3:$F$56)-COUNT('Dados B1'!$F$3:$F$56) | E5: =IFERROR(AVERAGE('Dados B1'!$F$3:$F$56),"") | F5: =IFERROR(MEDIAN('Dados B1'!$F$3:$F$56),"") | G5: =IFERROR(STDEV('Dados B1'!$F$3:$F$56),"") | H5: =IFERROR(MIN('Dados B1'!$F$3:$F$56),"") | I5: =IFERROR(PERCENTILE('Dados B1'!$F$3:$F$56,0.25),"") | J5: =IFERROR(PERCENTILE('Dados B1'!$F$3:$F$56,0.75),"") | K5: =IFERROR(MAX('Dados B1'!$F$3:$F$56),"")
A6: Horários | B6: Horas abertas por semana | C6: =COUNT('Dados B1'!$G$3:$G$56) | D6: =ROWS('Dados B1'!$G$3:$G$56)-COUNT('Dados B1'!$G$3:$G$56) | E6: =IFERROR(AVERAGE('Dados B1'!$G$3:$G$56),"") | F6: =IFERROR(MEDIAN('Dados B1'!$G$3:$G$56),"") | G6: =IFERROR(STDEV('Dados B1'!$G$3:$G$56),"") | H6: =IFERROR(MIN('Dados B1'!$G$3:$G$56),"") | I6: =IFERROR(PERCENTILE('Dados B1'!$G$3:$G$56,0.25),"") | J6: =IFERROR(PERCENTILE('Dados B1'!$G$3:$G$56,0.75),"") | K6: =IFERROR(MAX('Dados B1'!$G$3:$G$56),"")
A7: Horários | B7: Abertura mais cedo (hora do dia) | C7: =COUNT('Dados B1'!$H$3:$H$56) | D7: =ROWS('Dados B1'!$H$3:$H$56)-COUNT('Dados B1'!$H$3:$H$56) | E7: =IFERROR(AVERAGE('Dados B1'!$H$3:$H$56),"") | F7: =IFERROR(MEDIAN('Dados B1'!$H$3:$H$56),"") | G7: =IFERROR(STDEV('Dados B1'!$H$3:$H$56),"") | H7: =IFERROR(MIN('Dados B1'!$H$3:$H$56),"") | I7: =IFERROR(PERCENTILE('Dados B1'!$H$3:$H$56,0.25),"") | J7: =IFERROR(PERCENTILE('Dados B1'!$H$3:$H$56,0.75),"") | K7: =IFERROR(MAX('Dados B1'!$H$3:$H$56),"")
A8: Horários | B8: Fechamento mais tarde (25 = 1h) | C8: =COUNT('Dados B1'!$I$3:$I$56) | D8: =ROWS('Dados B1'!$I$3:$I$56)-COUNT('Dados B1'!$I$3:$I$56) | E8: =IFERROR(AVERAGE('Dados B1'!$I$3:$I$56),"") | F8: =IFERROR(MEDIAN('Dados B1'!$I$3:$I$56),"") | G8: =IFERROR(STDEV('Dados B1'!$I$3:$I$56),"") | H8: =IFERROR(MIN('Dados B1'!$I$3:$I$56),"") | I8: =IFERROR(PERCENTILE('Dados B1'!$I$3:$I$56,0.25),"") | J8: =IFERROR(PERCENTILE('Dados B1'!$I$3:$I$56,0.75),"") | K8: =IFERROR(MAX('Dados B1'!$I$3:$I$56),"")
A9: Entorno (Maps) | B9: Estações de metrô até 500 m | C9: =COUNT('Dados B1'!$Q$3:$Q$56) | D9: =ROWS('Dados B1'!$Q$3:$Q$56)-COUNT('Dados B1'!$Q$3:$Q$56) | E9: =IFERROR(AVERAGE('Dados B1'!$Q$3:$Q$56),"") | F9: =IFERROR(MEDIAN('Dados B1'!$Q$3:$Q$56),"") | G9: =IFERROR(STDEV('Dados B1'!$Q$3:$Q$56),"") | H9: =IFERROR(MIN('Dados B1'!$Q$3:$Q$56),"") | I9: =IFERROR(PERCENTILE('Dados B1'!$Q$3:$Q$56,0.25),"") | J9: =IFERROR(PERCENTILE('Dados B1'!$Q$3:$Q$56,0.75),"") | K9: =IFERROR(MAX('Dados B1'!$Q$3:$Q$56),"")
A10: Entorno (Maps) | B10: Estações de metrô até 1000 m | C10: =COUNT('Dados B1'!$R$3:$R$56) | D10: =ROWS('Dados B1'!$R$3:$R$56)-COUNT('Dados B1'!$R$3:$R$56) | E10: =IFERROR(AVERAGE('Dados B1'!$R$3:$R$56),"") | F10: =IFERROR(MEDIAN('Dados B1'!$R$3:$R$56),"") | G10: =IFERROR(STDEV('Dados B1'!$R$3:$R$56),"") | H10: =IFERROR(MIN('Dados B1'!$R$3:$R$56),"") | I10: =IFERROR(PERCENTILE('Dados B1'!$R$3:$R$56,0.25),"") | J10: =IFERROR(PERCENTILE('Dados B1'!$R$3:$R$56,0.75),"") | K10: =IFERROR(MAX('Dados B1'!$R$3:$R$56),"")
A11: Entorno (Maps) | B11: Distância ao metrô mais próximo (m) | C11: =COUNT('Dados B1'!$S$3:$S$56) | D11: =ROWS('Dados B1'!$S$3:$S$56)-COUNT('Dados B1'!$S$3:$S$56) | E11: =IFERROR(AVERAGE('Dados B1'!$S$3:$S$56),"") | F11: =IFERROR(MEDIAN('Dados B1'!$S$3:$S$56),"") | G11: =IFERROR(STDEV('Dados B1'!$S$3:$S$56),"") | H11: =IFERROR(MIN('Dados B1'!$S$3:$S$56),"") | I11: =IFERROR(PERCENTILE('Dados B1'!$S$3:$S$56,0.25),"") | J11: =IFERROR(PERCENTILE('Dados B1'!$S$3:$S$56,0.75),"") | K11: =IFERROR(MAX('Dados B1'!$S$3:$S$56),"")
A12: Entorno (Maps) | B12: Distância ao shopping mais próximo (m) | C12: =COUNT('Dados B1'!$T$3:$T$56) | D12: =ROWS('Dados B1'!$T$3:$T$56)-COUNT('Dados B1'!$T$3:$T$56) | E12: =IFERROR(AVERAGE('Dados B1'!$T$3:$T$56),"") | F12: =IFERROR(MEDIAN('Dados B1'!$T$3:$T$56),"") | G12: =IFERROR(STDEV('Dados B1'!$T$3:$T$56),"") | H12: =IFERROR(MIN('Dados B1'!$T$3:$T$56),"") | I12: =IFERROR(PERCENTILE('Dados B1'!$T$3:$T$56,0.25),"") | J12: =IFERROR(PERCENTILE('Dados B1'!$T$3:$T$56,0.75),"") | K12: =IFERROR(MAX('Dados B1'!$T$3:$T$56),"")
A13: Instagram | B13: Seguidores | C13: =COUNT('Dados B1'!$U$3:$U$56) | D13: =ROWS('Dados B1'!$U$3:$U$56)-COUNT('Dados B1'!$U$3:$U$56) | E13: =IFERROR(AVERAGE('Dados B1'!$U$3:$U$56),"") | F13: =IFERROR(MEDIAN('Dados B1'!$U$3:$U$56),"") | G13: =IFERROR(STDEV('Dados B1'!$U$3:$U$56),"") | H13: =IFERROR(MIN('Dados B1'!$U$3:$U$56),"") | I13: =IFERROR(PERCENTILE('Dados B1'!$U$3:$U$56,0.25),"") | J13: =IFERROR(PERCENTILE('Dados B1'!$U$3:$U$56,0.75),"") | K13: =IFERROR(MAX('Dados B1'!$U$3:$U$56),"")
A14: Instagram | B14: Posts desde a criação do perfil | C14: =COUNT('Dados B1'!$V$3:$V$56) | D14: =ROWS('Dados B1'!$V$3:$V$56)-COUNT('Dados B1'!$V$3:$V$56) | E14: =IFERROR(AVERAGE('Dados B1'!$V$3:$V$56),"") | F14: =IFERROR(MEDIAN('Dados B1'!$V$3:$V$56),"") | G14: =IFERROR(STDEV('Dados B1'!$V$3:$V$56),"") | H14: =IFERROR(MIN('Dados B1'!$V$3:$V$56),"") | I14: =IFERROR(PERCENTILE('Dados B1'!$V$3:$V$56,0.25),"") | J14: =IFERROR(PERCENTILE('Dados B1'!$V$3:$V$56,0.75),"") | K14: =IFERROR(MAX('Dados B1'!$V$3:$V$56),"")
A15: Instagram | B15: Idade do perfil (anos) | C15: =COUNT('Dados B1'!$W$3:$W$56) | D15: =ROWS('Dados B1'!$W$3:$W$56)-COUNT('Dados B1'!$W$3:$W$56) | E15: =IFERROR(AVERAGE('Dados B1'!$W$3:$W$56),"") | F15: =IFERROR(MEDIAN('Dados B1'!$W$3:$W$56),"") | G15: =IFERROR(STDEV('Dados B1'!$W$3:$W$56),"") | H15: =IFERROR(MIN('Dados B1'!$W$3:$W$56),"") | I15: =IFERROR(PERCENTILE('Dados B1'!$W$3:$W$56,0.25),"") | J15: =IFERROR(PERCENTILE('Dados B1'!$W$3:$W$56,0.75),"") | K15: =IFERROR(MAX('Dados B1'!$W$3:$W$56),"")
A16: Instagram | B16: Posts de 01/09 a 01/10/2026 | C16: =COUNT('Dados B1'!$X$3:$X$56) | D16: =ROWS('Dados B1'!$X$3:$X$56)-COUNT('Dados B1'!$X$3:$X$56) | E16: =IFERROR(AVERAGE('Dados B1'!$X$3:$X$56),"") | F16: =IFERROR(MEDIAN('Dados B1'!$X$3:$X$56),"") | G16: =IFERROR(STDEV('Dados B1'!$X$3:$X$56),"") | H16: =IFERROR(MIN('Dados B1'!$X$3:$X$56),"") | I16: =IFERROR(PERCENTILE('Dados B1'!$X$3:$X$56,0.25),"") | J16: =IFERROR(PERCENTILE('Dados B1'!$X$3:$X$56,0.75),"") | K16: =IFERROR(MAX('Dados B1'!$X$3:$X$56),"")
A17: Instagram | B17: Interações por post | C17: =COUNT('Dados B1'!$Y$3:$Y$56) | D17: =ROWS('Dados B1'!$Y$3:$Y$56)-COUNT('Dados B1'!$Y$3:$Y$56) | E17: =IFERROR(AVERAGE('Dados B1'!$Y$3:$Y$56),"") | F17: =IFERROR(MEDIAN('Dados B1'!$Y$3:$Y$56),"") | G17: =IFERROR(STDEV('Dados B1'!$Y$3:$Y$56),"") | H17: =IFERROR(MIN('Dados B1'!$Y$3:$Y$56),"") | I17: =IFERROR(PERCENTILE('Dados B1'!$Y$3:$Y$56,0.25),"") | J17: =IFERROR(PERCENTILE('Dados B1'!$Y$3:$Y$56,0.75),"") | K17: =IFERROR(MAX('Dados B1'!$Y$3:$Y$56),"")
A18: Instagram | B18: Engajamento (interações por post ÷ seguidores) | C18: =COUNT('Dados B1'!$Z$3:$Z$56) | D18: =ROWS('Dados B1'!$Z$3:$Z$56)-COUNT('Dados B1'!$Z$3:$Z$56) | E18: =IFERROR(AVERAGE('Dados B1'!$Z$3:$Z$56),"") | F18: =IFERROR(MEDIAN('Dados B1'!$Z$3:$Z$56),"") | G18: =IFERROR(STDEV('Dados B1'!$Z$3:$Z$56),"") | H18: =IFERROR(MIN('Dados B1'!$Z$3:$Z$56),"") | I18: =IFERROR(PERCENTILE('Dados B1'!$Z$3:$Z$56,0.25),"") | J18: =IFERROR(PERCENTILE('Dados B1'!$Z$3:$Z$56,0.75),"") | K18: =IFERROR(MAX('Dados B1'!$Z$3:$Z$56),"")
A19: Cardápio | B19: Itens com preço no cardápio | C19: =COUNT('Dados B1'!$AA$3:$AA$56) | D19: =ROWS('Dados B1'!$AA$3:$AA$56)-COUNT('Dados B1'!$AA$3:$AA$56) | E19: =IFERROR(AVERAGE('Dados B1'!$AA$3:$AA$56),"") | F19: =IFERROR(MEDIAN('Dados B1'!$AA$3:$AA$56),"") | G19: =IFERROR(STDEV('Dados B1'!$AA$3:$AA$56),"") | H19: =IFERROR(MIN('Dados B1'!$AA$3:$AA$56),"") | I19: =IFERROR(PERCENTILE('Dados B1'!$AA$3:$AA$56,0.25),"") | J19: =IFERROR(PERCENTILE('Dados B1'!$AA$3:$AA$56,0.75),"") | K19: =IFERROR(MAX('Dados B1'!$AA$3:$AA$56),"")
A20: Cardápio | B20: Couvert ou taxa de jogo (R$, casas que cobram) | C20: =COUNT('Dados B1'!$AD$3:$AD$56) | D20: =ROWS('Dados B1'!$AD$3:$AD$56)-COUNT('Dados B1'!$AD$3:$AD$56) | E20: =IFERROR(AVERAGE('Dados B1'!$AD$3:$AD$56),"") | F20: =IFERROR(MEDIAN('Dados B1'!$AD$3:$AD$56),"") | G20: =IFERROR(STDEV('Dados B1'!$AD$3:$AD$56),"") | H20: =IFERROR(MIN('Dados B1'!$AD$3:$AD$56),"") | I20: =IFERROR(PERCENTILE('Dados B1'!$AD$3:$AD$56,0.25),"") | J20: =IFERROR(PERCENTILE('Dados B1'!$AD$3:$AD$56,0.75),"") | K20: =IFERROR(MAX('Dados B1'!$AD$3:$AD$56),"")
A21: Cardápio | B21: Bebida, mediana do cardápio (R$) | C21: =COUNT('Dados B1'!$AE$3:$AE$56) | D21: =ROWS('Dados B1'!$AE$3:$AE$56)-COUNT('Dados B1'!$AE$3:$AE$56) | E21: =IFERROR(AVERAGE('Dados B1'!$AE$3:$AE$56),"") | F21: =IFERROR(MEDIAN('Dados B1'!$AE$3:$AE$56),"") | G21: =IFERROR(STDEV('Dados B1'!$AE$3:$AE$56),"") | H21: =IFERROR(MIN('Dados B1'!$AE$3:$AE$56),"") | I21: =IFERROR(PERCENTILE('Dados B1'!$AE$3:$AE$56,0.25),"") | J21: =IFERROR(PERCENTILE('Dados B1'!$AE$3:$AE$56,0.75),"") | K21: =IFERROR(MAX('Dados B1'!$AE$3:$AE$56),"")
A22: Cardápio | B22: Entrada ou prato, mediana (R$) | C22: =COUNT('Dados B1'!$AF$3:$AF$56) | D22: =ROWS('Dados B1'!$AF$3:$AF$56)-COUNT('Dados B1'!$AF$3:$AF$56) | E22: =IFERROR(AVERAGE('Dados B1'!$AF$3:$AF$56),"") | F22: =IFERROR(MEDIAN('Dados B1'!$AF$3:$AF$56),"") | G22: =IFERROR(STDEV('Dados B1'!$AF$3:$AF$56),"") | H22: =IFERROR(MIN('Dados B1'!$AF$3:$AF$56),"") | I22: =IFERROR(PERCENTILE('Dados B1'!$AF$3:$AF$56,0.25),"") | J22: =IFERROR(PERCENTILE('Dados B1'!$AF$3:$AF$56,0.75),"") | K22: =IFERROR(MAX('Dados B1'!$AF$3:$AF$56),"")
A23: Cardápio | B23: Cesta por pessoa, nível baixo (R$) | C23: =COUNT('Dados B1'!$AG$3:$AG$56) | D23: =ROWS('Dados B1'!$AG$3:$AG$56)-COUNT('Dados B1'!$AG$3:$AG$56) | E23: =IFERROR(AVERAGE('Dados B1'!$AG$3:$AG$56),"") | F23: =IFERROR(MEDIAN('Dados B1'!$AG$3:$AG$56),"") | G23: =IFERROR(STDEV('Dados B1'!$AG$3:$AG$56),"") | H23: =IFERROR(MIN('Dados B1'!$AG$3:$AG$56),"") | I23: =IFERROR(PERCENTILE('Dados B1'!$AG$3:$AG$56,0.25),"") | J23: =IFERROR(PERCENTILE('Dados B1'!$AG$3:$AG$56,0.75),"") | K23: =IFERROR(MAX('Dados B1'!$AG$3:$AG$56),"")
A24: Cardápio | B24: Cesta por pessoa, nível mediano (R$) | C24: =COUNT('Dados B1'!$AH$3:$AH$56) | D24: =ROWS('Dados B1'!$AH$3:$AH$56)-COUNT('Dados B1'!$AH$3:$AH$56) | E24: =IFERROR(AVERAGE('Dados B1'!$AH$3:$AH$56),"") | F24: =IFERROR(MEDIAN('Dados B1'!$AH$3:$AH$56),"") | G24: =IFERROR(STDEV('Dados B1'!$AH$3:$AH$56),"") | H24: =IFERROR(MIN('Dados B1'!$AH$3:$AH$56),"") | I24: =IFERROR(PERCENTILE('Dados B1'!$AH$3:$AH$56,0.25),"") | J24: =IFERROR(PERCENTILE('Dados B1'!$AH$3:$AH$56,0.75),"") | K24: =IFERROR(MAX('Dados B1'!$AH$3:$AH$56),"")
A25: Cardápio | B25: Cesta por pessoa, nível alto (R$) | C25: =COUNT('Dados B1'!$AI$3:$AI$56) | D25: =ROWS('Dados B1'!$AI$3:$AI$56)-COUNT('Dados B1'!$AI$3:$AI$56) | E25: =IFERROR(AVERAGE('Dados B1'!$AI$3:$AI$56),"") | F25: =IFERROR(MEDIAN('Dados B1'!$AI$3:$AI$56),"") | G25: =IFERROR(STDEV('Dados B1'!$AI$3:$AI$56),"") | H25: =IFERROR(MIN('Dados B1'!$AI$3:$AI$56),"") | I25: =IFERROR(PERCENTILE('Dados B1'!$AI$3:$AI$56,0.25),"") | J25: =IFERROR(PERCENTILE('Dados B1'!$AI$3:$AI$56,0.75),"") | K25: =IFERROR(MAX('Dados B1'!$AI$3:$AI$56),"")
A26: Acervo | B26: Títulos no acervo publicado | C26: =COUNT('Dados B1'!$AO$3:$AO$56) | D26: =ROWS('Dados B1'!$AO$3:$AO$56)-COUNT('Dados B1'!$AO$3:$AO$56) | E26: =IFERROR(AVERAGE('Dados B1'!$AO$3:$AO$56),"") | F26: =IFERROR(MEDIAN('Dados B1'!$AO$3:$AO$56),"") | G26: =IFERROR(STDEV('Dados B1'!$AO$3:$AO$56),"") | H26: =IFERROR(MIN('Dados B1'!$AO$3:$AO$56),"") | I26: =IFERROR(PERCENTILE('Dados B1'!$AO$3:$AO$56,0.25),"") | J26: =IFERROR(PERCENTILE('Dados B1'!$AO$3:$AO$56,0.75),"") | K26: =IFERROR(MAX('Dados B1'!$AO$3:$AO$56),"")
A27: Fonte: B1, Google Places API (09/2026 e 15/10/2026), coletor de entorno do Google Maps (15/10/2026), Instagram (01/09 a 01/10/2026) e cardápios
A28: Nota: desvio padrão amostral; quartis pelo método inclusivo. Engajamento em fração (0,01 = 1%).
A29: Entorno sem OpenStreetMap: shoppings de porte fora. Distância ao metrô vazia onde a cidade não tem metrô lido (Curitiba, Florianópolis, Belém, Goiânia, Vitória).

Sheet Tab 3
A1: Tabela 3 – Dias de funcionamento: todas abrem de quinta a sábado; só 28% abrem na segunda
A2: Dia | B2: Casas que abrem | C2: Casas com horário | D2: % das casas
A3: Segunda | B3: =COUNTIF('Dados B1'!$J$3:$J$56,1) | C3: =COUNT('Dados B1'!$J$3:$J$56) | D3: =B3/C3
A4: Terça | B4: =COUNTIF('Dados B1'!$K$3:$K$56,1) | C4: =COUNT('Dados B1'!$K$3:$K$56) | D4: =B4/C4
A5: Quarta | B5: =COUNTIF('Dados B1'!$L$3:$L$56,1) | C5: =COUNT('Dados B1'!$L$3:$L$56) | D5: =B5/C5
A6: Quinta | B6: =COUNTIF('Dados B1'!$M$3:$M$56,1) | C6: =COUNT('Dados B1'!$M$3:$M$56) | D6: =B6/C6
A7: Sexta | B7: =COUNTIF('Dados B1'!$N$3:$N$56,1) | C7: =COUNT('Dados B1'!$N$3:$N$56) | D7: =B7/C7
A8: Sábado | B8: =COUNTIF('Dados B1'!$O$3:$O$56,1) | C8: =COUNT('Dados B1'!$O$3:$O$56) | D8: =B8/C8
A9: Domingo | B9: =COUNTIF('Dados B1'!$P$3:$P$56,1) | C9: =COUNT('Dados B1'!$P$3:$P$56) | D9: =B9/C9
A10: Fonte: B1, Google Places API (regularOpeningHours, 15/10/2026)
A11: Nota: contagem não exclusiva (cada casa abre em vários dias); cada linha tem o próprio total.

Sheet Tab 4
A1: Tabela 4 – Painel por região: o Sudeste reúne 31 das 54 casas; no Sul nenhuma tem metrô a até 1 km
A2: Região | B2: casas | C2: nota (mediana) | D2: horas abertas por semana (média) | E2: abre domingo (%) | F2: abre segunda (%) | G2: metrô até 1000 m (% das casas) | H2: seguidores (mediana) | I2: casas com cesta | J2: cesta mediana (mediana, R$)
A3: Norte | B3: =COUNTIF('Dados B1'!$C$3:$C$56,$A3) | C3: {=IFERROR(MEDIAN(IF('Dados B1'!$C$3:$C$56=$A3,IF('Dados B1'!$D$3:$D$56<>"",'Dados B1'!$D$3:$D$56))),"")} | D3: =IFERROR(AVERAGEIFS('Dados B1'!$G$3:$G$56,'Dados B1'!$C$3:$C$56,$A3),"") | E3: =IFERROR(AVERAGEIFS('Dados B1'!$P$3:$P$56,'Dados B1'!$C$3:$C$56,$A3),"") | F3: =IFERROR(AVERAGEIFS('Dados B1'!$J$3:$J$56,'Dados B1'!$C$3:$C$56,$A3),"") | G3: =IFERROR(COUNTIFS('Dados B1'!$C$3:$C$56,$A3,'Dados B1'!$R$3:$R$56,">0")/COUNTIF('Dados B1'!$C$3:$C$56,$A3),"") | H3: {=IFERROR(MEDIAN(IF('Dados B1'!$C$3:$C$56=$A3,IF('Dados B1'!$U$3:$U$56<>"",'Dados B1'!$U$3:$U$56))),"")} | I3: =COUNTIFS('Dados B1'!$C$3:$C$56,$A3,'Dados B1'!$AH$3:$AH$56,"<>") | J3: {=IFERROR(MEDIAN(IF('Dados B1'!$C$3:$C$56=$A3,IF('Dados B1'!$AH$3:$AH$56<>"",'Dados B1'!$AH$3:$AH$56))),"")}
A4: Nordeste | B4: =COUNTIF('Dados B1'!$C$3:$C$56,$A4) | C4: {=IFERROR(MEDIAN(IF('Dados B1'!$C$3:$C$56=$A4,IF('Dados B1'!$D$3:$D$56<>"",'Dados B1'!$D$3:$D$56))),"")} | D4: =IFERROR(AVERAGEIFS('Dados B1'!$G$3:$G$56,'Dados B1'!$C$3:$C$56,$A4),"") | E4: =IFERROR(AVERAGEIFS('Dados B1'!$P$3:$P$56,'Dados B1'!$C$3:$C$56,$A4),"") | F4: =IFERROR(AVERAGEIFS('Dados B1'!$J$3:$J$56,'Dados B1'!$C$3:$C$56,$A4),"") | G4: =IFERROR(COUNTIFS('Dados B1'!$C$3:$C$56,$A4,'Dados B1'!$R$3:$R$56,">0")/COUNTIF('Dados B1'!$C$3:$C$56,$A4),"") | H4: {=IFERROR(MEDIAN(IF('Dados B1'!$C$3:$C$56=$A4,IF('Dados B1'!$U$3:$U$56<>"",'Dados B1'!$U$3:$U$56))),"")} | I4: =COUNTIFS('Dados B1'!$C$3:$C$56,$A4,'Dados B1'!$AH$3:$AH$56,"<>") | J4: {=IFERROR(MEDIAN(IF('Dados B1'!$C$3:$C$56=$A4,IF('Dados B1'!$AH$3:$AH$56<>"",'Dados B1'!$AH$3:$AH$56))),"")}
A5: Centro-Oeste | B5: =COUNTIF('Dados B1'!$C$3:$C$56,$A5) | C5: {=IFERROR(MEDIAN(IF('Dados B1'!$C$3:$C$56=$A5,IF('Dados B1'!$D$3:$D$56<>"",'Dados B1'!$D$3:$D$56))),"")} | D5: =IFERROR(AVERAGEIFS('Dados B1'!$G$3:$G$56,'Dados B1'!$C$3:$C$56,$A5),"") | E5: =IFERROR(AVERAGEIFS('Dados B1'!$P$3:$P$56,'Dados B1'!$C$3:$C$56,$A5),"") | F5: =IFERROR(AVERAGEIFS('Dados B1'!$J$3:$J$56,'Dados B1'!$C$3:$C$56,$A5),"") | G5: =IFERROR(COUNTIFS('Dados B1'!$C$3:$C$56,$A5,'Dados B1'!$R$3:$R$56,">0")/COUNTIF('Dados B1'!$C$3:$C$56,$A5),"") | H5: {=IFERROR(MEDIAN(IF('Dados B1'!$C$3:$C$56=$A5,IF('Dados B1'!$U$3:$U$56<>"",'Dados B1'!$U$3:$U$56))),"")} | I5: =COUNTIFS('Dados B1'!$C$3:$C$56,$A5,'Dados B1'!$AH$3:$AH$56,"<>") | J5: {=IFERROR(MEDIAN(IF('Dados B1'!$C$3:$C$56=$A5,IF('Dados B1'!$AH$3:$AH$56<>"",'Dados B1'!$AH$3:$AH$56))),"")}
A6: Sudeste | B6: =COUNTIF('Dados B1'!$C$3:$C$56,$A6) | C6: {=IFERROR(MEDIAN(IF('Dados B1'!$C$3:$C$56=$A6,IF('Dados B1'!$D$3:$D$56<>"",'Dados B1'!$D$3:$D$56))),"")} | D6: =IFERROR(AVERAGEIFS('Dados B1'!$G$3:$G$56,'Dados B1'!$C$3:$C$56,$A6),"") | E6: =IFERROR(AVERAGEIFS('Dados B1'!$P$3:$P$56,'Dados B1'!$C$3:$C$56,$A6),"") | F6: =IFERROR(AVERAGEIFS('Dados B1'!$J$3:$J$56,'Dados B1'!$C$3:$C$56,$A6),"") | G6: =IFERROR(COUNTIFS('Dados B1'!$C$3:$C$56,$A6,'Dados B1'!$R$3:$R$56,">0")/COUNTIF('Dados B1'!$C$3:$C$56,$A6),"") | H6: {=IFERROR(MEDIAN(IF('Dados B1'!$C$3:$C$56=$A6,IF('Dados B1'!$U$3:$U$56<>"",'Dados B1'!$U$3:$U$56))),"")} | I6: =COUNTIFS('Dados B1'!$C$3:$C$56,$A6,'Dados B1'!$AH$3:$AH$56,"<>") | J6: {=IFERROR(MEDIAN(IF('Dados B1'!$C$3:$C$56=$A6,IF('Dados B1'!$AH$3:$AH$56<>"",'Dados B1'!$AH$3:$AH$56))),"")}
A7: Sul | B7: =COUNTIF('Dados B1'!$C$3:$C$56,$A7) | C7: {=IFERROR(MEDIAN(IF('Dados B1'!$C$3:$C$56=$A7,IF('Dados B1'!$D$3:$D$56<>"",'Dados B1'!$D$3:$D$56))),"")} | D7: =IFERROR(AVERAGEIFS('Dados B1'!$G$3:$G$56,'Dados B1'!$C$3:$C$56,$A7),"") | E7: =IFERROR(AVERAGEIFS('Dados B1'!$P$3:$P$56,'Dados B1'!$C$3:$C$56,$A7),"") | F7: =IFERROR(AVERAGEIFS('Dados B1'!$J$3:$J$56,'Dados B1'!$C$3:$C$56,$A7),"") | G7: =IFERROR(COUNTIFS('Dados B1'!$C$3:$C$56,$A7,'Dados B1'!$R$3:$R$56,">0")/COUNTIF('Dados B1'!$C$3:$C$56,$A7),"") | H7: {=IFERROR(MEDIAN(IF('Dados B1'!$C$3:$C$56=$A7,IF('Dados B1'!$U$3:$U$56<>"",'Dados B1'!$U$3:$U$56))),"")} | I7: =COUNTIFS('Dados B1'!$C$3:$C$56,$A7,'Dados B1'!$AH$3:$AH$56,"<>") | J7: {=IFERROR(MEDIAN(IF('Dados B1'!$C$3:$C$56=$A7,IF('Dados B1'!$AH$3:$AH$56<>"",'Dados B1'!$AH$3:$AH$56))),"")}
A8: Total | B8: =SUM(B3:B7) | C8: =MEDIAN('Dados B1'!$D$3:$D$56) | D8: =AVERAGE('Dados B1'!$G$3:$G$56) | E8: =AVERAGE('Dados B1'!$P$3:$P$56) | F8: =AVERAGE('Dados B1'!$J$3:$J$56) | G8: =COUNTIF('Dados B1'!$R$3:$R$56,">0")/COUNTA('Dados B1'!$A$3:$A$56) | H8: =MEDIAN('Dados B1'!$U$3:$U$56) | I8: =COUNT('Dados B1'!$AH$3:$AH$56) | J8: =MEDIAN('Dados B1'!$AH$3:$AH$56)
A9: Fonte: B1, Google Places API (09/2026 e 15/10/2026), coletor de entorno do Google Maps (15/10/2026), Instagram (01/09 a 01/10/2026) e cardápios
A10: Nota: medianas calculadas só entre as casas com dado; cesta só nas casas com couvert, bebida e prato encontrados.

Sheet Tab 5
A1: Tabela 5 – Painel por metrópole: a cesta por pessoa varia de metrópole para metrópole
A2: Metrópole | B2: Região | C2: casas | D2: nota (mediana) | E2: horas abertas por semana (média) | F2: abre domingo (%) | G2: abre segunda (%) | H2: metrô até 1000 m (% das casas) | I2: seguidores (mediana) | J2: casas com cesta | K2: cesta mediana (mediana, R$)
A3: Belém | B3: Norte | C3: =COUNTIF('Dados B1'!$B$3:$B$56,$A3) | D3: {=IFERROR(MEDIAN(IF('Dados B1'!$B$3:$B$56=$A3,IF('Dados B1'!$D$3:$D$56<>"",'Dados B1'!$D$3:$D$56))),"")} | E3: =IFERROR(AVERAGEIFS('Dados B1'!$G$3:$G$56,'Dados B1'!$B$3:$B$56,$A3),"") | F3: =IFERROR(AVERAGEIFS('Dados B1'!$P$3:$P$56,'Dados B1'!$B$3:$B$56,$A3),"") | G3: =IFERROR(AVERAGEIFS('Dados B1'!$J$3:$J$56,'Dados B1'!$B$3:$B$56,$A3),"") | H3: =IFERROR(COUNTIFS('Dados B1'!$B$3:$B$56,$A3,'Dados B1'!$R$3:$R$56,">0")/COUNTIF('Dados B1'!$B$3:$B$56,$A3),"") | I3: {=IFERROR(MEDIAN(IF('Dados B1'!$B$3:$B$56=$A3,IF('Dados B1'!$U$3:$U$56<>"",'Dados B1'!$U$3:$U$56))),"")} | J3: =COUNTIFS('Dados B1'!$B$3:$B$56,$A3,'Dados B1'!$AH$3:$AH$56,"<>") | K3: {=IFERROR(MEDIAN(IF('Dados B1'!$B$3:$B$56=$A3,IF('Dados B1'!$AH$3:$AH$56<>"",'Dados B1'!$AH$3:$AH$56))),"")}
A4: Fortaleza | B4: Nordeste | C4: =COUNTIF('Dados B1'!$B$3:$B$56,$A4) | D4: {=IFERROR(MEDIAN(IF('Dados B1'!$B$3:$B$56=$A4,IF('Dados B1'!$D$3:$D$56<>"",'Dados B1'!$D$3:$D$56))),"")} | E4: =IFERROR(AVERAGEIFS('Dados B1'!$G$3:$G$56,'Dados B1'!$B$3:$B$56,$A4),"") | F4: =IFERROR(AVERAGEIFS('Dados B1'!$P$3:$P$56,'Dados B1'!$B$3:$B$56,$A4),"") | G4: =IFERROR(AVERAGEIFS('Dados B1'!$J$3:$J$56,'Dados B1'!$B$3:$B$56,$A4),"") | H4: =IFERROR(COUNTIFS('Dados B1'!$B$3:$B$56,$A4,'Dados B1'!$R$3:$R$56,">0")/COUNTIF('Dados B1'!$B$3:$B$56,$A4),"") | I4: {=IFERROR(MEDIAN(IF('Dados B1'!$B$3:$B$56=$A4,IF('Dados B1'!$U$3:$U$56<>"",'Dados B1'!$U$3:$U$56))),"")} | J4: =COUNTIFS('Dados B1'!$B$3:$B$56,$A4,'Dados B1'!$AH$3:$AH$56,"<>") | K4: {=IFERROR(MEDIAN(IF('Dados B1'!$B$3:$B$56=$A4,IF('Dados B1'!$AH$3:$AH$56<>"",'Dados B1'!$AH$3:$AH$56))),"")}
A5: Recife | B5: Nordeste | C5: =COUNTIF('Dados B1'!$B$3:$B$56,$A5) | D5: {=IFERROR(MEDIAN(IF('Dados B1'!$B$3:$B$56=$A5,IF('Dados B1'!$D$3:$D$56<>"",'Dados B1'!$D$3:$D$56))),"")} | E5: =IFERROR(AVERAGEIFS('Dados B1'!$G$3:$G$56,'Dados B1'!$B$3:$B$56,$A5),"") | F5: =IFERROR(AVERAGEIFS('Dados B1'!$P$3:$P$56,'Dados B1'!$B$3:$B$56,$A5),"") | G5: =IFERROR(AVERAGEIFS('Dados B1'!$J$3:$J$56,'Dados B1'!$B$3:$B$56,$A5),"") | H5: =IFERROR(COUNTIFS('Dados B1'!$B$3:$B$56,$A5,'Dados B1'!$R$3:$R$56,">0")/COUNTIF('Dados B1'!$B$3:$B$56,$A5),"") | I5: {=IFERROR(MEDIAN(IF('Dados B1'!$B$3:$B$56=$A5,IF('Dados B1'!$U$3:$U$56<>"",'Dados B1'!$U$3:$U$56))),"")} | J5: =COUNTIFS('Dados B1'!$B$3:$B$56,$A5,'Dados B1'!$AH$3:$AH$56,"<>") | K5: {=IFERROR(MEDIAN(IF('Dados B1'!$B$3:$B$56=$A5,IF('Dados B1'!$AH$3:$AH$56<>"",'Dados B1'!$AH$3:$AH$56))),"")}
A6: Salvador | B6: Nordeste | C6: =COUNTIF('Dados B1'!$B$3:$B$56,$A6) | D6: {=IFERROR(MEDIAN(IF('Dados B1'!$B$3:$B$56=$A6,IF('Dados B1'!$D$3:$D$56<>"",'Dados B1'!$D$3:$D$56))),"")} | E6: =IFERROR(AVERAGEIFS('Dados B1'!$G$3:$G$56,'Dados B1'!$B$3:$B$56,$A6),"") | F6: =IFERROR(AVERAGEIFS('Dados B1'!$P$3:$P$56,'Dados B1'!$B$3:$B$56,$A6),"") | G6: =IFERROR(AVERAGEIFS('Dados B1'!$J$3:$J$56,'Dados B1'!$B$3:$B$56,$A6),"") | H6: =IFERROR(COUNTIFS('Dados B1'!$B$3:$B$56,$A6,'Dados B1'!$R$3:$R$56,">0")/COUNTIF('Dados B1'!$B$3:$B$56,$A6),"") | I6: {=IFERROR(MEDIAN(IF('Dados B1'!$B$3:$B$56=$A6,IF('Dados B1'!$U$3:$U$56<>"",'Dados B1'!$U$3:$U$56))),"")} | J6: =COUNTIFS('Dados B1'!$B$3:$B$56,$A6,'Dados B1'!$AH$3:$AH$56,"<>") | K6: {=IFERROR(MEDIAN(IF('Dados B1'!$B$3:$B$56=$A6,IF('Dados B1'!$AH$3:$AH$56<>"",'Dados B1'!$AH$3:$AH$56))),"")}
A7: Brasília | B7: Centro-Oeste | C7: =COUNTIF('Dados B1'!$B$3:$B$56,$A7) | D7: {=IFERROR(MEDIAN(IF('Dados B1'!$B$3:$B$56=$A7,IF('Dados B1'!$D$3:$D$56<>"",'Dados B1'!$D$3:$D$56))),"")} | E7: =IFERROR(AVERAGEIFS('Dados B1'!$G$3:$G$56,'Dados B1'!$B$3:$B$56,$A7),"") | F7: =IFERROR(AVERAGEIFS('Dados B1'!$P$3:$P$56,'Dados B1'!$B$3:$B$56,$A7),"") | G7: =IFERROR(AVERAGEIFS('Dados B1'!$J$3:$J$56,'Dados B1'!$B$3:$B$56,$A7),"") | H7: =IFERROR(COUNTIFS('Dados B1'!$B$3:$B$56,$A7,'Dados B1'!$R$3:$R$56,">0")/COUNTIF('Dados B1'!$B$3:$B$56,$A7),"") | I7: {=IFERROR(MEDIAN(IF('Dados B1'!$B$3:$B$56=$A7,IF('Dados B1'!$U$3:$U$56<>"",'Dados B1'!$U$3:$U$56))),"")} | J7: =COUNTIFS('Dados B1'!$B$3:$B$56,$A7,'Dados B1'!$AH$3:$AH$56,"<>") | K7: {=IFERROR(MEDIAN(IF('Dados B1'!$B$3:$B$56=$A7,IF('Dados B1'!$AH$3:$AH$56<>"",'Dados B1'!$AH$3:$AH$56))),"")}
A8: Goiânia | B8: Centro-Oeste | C8: =COUNTIF('Dados B1'!$B$3:$B$56,$A8) | D8: {=IFERROR(MEDIAN(IF('Dados B1'!$B$3:$B$56=$A8,IF('Dados B1'!$D$3:$D$56<>"",'Dados B1'!$D$3:$D$56))),"")} | E8: =IFERROR(AVERAGEIFS('Dados B1'!$G$3:$G$56,'Dados B1'!$B$3:$B$56,$A8),"") | F8: =IFERROR(AVERAGEIFS('Dados B1'!$P$3:$P$56,'Dados B1'!$B$3:$B$56,$A8),"") | G8: =IFERROR(AVERAGEIFS('Dados B1'!$J$3:$J$56,'Dados B1'!$B$3:$B$56,$A8),"") | H8: =IFERROR(COUNTIFS('Dados B1'!$B$3:$B$56,$A8,'Dados B1'!$R$3:$R$56,">0")/COUNTIF('Dados B1'!$B$3:$B$56,$A8),"") | I8: {=IFERROR(MEDIAN(IF('Dados B1'!$B$3:$B$56=$A8,IF('Dados B1'!$U$3:$U$56<>"",'Dados B1'!$U$3:$U$56))),"")} | J8: =COUNTIFS('Dados B1'!$B$3:$B$56,$A8,'Dados B1'!$AH$3:$AH$56,"<>") | K8: {=IFERROR(MEDIAN(IF('Dados B1'!$B$3:$B$56=$A8,IF('Dados B1'!$AH$3:$AH$56<>"",'Dados B1'!$AH$3:$AH$56))),"")}
A9: Belo Horizonte | B9: Sudeste | C9: =COUNTIF('Dados B1'!$B$3:$B$56,$A9) | D9: {=IFERROR(MEDIAN(IF('Dados B1'!$B$3:$B$56=$A9,IF('Dados B1'!$D$3:$D$56<>"",'Dados B1'!$D$3:$D$56))),"")} | E9: =IFERROR(AVERAGEIFS('Dados B1'!$G$3:$G$56,'Dados B1'!$B$3:$B$56,$A9),"") | F9: =IFERROR(AVERAGEIFS('Dados B1'!$P$3:$P$56,'Dados B1'!$B$3:$B$56,$A9),"") | G9: =IFERROR(AVERAGEIFS('Dados B1'!$J$3:$J$56,'Dados B1'!$B$3:$B$56,$A9),"") | H9: =IFERROR(COUNTIFS('Dados B1'!$B$3:$B$56,$A9,'Dados B1'!$R$3:$R$56,">0")/COUNTIF('Dados B1'!$B$3:$B$56,$A9),"") | I9: {=IFERROR(MEDIAN(IF('Dados B1'!$B$3:$B$56=$A9,IF('Dados B1'!$U$3:$U$56<>"",'Dados B1'!$U$3:$U$56))),"")} | J9: =COUNTIFS('Dados B1'!$B$3:$B$56,$A9,'Dados B1'!$AH$3:$AH$56,"<>") | K9: {=IFERROR(MEDIAN(IF('Dados B1'!$B$3:$B$56=$A9,IF('Dados B1'!$AH$3:$AH$56<>"",'Dados B1'!$AH$3:$AH$56))),"")}
A10: Rio de Janeiro | B10: Sudeste | C10: =COUNTIF('Dados B1'!$B$3:$B$56,$A10) | D10: {=IFERROR(MEDIAN(IF('Dados B1'!$B$3:$B$56=$A10,IF('Dados B1'!$D$3:$D$56<>"",'Dados B1'!$D$3:$D$56))),"")} | E10: =IFERROR(AVERAGEIFS('Dados B1'!$G$3:$G$56,'Dados B1'!$B$3:$B$56,$A10),"") | F10: =IFERROR(AVERAGEIFS('Dados B1'!$P$3:$P$56,'Dados B1'!$B$3:$B$56,$A10),"") | G10: =IFERROR(AVERAGEIFS('Dados B1'!$J$3:$J$56,'Dados B1'!$B$3:$B$56,$A10),"") | H10: =IFERROR(COUNTIFS('Dados B1'!$B$3:$B$56,$A10,'Dados B1'!$R$3:$R$56,">0")/COUNTIF('Dados B1'!$B$3:$B$56,$A10),"") | I10: {=IFERROR(MEDIAN(IF('Dados B1'!$B$3:$B$56=$A10,IF('Dados B1'!$U$3:$U$56<>"",'Dados B1'!$U$3:$U$56))),"")} | J10: =COUNTIFS('Dados B1'!$B$3:$B$56,$A10,'Dados B1'!$AH$3:$AH$56,"<>") | K10: {=IFERROR(MEDIAN(IF('Dados B1'!$B$3:$B$56=$A10,IF('Dados B1'!$AH$3:$AH$56<>"",'Dados B1'!$AH$3:$AH$56))),"")}
A11: São Paulo | B11: Sudeste | C11: =COUNTIF('Dados B1'!$B$3:$B$56,$A11) | D11: {=IFERROR(MEDIAN(IF('Dados B1'!$B$3:$B$56=$A11,IF('Dados B1'!$D$3:$D$56<>"",'Dados B1'!$D$3:$D$56))),"")} | E11: =IFERROR(AVERAGEIFS('Dados B1'!$G$3:$G$56,'Dados B1'!$B$3:$B$56,$A11),"") | F11: =IFERROR(AVERAGEIFS('Dados B1'!$P$3:$P$56,'Dados B1'!$B$3:$B$56,$A11),"") | G11: =IFERROR(AVERAGEIFS('Dados B1'!$J$3:$J$56,'Dados B1'!$B$3:$B$56,$A11),"") | H11: =IFERROR(COUNTIFS('Dados B1'!$B$3:$B$56,$A11,'Dados B1'!$R$3:$R$56,">0")/COUNTIF('Dados B1'!$B$3:$B$56,$A11),"") | I11: {=IFERROR(MEDIAN(IF('Dados B1'!$B$3:$B$56=$A11,IF('Dados B1'!$U$3:$U$56<>"",'Dados B1'!$U$3:$U$56))),"")} | J11: =COUNTIFS('Dados B1'!$B$3:$B$56,$A11,'Dados B1'!$AH$3:$AH$56,"<>") | K11: {=IFERROR(MEDIAN(IF('Dados B1'!$B$3:$B$56=$A11,IF('Dados B1'!$AH$3:$AH$56<>"",'Dados B1'!$AH$3:$AH$56))),"")}
A12: Vitória | B12: Sudeste | C12: =COUNTIF('Dados B1'!$B$3:$B$56,$A12) | D12: {=IFERROR(MEDIAN(IF('Dados B1'!$B$3:$B$56=$A12,IF('Dados B1'!$D$3:$D$56<>"",'Dados B1'!$D$3:$D$56))),"")} | E12: =IFERROR(AVERAGEIFS('Dados B1'!$G$3:$G$56,'Dados B1'!$B$3:$B$56,$A12),"") | F12: =IFERROR(AVERAGEIFS('Dados B1'!$P$3:$P$56,'Dados B1'!$B$3:$B$56,$A12),"") | G12: =IFERROR(AVERAGEIFS('Dados B1'!$J$3:$J$56,'Dados B1'!$B$3:$B$56,$A12),"") | H12: =IFERROR(COUNTIFS('Dados B1'!$B$3:$B$56,$A12,'Dados B1'!$R$3:$R$56,">0")/COUNTIF('Dados B1'!$B$3:$B$56,$A12),"") | I12: {=IFERROR(MEDIAN(IF('Dados B1'!$B$3:$B$56=$A12,IF('Dados B1'!$U$3:$U$56<>"",'Dados B1'!$U$3:$U$56))),"")} | J12: =COUNTIFS('Dados B1'!$B$3:$B$56,$A12,'Dados B1'!$AH$3:$AH$56,"<>") | K12: {=IFERROR(MEDIAN(IF('Dados B1'!$B$3:$B$56=$A12,IF('Dados B1'!$AH$3:$AH$56<>"",'Dados B1'!$AH$3:$AH$56))),"")}
A13: Curitiba | B13: Sul | C13: =COUNTIF('Dados B1'!$B$3:$B$56,$A13) | D13: {=IFERROR(MEDIAN(IF('Dados B1'!$B$3:$B$56=$A13,IF('Dados B1'!$D$3:$D$56<>"",'Dados B1'!$D$3:$D$56))),"")} | E13: =IFERROR(AVERAGEIFS('Dados B1'!$G$3:$G$56,'Dados B1'!$B$3:$B$56,$A13),"") | F13: =IFERROR(AVERAGEIFS('Dados B1'!$P$3:$P$56,'Dados B1'!$B$3:$B$56,$A13),"") | G13: =IFERROR(AVERAGEIFS('Dados B1'!$J$3:$J$56,'Dados B1'!$B$3:$B$56,$A13),"") | H13: =IFERROR(COUNTIFS('Dados B1'!$B$3:$B$56,$A13,'Dados B1'!$R$3:$R$56,">0")/COUNTIF('Dados B1'!$B$3:$B$56,$A13),"") | I13: {=IFERROR(MEDIAN(IF('Dados B1'!$B$3:$B$56=$A13,IF('Dados B1'!$U$3:$U$56<>"",'Dados B1'!$U$3:$U$56))),"")} | J13: =COUNTIFS('Dados B1'!$B$3:$B$56,$A13,'Dados B1'!$AH$3:$AH$56,"<>") | K13: {=IFERROR(MEDIAN(IF('Dados B1'!$B$3:$B$56=$A13,IF('Dados B1'!$AH$3:$AH$56<>"",'Dados B1'!$AH$3:$AH$56))),"")}
A14: Florianópolis | B14: Sul | C14: =COUNTIF('Dados B1'!$B$3:$B$56,$A14) | D14: {=IFERROR(MEDIAN(IF('Dados B1'!$B$3:$B$56=$A14,IF('Dados B1'!$D$3:$D$56<>"",'Dados B1'!$D$3:$D$56))),"")} | E14: =IFERROR(AVERAGEIFS('Dados B1'!$G$3:$G$56,'Dados B1'!$B$3:$B$56,$A14),"") | F14: =IFERROR(AVERAGEIFS('Dados B1'!$P$3:$P$56,'Dados B1'!$B$3:$B$56,$A14),"") | G14: =IFERROR(AVERAGEIFS('Dados B1'!$J$3:$J$56,'Dados B1'!$B$3:$B$56,$A14),"") | H14: =IFERROR(COUNTIFS('Dados B1'!$B$3:$B$56,$A14,'Dados B1'!$R$3:$R$56,">0")/COUNTIF('Dados B1'!$B$3:$B$56,$A14),"") | I14: {=IFERROR(MEDIAN(IF('Dados B1'!$B$3:$B$56=$A14,IF('Dados B1'!$U$3:$U$56<>"",'Dados B1'!$U$3:$U$56))),"")} | J14: =COUNTIFS('Dados B1'!$B$3:$B$56,$A14,'Dados B1'!$AH$3:$AH$56,"<>") | K14: {=IFERROR(MEDIAN(IF('Dados B1'!$B$3:$B$56=$A14,IF('Dados B1'!$AH$3:$AH$56<>"",'Dados B1'!$AH$3:$AH$56))),"")}
A15: Porto Alegre | B15: Sul | C15: =COUNTIF('Dados B1'!$B$3:$B$56,$A15) | D15: {=IFERROR(MEDIAN(IF('Dados B1'!$B$3:$B$56=$A15,IF('Dados B1'!$D$3:$D$56<>"",'Dados B1'!$D$3:$D$56))),"")} | E15: =IFERROR(AVERAGEIFS('Dados B1'!$G$3:$G$56,'Dados B1'!$B$3:$B$56,$A15),"") | F15: =IFERROR(AVERAGEIFS('Dados B1'!$P$3:$P$56,'Dados B1'!$B$3:$B$56,$A15),"") | G15: =IFERROR(AVERAGEIFS('Dados B1'!$J$3:$J$56,'Dados B1'!$B$3:$B$56,$A15),"") | H15: =IFERROR(COUNTIFS('Dados B1'!$B$3:$B$56,$A15,'Dados B1'!$R$3:$R$56,">0")/COUNTIF('Dados B1'!$B$3:$B$56,$A15),"") | I15: {=IFERROR(MEDIAN(IF('Dados B1'!$B$3:$B$56=$A15,IF('Dados B1'!$U$3:$U$56<>"",'Dados B1'!$U$3:$U$56))),"")} | J15: =COUNTIFS('Dados B1'!$B$3:$B$56,$A15,'Dados B1'!$AH$3:$AH$56,"<>") | K15: {=IFERROR(MEDIAN(IF('Dados B1'!$B$3:$B$56=$A15,IF('Dados B1'!$AH$3:$AH$56<>"",'Dados B1'!$AH$3:$AH$56))),"")}
A16: Total | C16: =SUM(C3:C15) | D16: =MEDIAN('Dados B1'!$D$3:$D$56) | E16: =AVERAGE('Dados B1'!$G$3:$G$56) | F16: =AVERAGE('Dados B1'!$P$3:$P$56) | G16: =AVERAGE('Dados B1'!$J$3:$J$56) | H16: =COUNTIF('Dados B1'!$R$3:$R$56,">0")/COUNTA('Dados B1'!$A$3:$A$56) | I16: =MEDIAN('Dados B1'!$U$3:$U$56) | J16: =COUNT('Dados B1'!$AH$3:$AH$56) | K16: =MEDIAN('Dados B1'!$AH$3:$AH$56)
A17: Fonte: B1, Google Places API (09/2026 e 15/10/2026), coletor de entorno do Google Maps (15/10/2026), Instagram (01/09 a 01/10/2026) e cardápios
A18: Nota: o gráfico mostra a mediana da cesta mediana das casas com cesta em cada metrópole; metrópoles sem cesta ficam fora.

Sheet Tab 6
A1: Tabela 6 – Entorno pelo Google Maps: a maioria das casas tem shopping a até 1 km; metrô perto é minoria
A2: Distância (linha reta) | B2: Metrô: casas | C2: Metrô: % | D2: Shopping: casas | E2: Shopping: %
A3: Até 500 m | B3: =COUNTIFS('Dados B1'!$S$3:$S$56,"<=500") | C3: =B3/B$9 | D3: =COUNTIFS('Dados B1'!$T$3:$T$56,"<=500") | E3: =D3/D$9
A4: De 501 a 1000 m | B4: =COUNTIFS('Dados B1'!$S$3:$S$56,">500",'Dados B1'!$S$3:$S$56,"<=1000") | C4: =B4/B$9 | D4: =COUNTIFS('Dados B1'!$T$3:$T$56,">500",'Dados B1'!$T$3:$T$56,"<=1000") | E4: =D4/D$9
A5: De 1001 a 2000 m | B5: =COUNTIFS('Dados B1'!$S$3:$S$56,">1000",'Dados B1'!$S$3:$S$56,"<=2000") | C5: =B5/B$9 | D5: =COUNTIFS('Dados B1'!$T$3:$T$56,">1000",'Dados B1'!$T$3:$T$56,"<=2000") | E5: =D5/D$9
A6: Mais de 2000 m | B6: =COUNTIFS('Dados B1'!$S$3:$S$56,">2000") | C6: =B6/B$9 | D6: =COUNTIFS('Dados B1'!$T$3:$T$56,">2000") | E6: =D6/D$9
A7: Sem leitura (cidade sem metrô ou leitura a mais de 50 km) | B7: =COUNTA('Dados B1'!$A$3:$A$56)-COUNT('Dados B1'!$S$3:$S$56) | C7: =B7/B$9 | D7: =COUNTA('Dados B1'!$A$3:$A$56)-COUNT('Dados B1'!$T$3:$T$56) | E7: =D7/D$9
A8: Conferência (total − casas; deve ser 0) | B8: =B9-COUNTA('Dados B1'!$A$3:$A$56) | D8: =D9-COUNTA('Dados B1'!$A$3:$A$56)
A9: Total | B9: =SUM(B3:B7) | C9: =SUM(C3:C7) | D9: =SUM(D3:D7) | E9: =SUM(E3:E7)
A10: Fonte: B1, coletor de entorno do Google Maps (15/10/2026)
A11: Nota: sem dados do OpenStreetMap (porte do shopping fora). Shopping de qualquer porte lido pelo Maps.

Sheet Tab 7
A1: Tabela 7 – Preços nos cardápios: a cesta mediana por pessoa fica em R$ 54 (metade das casas entre R$ 38,50 e R$ 70)
A2: Categoria | B2: Casas com preço | C2: 1º quartil (R$) | D2: Mediana (R$) | E2: 3º quartil (R$)
A3: Couvert ou taxa de jogo (casas que cobram) | B3: =COUNT('Dados B1'!$AD$3:$AD$56) | C3: =IFERROR(PERCENTILE('Dados B1'!$AD$3:$AD$56,0.25),"") | D3: =IFERROR(MEDIAN('Dados B1'!$AD$3:$AD$56),"") | E3: =IFERROR(PERCENTILE('Dados B1'!$AD$3:$AD$56,0.75),"")
A4: Bebida | B4: =COUNT('Dados B1'!$AE$3:$AE$56) | C4: =IFERROR(PERCENTILE('Dados B1'!$AE$3:$AE$56,0.25),"") | D4: =IFERROR(MEDIAN('Dados B1'!$AE$3:$AE$56),"") | E4: =IFERROR(PERCENTILE('Dados B1'!$AE$3:$AE$56,0.75),"")
A5: Entrada ou prato | B5: =COUNT('Dados B1'!$AF$3:$AF$56) | C5: =IFERROR(PERCENTILE('Dados B1'!$AF$3:$AF$56,0.25),"") | D5: =IFERROR(MEDIAN('Dados B1'!$AF$3:$AF$56),"") | E5: =IFERROR(PERCENTILE('Dados B1'!$AF$3:$AF$56,0.75),"")
A6: Hambúrguer | B6: =COUNT('Dados B1'!$AJ$3:$AJ$56) | C6: =IFERROR(PERCENTILE('Dados B1'!$AJ$3:$AJ$56,0.25),"") | D6: =IFERROR(MEDIAN('Dados B1'!$AJ$3:$AJ$56),"") | E6: =IFERROR(PERCENTILE('Dados B1'!$AJ$3:$AJ$56,0.75),"")
A7: Batata | B7: =COUNT('Dados B1'!$AK$3:$AK$56) | C7: =IFERROR(PERCENTILE('Dados B1'!$AK$3:$AK$56,0.25),"") | D7: =IFERROR(MEDIAN('Dados B1'!$AK$3:$AK$56),"") | E7: =IFERROR(PERCENTILE('Dados B1'!$AK$3:$AK$56,0.75),"")
A8: Cerveja | B8: =COUNT('Dados B1'!$AL$3:$AL$56) | C8: =IFERROR(PERCENTILE('Dados B1'!$AL$3:$AL$56,0.25),"") | D8: =IFERROR(MEDIAN('Dados B1'!$AL$3:$AL$56),"") | E8: =IFERROR(PERCENTILE('Dados B1'!$AL$3:$AL$56,0.75),"")
A9: Refrigerante | B9: =COUNT('Dados B1'!$AM$3:$AM$56) | C9: =IFERROR(PERCENTILE('Dados B1'!$AM$3:$AM$56,0.25),"") | D9: =IFERROR(MEDIAN('Dados B1'!$AM$3:$AM$56),"") | E9: =IFERROR(PERCENTILE('Dados B1'!$AM$3:$AM$56,0.75),"")
A10: Drinks | B10: =COUNT('Dados B1'!$AN$3:$AN$56) | C10: =IFERROR(PERCENTILE('Dados B1'!$AN$3:$AN$56,0.25),"") | D10: =IFERROR(MEDIAN('Dados B1'!$AN$3:$AN$56),"") | E10: =IFERROR(PERCENTILE('Dados B1'!$AN$3:$AN$56,0.75),"")
A11: Cesta por pessoa, nível baixo | B11: =COUNT('Dados B1'!$AG$3:$AG$56) | C11: =IFERROR(PERCENTILE('Dados B1'!$AG$3:$AG$56,0.25),"") | D11: =IFERROR(MEDIAN('Dados B1'!$AG$3:$AG$56),"") | E11: =IFERROR(PERCENTILE('Dados B1'!$AG$3:$AG$56,0.75),"")
A12: Cesta por pessoa, nível mediano | B12: =COUNT('Dados B1'!$AH$3:$AH$56) | C12: =IFERROR(PERCENTILE('Dados B1'!$AH$3:$AH$56,0.25),"") | D12: =IFERROR(MEDIAN('Dados B1'!$AH$3:$AH$56),"") | E12: =IFERROR(PERCENTILE('Dados B1'!$AH$3:$AH$56,0.75),"")
A13: Cesta por pessoa, nível alto | B13: =COUNT('Dados B1'!$AI$3:$AI$56) | C13: =IFERROR(PERCENTILE('Dados B1'!$AI$3:$AI$56,0.25),"") | D13: =IFERROR(MEDIAN('Dados B1'!$AI$3:$AI$56),"") | E13: =IFERROR(PERCENTILE('Dados B1'!$AI$3:$AI$56,0.75),"")
A14: Fonte: B1, cardápios transcritos (B1_cardapios_itens_precos.xlsx)
A15: Nota: cada casa entra com a mediana do próprio cardápio na categoria; quartis entre as casas.
A16: Cesta = couvert + bebida + entrada ou prato, só nas casas em que os três foram encontrados.

Sheet Tab 8
A1: Tabela 8 – Couvert: encontrado no cardápio de 8 das 36 casas com cardápio
A2: Situação | B2: Casas | C2: % do total
A3: Couvert ou taxa de jogo encontrado no cardápio | B3: =COUNTIFS('Dados B1'!$AB$3:$AB$56,1,'Dados B1'!$AC$3:$AC$56,1) | C3: =B3/B$6
A4: Couvert não encontrado no cardápio | B4: =COUNTIF('Dados B1'!$AB$3:$AB$56,1)-B3 | C4: =B4/B$6
A5: Sem cardápio transcrito | B5: =COUNTA('Dados B1'!$A$3:$A$56)-COUNTIF('Dados B1'!$AB$3:$AB$56,1) | C5: =B5/B$6
A6: Total | B6: =SUM(B3:B5) | C6: =SUM(C3:C5)
A7: Conferência (total − casas; deve ser 0) | B7: =B6-COUNTA('Dados B1'!$A$3:$A$56)
A8: Fonte: B1, cardápios transcritos (B1_cardapios_itens_precos.xlsx)
A9: Nota: "não encontrado" não quer dizer que a casa não cobra; o couvert pode estar fora do cardápio coletado.

Sheet Tab 9
A1: Tabela 9 – Modelos de cobrança citados no Instagram: couvert lúdico e inscrição em evento são os mais comuns
A2: Modelo | B2: Posts que citam | C2: Estabelecimentos que citam | D2: Casas de jogos que citam | E2: Casas de jogos (total) | F2: Casas de jogos (%) | G2: Lojas que citam | H2: Lojas (total) | I2: Lojas (%)
A3: couvert lúdico ou taxa de entrada | B3: 816 | C3: 34 | D3: 21 | E3: 23 | F3: =D3/E3 | G3: 13 | H3: 24 | I3: =G3/H3
A4: entrada gratuita | B4: 582 | C4: 31 | D4: 19 | E4: 23 | F4: =D4/E4 | G4: 12 | H4: 24 | I4: =G4/H4
A5: cobrança por hora | B5: 55 | C5: 19 | D5: 11 | E5: 23 | F5: =D5/E5 | G5: 8 | H5: 24 | I5: =G5/H5
A6: cobrança por turno ou período | B6: 114 | C6: 25 | D6: 16 | E6: 23 | F6: =D6/E6 | G6: 9 | H6: 24 | I6: =G6/H6
A7: dia livre (sem limite de tempo) | B7: 579 | C7: 30 | D7: 18 | E7: 23 | F7: =D7/E7 | G7: 12 | H7: 24 | I7: =G7/H7
A8: passaporte ou pacote de visitas | B8: 142 | C8: 28 | D8: 18 | E8: 23 | F8: =D8/E8 | G8: 10 | H8: 24 | I8: =G8/H8
A9: assinatura ou plano mensal | B9: 214 | C9: 15 | D9: 9 | E9: 23 | F9: =D9/E9 | G9: 6 | H9: 24 | I9: =G9/H9
A10: consumação mínima ou isenção por consumo | B10: 140 | C10: 17 | D10: 5 | E10: 23 | F10: =D10/E10 | G10: 12 | H10: 24 | I10: =G10/H10
A11: preço diferente por dia da semana | B11: 46 | C11: 11 | D11: 9 | E11: 23 | F11: =D11/E11 | G11: 2 | H11: 24 | I11: =G11/H11
A12: rodízio ou buffet com jogos | B12: 189 | C12: 12 | D12: 8 | E12: 23 | F12: =D12/E12 | G12: 4 | H12: 24 | I12: =G12/H12
A13: aluguel de jogos | B13: 138 | C13: 21 | D13: 13 | E13: 23 | F13: =D13/E13 | G13: 8 | H13: 24 | I13: =G13/H13
A14: inscrição em evento ou torneio | B14: 3549 | C14: 45 | D14: 21 | E14: 23 | F14: =D14/E14 | G14: 24 | H14: 24 | I14: =G14/H14
A15: Fonte: B1, legendas do Instagram das casas (coletor do Instagram, 2026), análise de legendas
A16: Nota: contagem não exclusiva (um post pode citar vários modelos).

Sheet Tab 10
A1: Tabela 10 – Eventos no Instagram: encontros/RPG, competições e noites temáticas puxam a agenda
A2: Categoria | B2: Posts | C2: Estabelecimentos | D2: Casas de jogos com o evento | E2: Casas de jogos (total) | F2: Casas de jogos: posts por casa por mês | G2: Lojas com o evento | H2: Lojas (total) | I2: Lojas: posts por casa por mês
A3: todos os eventos prováveis | B3: 2237 | C3: 45 | D3: 22 | E3: 22 | F3: 3.23 | G3: 23 | H3: 23 | I3: 5.01
A4: noite temática | B4: 456 | C4: 41 | D4: 22 | E4: 22 | F4: 1.22 | G4: 19 | H4: 23 | I4: 0.49
A5: workshop/aula | B5: 105 | C5: 27 | D5: 13 | E5: 22 | F5: 0.21 | G5: 14 | H5: 23 | I5: 0.18
A6: competição | B6: 1231 | C6: 44 | D6: 21 | E6: 22 | F6: 1.22 | G6: 23 | H6: 23 | I6: 3.29
A7: quiz/bingo | B7: 125 | C7: 13 | D7: 11 | E7: 22 | F7: 0.45 | G7: 2 | H7: 23 | I7: 0.03
A8: encontro/RPG | B8: 1190 | C8: 41 | D8: 21 | E8: 22 | F8: 1.63 | G8: 20 | H8: 23 | I8: 2.75
A9: sorteio (não é evento; referência) | B9: 329 | C9: 35 | D9: 14 | E9: 22 | F9: 0.41 | G9: 21 | H9: 23 | I9: 0.8
A10: Fonte: B1, legendas do Instagram das casas (coletor do Instagram, 2026), análise de legendas
A11: Nota: categorias não exclusivas; o gráfico mostra posts por casa por mês, sem "todos os eventos" e sem sorteio (que não é evento).

Sheet Tab 11
A1: Tabela 11 – Dia citado nos eventos: casas de jogos anunciam mais domingo e quinta; lojas, sábado
A2: Dia | B2: Casas de jogos: eventos que citam | C2: Casas de jogos: % dos eventos | D2: Casas de jogos: estabelecimentos | E2: Lojas: eventos que citam | F2: Lojas: % dos eventos | G2: Lojas: estabelecimentos
A3: segunda | B3: 37 | C3: 0.043 | D3: 15 | E3: 37 | F3: 0.027 | G3: 10
A4: terça | B4: 59 | C4: 0.069 | D4: 14 | E4: 146 | F4: 0.105 | G4: 14
A5: quarta | B5: 103 | C5: 0.121 | D5: 17 | E5: 181 | F5: 0.131 | G5: 15
A6: quinta | B6: 121 | C6: 0.142 | D6: 18 | E6: 67 | F6: 0.048 | G6: 13
A7: sexta | B7: 86 | C7: 0.101 | D7: 17 | E7: 207 | F7: 0.15 | G7: 17
A8: sábado | B8: 79 | C8: 0.093 | D8: 17 | E8: 329 | F8: 0.238 | G8: 18
A9: domingo | B9: 145 | C9: 0.17 | D9: 20 | E9: 136 | F9: 0.098 | G9: 15
A10: Fonte: B1, legendas do Instagram das casas (coletor do Instagram, 2026), análise de legendas
A11: Nota: % sobre os eventos prováveis de cada tipo de casa; um evento pode citar mais de um dia ou nenhum.

Sheet Tab 12
A1: Tabela 12 – Temas das legendas do Instagram: programação, varejo e preço dominam
A2: Código | B2: Tema | C2: Posts com o tema | D2: % dos posts | E2: % ponderado por estabelecimento | F2: Estabelecimentos com o tema
A3: ACV | B3: Acervo de jogos | C3: 830 | D3: 0.07 | E3: 0.084 | F3: 40
A4: MED | B4: Mediação lúdica (monitoria) | C4: 378 | D4: 0.032 | E4: 0.048 | F4: 31
A5: ATD | B5: Atendimento e hospitalidade | C5: 483 | D5: 0.04 | E5: 0.063 | F5: 40
A6: AB | B6: Alimentos e bebidas | C6: 2510 | D6: 0.21 | E6: 0.223 | F6: 42
A7: PRC | B7: Preço e valor percebido | C7: 3224 | D7: 0.27 | E7: 0.284 | F7: 45
A8: AMB | B8: Ambiente físico e conforto | C8: 415 | D8: 0.035 | E8: 0.038 | F8: 41
A9: CAP | B9: Capacidade, reserva e fila | C9: 1366 | D9: 0.114 | E9: 0.152 | F9: 45
A10: PRG | B10: Programação e atrações | C10: 6303 | D10: 0.528 | E10: 0.534 | F10: 45
A11: COMU | B11: Comunidade de jogadores | C11: 431 | D11: 0.036 | E11: 0.042 | F11: 38
A12: VAR | B12: Varejo e pós-venda | C12: 3789 | D12: 0.317 | E12: 0.355 | F12: 45
A13: LOC | B13: Localização e acesso | C13: 1305 | D13: 0.109 | E13: 0.156 | F13: 38
A14: INC | B14: Segurança, inclusão e respeito | C14: 219 | D14: 0.018 | E14: 0.024 | F14: 33
... A24: SOR | B24: Sorteio ou concurso (só legendas) | C24: 735 | D24: 0.062 | E24: 0.063 | F24: 42
A25: Fonte: B1, legendas do Instagram das casas (coletor do Instagram, 2026), análise de legendas
A26: Nota: temas não exclusivos; o % ponderado dá peso igual a cada estabelecimento. Comparação com o B2 retirada desta planilha.

Sheet Tab 13
A1: Tabela 13 – Os 20 jogos mais presentes nos acervos publicados (30 acervos): Catan, Saboteur e Potion Explosion lideram
A2: Jogo | B2: Casas com o jogo | C2: Jogadores (mín.) | D2: Jogadores (máx.) | E2: Duração (min) | F2: Preço provável (R$) | G2: Aluguel (mediana, R$)
A3: Catan: O Jogo | B3: 28 | C3: 3 | D3: 4 | E3: 90 | F3: 349.88 | G3: 40
A4: Saboteur | B4: 27 | C4: 3 | D4: 10 | E4: 30 | F4: 105 | G4: 17.5
A5: Potion Explosion | B5: 26 | C5: 2 | D5: 4 | E5: 45 | F5: 389.94 | G5: 35
A6: 7 Wonders | B6: 25 | C6: 2 | D6: 7 | E6: 30 | F6: 304.9 | G6: 40
A7: Bandido | B7: 25 | C7: 1 | D7: 4 | E7: 15 | F7: 64.9 | G7: 15
A8: Concept | B8: 25 | C8: 4 | D8: 12 | E8: 40 | F8: 299.95 | G8: 30
A9: 7 Wonders Duel | B9: 24 | C9: 2 | D9: 2 | E9: 30 | F9: 249.9 | G9: 30
A10: Azul | B10: 24 | C10: 2 | D10: 4 | E10: 45 | F10: 344.45 | G10: 37.5
A11: Taco Gato Cabra Queijo Pizza | B11: 24 | C11: 2 | D11: 8 | E11: 10 | F11: 62.5 | G11: 15
A12: The Mind | B12: 24 | C12: 2 | D12: 4 | E12: 15 | F12: 79.95 | G12: 15
A13: The Resistance | B13: 24 | C13: 5 | D13: 10 | E13: 30 | F13: 159.9 | G13: 25
A14: Ticket to Ride | B14: 24 | C14: 2 | D14: 5 | E14: 45 | F14: 405 | G14: 35
... A22: Love Letter | B22: 22 | C22: 2 | D22: 4 | E22: 20 | F22: 89.89 | G22: 20
A23: Fonte: B1, acervos publicados (acervodejogos, Ludopedia, Rejoy e listas das casas) e preços de lojas (B1_cesta_jogos.xlsx)
A24: Nota: preço vazio = jogo sem preço nas lojas consultadas.

Sheet Tab 14
A1: Tabela 14 – Custo do acervo inicial: de R$ 40 mil (acervo pequeno) a R$ 119 mil (acervo grande)
A2: Tamanho do acervo | B2: Títulos | C2: Núcleo com preço | D2: Títulos restantes | E2: Custo otimista (R$) | F2: Custo provável (R$) | G2: Custo pessimista (R$)
A3: Pequeno (1º quartil dos acervos) | B3: 222 | C3: 77 | D3: =B3-C3 | E3: 40131.59 | F3: 42928.78 | G3: 44732.45
A4: Mediano (mediana dos acervos) | B4: 322 | C4: 77 | D4: =B4-C4 | E4: 57273.26 | F4: 60884.32 | G4: 63281.49
A5: Grande (3º quartil dos acervos) | B5: 622 | C5: 77 | D5: =B5-C5 | E5: 108698.28 | F5: 114750.94 | G5: 118928.59
A6: Fonte: B1, acervos publicados e preços de lojas (B1_cesta_jogos.xlsx, aba acervo_inicial)
A7: Nota: títulos restantes (fora do núcleo com preço) pelo preço médio do núcleo.

Sheet Tab 15
A1: Tabela 15 – Contagem direta na São Jogue: grupos ficam de 1h20 a 2h na mesa
A2: Medida | B2: 10/10 Bela Vista | C2: 16/10 Bela Vista | D2: 17/10 Paralela
A3: Horas observadas | B3: 3.32 | C3: 2.48 | D3: 2.47
A4: Grupos que entraram (porta) | B4: 14 | C4: 4 | D4: 3
A5: Pessoas que entraram | B5: 38 | C5: 10 | D5: 13
A6: Pessoas por hora | B6: =IFERROR(B5/B3,"") | C6: =IFERROR(C5/C3,"") | D6: =IFERROR(D5/D3,"")
A7: Pessoas por grupo (porta) | B7: =IFERROR(B5/B4,"") | C7: =IFERROR(C5/C4,"") | D7: =IFERROR(D5/D4,"")
A8: Permanência média pela porta (min) | B8: 99.4 | C8: 61.8 | D8: 53.3
A9: Grupos acompanhados na mesa | B9: 9 | C9: 7 | D9: 4
A10: Pessoas nas mesas | B10: 41 | C10: 17 | D10: 12
A11: Pessoas por grupo (mesa) | B11: =IFERROR(B10/B9,"") | C11: =IFERROR(C10/C9,"") | D11: =IFERROR(D10/D9,"")
A12: Permanência média na mesa (min) | B12: 116.2 | C12: 82.9 | D12: 99.5
A13: Permanência mediana na mesa (min) | B13: 121 | C13: 95 | D13: 91.5
A14: Fonte: B3, contagem direta nas unidades da São Jogue (app de observação, 10/10, 16/10 e 17/10/2026)
A15: Nota: visitas de cerca de 3 h, do lado de fora; 10/10 só com o POV1.

Sheet Tab 16
A1: Tabela 16 – População e renda das capitais do B1: Salvador e Belém têm a menor renda do trabalho do grupo
A2: Capital | B2: UF | C2: População 2022 | D2: População estimada 2026 | E2: População de 20 a 39 anos (2022) | F2: % de 20 a 39 anos | G2: Renda média, 14 anos ou mais (2022, R$) | H2: Renda mediana, 14 anos ou mais (2022, R$) | I2: Renda habitual do trabalho (2º tri. 2026, R$)
A3: Florianópolis | B3: SC | C3: 537211 | D3: 598370 | E3: 185946 | F3: =E3/C3 | G3: 4222.88 | H3: 2100 | I3: 6861
A4: Porto Alegre | B4: RS | C4: 1332845 | D4: 1388791 | E4: 391627 | F4: =E4/C4 | G4: 3749.45 | H4: 1900 | I4: 6402
A5: Curitiba | B5: PR | C5: 1773718 | D5: 1832183 | E5: 551000 | F5: =E5/C5 | G5: 3685.62 | H5: 2000 | I5: 6134
A6: Brasília | B6: DF | C6: 2817381 | D6: 3009996 | E6: 914611 | F6: =E6/C6 | G6: 3629.16 | H6: 1500 | I6: 6007
A7: Vitória | B7: ES | C7: 322869 | D7: 343935 | E7: 96495 | F7: =E7/C7 | G7: 3950.45 | H7: 1800 | I7: 5982
A8: Goiânia | B8: GO | C8: 1437366 | D8: 1511709 | E8: 474870 | F8: =E8/C8 | G8: 3202.02 | H8: 1500 | I8: 5496
A9: São Paulo | B9: SP | C9: 11451999 | D9: 11911337 | E9: 3559246 | F9: =E9/C9 | G9: 3216.65 | H9: 1500 | I9: 5431
A10: Belo Horizonte | B10: MG | C10: 2315560 | D10: 2415451 | E10: 702819 | F10: =E10/C10 | G10: 3206.74 | H10: 1500 | I10: 5130
A11: Rio de Janeiro | B11: RJ | C11: 6211223 | D11: 6731133 | E11: 1834349 | F11: =E11/C11 | G11: 2964.14 | H11: 1250 | I11: 5027
A12: Fortaleza | B12: CE | C12: 2428708 | D12: 2582360 | E12: 790398 | F12: =E12/C12 | G12: 2014.23 | H12: 1212 | I12: 3887
A13: Recife | B13: PE | C13: 1488920 | D13: 1588983 | E13: 447131 | F13: =E13/C13 | G13: 2728.51 | H13: 1212 | I13: 3758
A14: Salvador | B14: BA | C14: 2417678 | D14: 2559945 | E14: 736849 | F14: =E14/C14 | G14: 2089.3 | H14: 1212 | I14: 3417
A15: Belém | B15: PA | C15: 1303403 | D15: 1396157 | E15: 404656 | F15: =E15/C15 | G15: 1998.96 | H15: 1200 | I15: 3406
A16: Fonte: B4, IBGE: Censo 2022, estimativas de população 2026 e PNAD Contínua (2º trimestre de 2026)

Sheet Tab 17
A1: Tabela 17 – Aluguel comercial por m²: Salvador está entre as capitais mais caras do grupo
A2: Capital | B2: UF | C2: Locação comercial (R$/m²) | D2: Estimativa, mediana (R$/m²) | E2: Valor usado (R$/m²) | F2: Variação em 12 meses | G2: Origem do valor
A3: São Paulo | B3: SP | C3: 61.742989 | E3: =IF(C3<>"",C3,D3) | F3: 0.078221866 | G3: FipeZap comercial
A4: Recife | B4: PE | D4: 57.32 | E4: =IF(C4<>"",C4,D4) | G4: estimado (residencial × razão comercial/residencial)
A5: Rio de Janeiro | B5: RJ | C5: 56.980749 | E5: =IF(C5<>"",C5,D5) | F5: 0.21339627 | G5: FipeZap comercial
A6: Belém | B6: PA | D6: 56.02 | E6: =IF(C6<>"",C6,D6) | G6: estimado (residencial × razão comercial/residencial)
A7: Salvador | B7: BA | C7: 54.145255 | E7: =IF(C7<>"",C7,D7) | F7: 0.18855597 | G7: FipeZap comercial
A8: Florianópolis | B8: SC | C8: 51.77842 | E8: =IF(C8<>"",C8,D8) | F8: 0.074392232 | G8: FipeZap comercial
A9: Vitória | B9: ES | D9: 48.9 | E9: =IF(C9<>"",C9,D9) | G9: estimado (residencial × razão comercial/residencial)
A10: Curitiba | B10: PR | C10: 46.234575 | E10: =IF(C10<>"",C10,D10) | F10: 0.12846141 | G10: FipeZap comercial
A11: Brasília | B11: DF | C11: 44.19515 | E11: =IF(C11<>"",C11,D11) | F11: 0.0765629 | G11: FipeZap comercial
A12: Goiânia | B12: GO | D12: 38.63 | E12: =IF(C12<>"",C12,D12) | G12: estimado (residencial × razão comercial/residencial)
A13: Belo Horizonte | B13: MG | C13: 37.859152 | E13: =IF(C13<>"",C13,D13) | F13: 0.087934972 | G13: FipeZap comercial
A14: Fortaleza | B14: CE | D14: 37.24 | E14: =IF(C14<>"",C14,D14) | G14: estimado (residencial × razão comercial/residencial)
A15: Porto Alegre | B15: RS | C15: 34.728919 | E15: =IF(C15<>"",C15,D15) | F15: 0.028469123 | G15: FipeZap comercial
A16: Fonte: B4, FipeZap (índice de locação comercial e residencial, julho de 2026)
A17: Nota: onde o FipeZap não cobre o comercial, estimativa pelo residencial vezes a razão comercial/residencial das capitais cobertas.

Sheet Tab 18
A1: Tabela 18 – Salário de admissão em alimentação: Salvador paga perto do salário mínimo e abaixo das capitais
A2: Ocupação | B2: Salvador: admissões | C2: Salvador: salário mediano (R$) | D2: 27 capitais: admissões | E2: 27 capitais: salário mediano (R$) | F2: Salvador ÷ 27 capitais | G2: Amostra pequena em Salvador
A3: Gerente de restaurante | B3: 158 | C3: 2500 | D3: 7387 | E3: 2700 | F3: =C3/E3 | G3: não
A4: Gerente de bar | B4: 14 | C4: 2500 | D4: 1404 | E4: 2500 | F4: =C4/E4 | G4: sim
A5: Cozinheiro geral | B5: 1827 | C5: 1700 | D5: 54113 | E5: 1872.16 | F5: =C5/E5 | G5: não
A6: Recreador | B6: 8 | C6: 1625.09 | D6: 1188 | E6: 1669.2 | F6: =C6/E6 | G6: sim
A7: Operador de caixa | B7: 600 | C7: 1625.09 | D7: 14316 | E7: 1733.45 | F7: =C7/E7 | G7: não
A8: Garçom | B8: 1595 | C8: 1625.09 | D8: 43378 | E8: 1750.68 | F8: =C8/E8 | G8: não
A9: Cumim | B9: 601 | C9: 1625.09 | D9: 15978 | E9: 1700 | F9: =C9/E9 | G9: não
A10: Barman | B10: 351 | C10: 1625.09 | D10: 9253 | E10: 1771 | F10: =C10/E10 | G10: não
A11: Atendente de lanchonete | B11: 2943 | C11: 1625.09 | D11: 125235 | E11: 1688.53 | F11: =C11/E11 | G11: não
A12: Auxiliar nos serviços de alimentação | B12: 2737 | C12: 1625.09 | D12: 113010 | E12: 1787 | F12: =C12/E12 | G12: não
A13: Faxineiro | B13: 1470 | C13: 1625.09 | D13: 31783 | E13: 1703 | F13: =C13/E13 | G13: não
A14: Atendente de lojas e mercados | B14: 854 | C14: 1625.09 | D14: 19178 | E14: 1712 | F14: =C14/E14 | G14: não
A15: Fonte: B4, Novo CAGED (admissões de 08/2025 a 07/2026, CNAE 56 – alimentação)

Sheet Tab 19
A1: Tabela 19 – Simples Nacional, anexos I e III: alíquota efetiva no teto de cada faixa
A2: Anexo | B2: Faixa | C2: Receita bruta em 12 meses, de (R$) | D2: Até (R$) | E2: Alíquota nominal | F2: Parcela a deduzir (R$) | G2: Alíquota efetiva no teto da faixa
A3: I | B3: 1 | C3: 0 | D3: 180000 | E3: 0.04 | F3: 0 | G3: =IFERROR((D3*E3-F3)/D3,"")
A4: I | B4: 2 | C4: 180000.01 | D4: 360000 | E4: 0.073 | F4: 5940 | G4: =IFERROR((D4*E4-F4)/D4,"")
A5: I | B5: 3 | C5: 360000.01 | D5: 720000 | E5: 0.095 | F5: 13860 | G5: =IFERROR((D5*E5-F5)/D5,"")
A6: I | B6: 4 | C6: 720000.01 | D6: 1800000 | E6: 0.107 | F6: 22500 | G6: =IFERROR((D6*E6-F6)/D6,"")
A7: I | B7: 5 | C7: 1800000 | D7: 3600000 | E7: 0.143 | F7: 87300 | G7: =IFERROR((D7*E7-F7)/D7,"")
A8: I | B8: 6 | C8: 3600000 | D8: 4800000 | E8: 0.19 | F8: 378000 | G8: =IFERROR((D8*E8-F8)/D8,"")
A9: III | B9: 1 | C9: 0 | D9: 180000 | E9: 0.06 | F9: 0 | G9: =IFERROR((D9*E9-F9)/D9,"")
A10: III | B10: 2 | C10: 180000.01 | D10: 360000 | E10: 0.112 | F10: 9360 | G10: =IFERROR((D10*E10-F10)/D10,"")
A11: III | B11: 3 | C11: 360000.01 | D11: 720000 | E11: 0.135 | F11: 17640 | G11: =IFERROR((D11*E11-F11)/D11,"")
A12: III | B12: 4 | C12: 720000.01 | D12: 1800000 | E12: 0.16 | F12: 35640 | G12: =IFERROR((D12*E12-F12)/D12,"")
A13: III | B13: 5 | C13: 1800000 | D13: 3600000 | E13: 0.21 | F13: 125640 | G13: =IFERROR((D13*E13-F13)/D13,"")
A14: III | B14: 6 | C14: 3600000 | D14: 4800000 | E14: 0.33 | F14: 648000 | G14: =IFERROR((D14*E14-F14)/D14,"")
A15: Fonte: B4, Lei Complementar 123/2006, anexos I e III (Simples Nacional, 2026)
A16: Nota: alíquota efetiva = (receita × alíquota nominal − parcela a deduzir) ÷ receita.

Sheet Tab 20
A1: Tabela 20 – Selic e IPCA: juros altos em 2026, com queda esperada até 2030
A2: Ano | B2: Tipo | C2: Selic meta | D2: IPCA em 12 meses | E2: Referência
A3: 2017 | B3: realizado | C3: 0.07 | D3: 0.0295 | E3: Selic 12/2017; IPCA 12/2017
A4: 2018 | B4: realizado | C4: 0.065 | D4: 0.0375 | E4: Selic 12/2018; IPCA 12/2018
A5: 2019 | B5: realizado | C5: 0.045 | D5: 0.0431 | E5: Selic 12/2019; IPCA 12/2019
A6: 2020 | B6: realizado | C6: 0.02 | D6: 0.0452 | E6: Selic 12/2020; IPCA 12/2020
A7: 2021 | B7: realizado | C7: 0.0925 | D7: 0.1006 | E7: Selic 12/2021; IPCA 12/2021
A8: 2022 | B8: realizado | C8: 0.1375 | D8: 0.0579 | E8: Selic 12/2022; IPCA 12/2022
A9: 2023 | B9: realizado | C9: 0.1175 | D9: 0.0462 | E9: Selic 12/2023; IPCA 12/2023
A10: 2024 | B10: realizado | C10: 0.1225 | D10: 0.0483 | E10: Selic 12/2024; IPCA 12/2024
A11: 2025 | B11: realizado | C11: 0.15 | D11: 0.0426 | E11: Selic 12/2025; IPCA 12/2025
A12: 2026 | B12: realizado | C12: 0.14 | D12: 0.0422 | E12: Selic 09/2026; IPCA 08/2026
A13: 2026 | B13: Focus (mediana) | C13: 0.1375 | D13: 0.049 | E13: 11/09/2026
A14: 2027 | B14: Focus (mediana) | C14: 0.12 | D14: 0.043 | E14: 11/09/2026
... A17: 2030 | B17: Focus (mediana) | C17: 0.1 | D17: 0.035 | E17: 11/09/2026
A18: Fonte: B4, Banco Central do Brasil: SGS (séries 432 e 13522) e Relatório Focus de 11/09/2026
A19: Nota: realizado = último valor do ano (2026 até a data indicada); Focus = mediana das expectativas para o fim do ano.

Sheet Tab 21
A1: Tabela 21 – IPCA em 12 meses: alimentação fora do domicílio sobe mais que o índice geral
A2: Mês | B2: Brasil: índice geral | C2: Brasil: alimentação fora do domicílio | D2: Salvador: índice geral | E2: Salvador: alimentação fora do domicílio
A3: 08/2024 | B3: 0.0424 | C3: 0.0455 | D3: 0.0371 | E3: 0.0338
A4: 08/2025 | B4: 0.0513 | C4: 0.085 | D4: 0.0494 | E4: 0.077
A5: 08/2026 | B5: 0.0422 | C5: 0.054 | D5: 0.0364 | E5: 0.0655
A6: Fonte: B4, IBGE, IPCA (tabela 7060, variação acumulada em 12 meses)

Sheet Dados B1
A1: Base – as 54 casas do B1 (valores; as Tabelas 1 a 8 calculam por fórmula sobre esta aba)
